{
  "version": 8,
  "blockIdVersion": 11,
  "anchorX": 0,
  "anchorY": 0,
  "anchorZ": 0,
  "blocks": [
    {
      "x": -8,
      "y": 1,
      "z": -1,
      "name": "Rock_Gold_Brick_Smooth"
    },
    {
      "x": -8,
      "y": 0,
      "z": 1,
      "name": "Rock_Gold_Brick_Smooth"
    },
    {
      "x": -8,
      "y": 1,
      "z": 1,
      "name": "Plant_Moss_Rug_Green",
      "support": 15
    },
    {
      "x": -7,
      "y": 2,
      "z": -5,
      "name": "Rock_Gold_Brick_Smooth_Half",
      "rotation": 6
    },
    {
      "x": -7,
      "y": 2,
      "z": -4,
      "name": "Rock_Gold_Brick_Smooth_Half",
      "rotation": 4
    },
    {
      "x": -7,
      "y": 1,
      "z": -2,
      "name": "Rock_Gold_Brick_Smooth"
    },
    {
      "x": -7,
      "y": 0,
      "z": -1,
      "name": "Rock_Gold_Brick_Smooth_Half",
      "rotation": 8
    },
    {
      "x": -7,
      "y": 1,
      "z": -1,
      "name": "Rock_Gold_Brick_Smooth"
    },
    {
      "x": -7,
      "y": 0,
      "z": 0,
      "name": "Rock_Gold_Brick_Decorative"
    },
    {
      "x": -7,
      "y": -1,
      "z": 1,
      "name": "Rock_Gold_Brick_Smooth_Half",
      "rotation": 8
    },
    {
      "x": -7,
      "y": 0,
      "z": 1,
      "name": "Rock_Gold_Brick_Smooth"
    },
    {
      "x": -7,
      "y": -1,
      "z": 2,
      "name": "Rock_Gold_Brick_Smooth"
    },
    {
      "x": -7,
      "y": 0,
      "z": 2,
      "name": "Plant_Moss_Short_Green",
      "support": 15
    },
    {
      "x": -7,
      "y": -2,
      "z": 4,
      "name": "Rock_Gold_Brick_Smooth_Half",
      "rotation": 6
    },
    {
      "x": -7,
      "y": -2,
      "z": 5,
      "name": "Rock_Gold_Brick_Smooth_Half",
      "rotation": 4
    },
    {
      "x": -6,
      "y": 3,
      "z": -5,
      "name": "Plant_Moss_Wall_Green",
      "support": 15,
      "rotation": 3
    },
    {
      "x": -6,
      "y": 2,
      "z": -4,
      "name": "Soil_Clay_Smooth_Yellow"
    },
    {
      "x": -6,
      "y": 1,
      "z": -3,
      "name": "Rock_Gold_Brick_Smooth_Half",
      "rotation": 8
    },
    {
      "x": -6,
      "y": 2,
      "z": -3,
      "name": "Rock_Gold_Brick_Smooth"
    },
    {
      "x": -6,
      "y": 3,
      "z": -3,
      "name": "Plant_Moss_Rug_Green",
      "support": 15
    },
    {
      "x": -6,
      "y": 0,
      "z": 0,
      "name": "Rock_Gold_Brick"
    },
    {
      "x": -6,
      "y": 1,
      "z": 0,
      "name": "Plant_Moss_Rug_Green",
      "support": 15
    },
    {
      "x": -6,
      "y": -2,
      "z": 3,
      "name": "Rock_Gold_Brick_Smooth_Half",
      "rotation": 8
    },
    {
      "x": -6,
      "y": -1,
      "z": 3,
      "name": "Soil_Clay_Smooth_Yellow"
    },
    {
      "x": -6,
      "y": 0,
      "z": 3,
      "name": "Plant_Moss_Short_Green",
      "support": 15
    },
    {
      "x": -6,
      "y": -2,
      "z": 4,
      "name": "Soil_Clay_Smooth_Yellow"
    },
    {
      "x": -5,
      "y": 4,
      "z": -7,
      "name": "Rock_Gold_Brick_Smooth_Half",
      "rotation": 7
    },
    {
      "x": -5,
      "y": 2,
      "z": -5,
      "name": "Rock_Gold_Brick_Smooth_Half",
      "rotation": 8
    },
    {
      "x": -5,
      "y": 3,
      "z": -5,
      "name": "Soil_Clay_Smooth_Yellow"
    },
    {
      "x": -5,
      "y": 4,
      "z": -5,
      "name": "Plant_Moss_Rug_Green",
      "support": 15
    },
    {
      "x": -5,
      "y": 0,
      "z": 0,
      "name": "Rock_Gold_Brick_Beam",
      "rotation": 5
    },
    {
      "x": -5,
      "y": -3,
      "z": 5,
      "name": "Rock_Gold_Brick_Smooth_Half",
      "rotation": 8
    },
    {
      "x": -5,
      "y": -2,
      "z": 5,
      "name": "Rock_Gold_Brick_Smooth"
    },
    {
      "x": -5,
      "y": -1,
      "z": 5,
      "name": "Plant_Moss_Rug_Green",
      "support": 15
    },
    {
      "x": -5,
      "y": -3,
      "z": 7,
      "name": "Rock_Gold_Brick_Smooth_Half",
      "rotation": 7
    },
    {
      "x": -4,
      "y": 4,
      "z": -7,
      "name": "Rock_Gold_Brick_Smooth_Half",
      "rotation": 5
    },
    {
      "x": -4,
      "y": 3,
      "z": -6,
      "name": "Rock_Gold_Brick_Smooth"
    },
    {
      "x": -4,
      "y": 4,
      "z": -6,
      "name": "Plant_Moss_Rug_Green",
      "support": 15
    },
    {
      "x": -4,
      "y": 2,
      "z": -4,
      "name": "Rock_Gold_Brick_Smooth"
    },
    {
      "x": -4,
      "y": 0,
      "z": 0,
      "name": "Rock_Gold_Brick_Beam",
      "rotation": 5
    },
    {
      "x": -4,
      "y": -2,
      "z": 4,
      "name": "Rock_Gold_Brick_Smooth"
    },
    {
      "x": -4,
      "y": -1,
      "z": 4,
      "name": "Plant_Moss_Rug_Green",
      "support": 15
    },
    {
      "x": -4,
      "y": -3,
      "z": 6,
      "name": "Rock_Gold_Brick_Smooth"
    },
    {
      "x": -4,
      "y": -3,
      "z": 7,
      "name": "Rock_Gold_Brick_Smooth_Half",
      "rotation": 5
    },
    {
      "x": -3,
      "y": 3,
      "z": -6,
      "name": "Soil_Clay_Smooth_Yellow"
    },
    {
      "x": -3,
      "y": 4,
      "z": -6,
      "name": "Plant_Moss_Rug_Green",
      "support": 15
    },
    {
      "x": -3,
      "y": 1,
      "z": -3,
      "name": "Rock_Gold_Brick_Smooth_Half",
      "rotation": 8
    },
    {
      "x": -3,
      "y": 2,
      "z": -3,
      "name": "Rock_Gold_Brick_Smooth_Half"
    },
    {
      "x": -3,
      "y": 0,
      "z": 0,
      "name": "Rock_Gold_Brick_Beam",
      "rotation": 5
    },
    {
      "x": -3,
      "y": -2,
      "z": 3,
      "name": "Rock_Gold_Brick_Smooth_Half",
      "rotation": 8
    },
    {
      "x": -3,
      "y": -1,
      "z": 3,
      "name": "Rock_Gold_Brick_Smooth_Half"
    },
    {
      "x": -3,
      "y": -3,
      "z": 6,
      "name": "Rock_Gold_Brick_Smooth"
    },
    {
      "x": -2,
      "y": 4,
      "z": -7,
      "name": "Rock_Gold_Brick_Smooth"
    },
    {
      "x": -2,
      "y": 1,
      "z": -2,
      "name": "Rock_Gold_Brick_Smooth"
    },
    {
      "x": -2,
      "y": 1,
      "z": -1,
      "name": "Plant_Moss_Wall_Green",
      "support": 15,
      "rotation": 3
    },
    {
      "x": -2,
      "y": 0,
      "z": 0,
      "name": "Rock_Gold_Brick_Beam",
      "rotation": 5
    },
    {
      "x": -2,
      "y": -1,
      "z": 2,
      "name": "Rock_Gold_Brick_Smooth"
    },
    {
      "x": -2,
      "y": -3,
      "z": 7,
      "name": "Rock_Gold_Brick_Smooth"
    },
    {
      "x": -1,
      "y": 4,
      "z": -8,
      "name": "Rock_Gold_Brick_Smooth"
    },
    {
      "x": -1,
      "y": 3,
      "z": -7,
      "name": "Plant_Moss_Cave_Green",
      "support": 15,
      "rotation": 8
    },
    {
      "x": -1,
      "y": 4,
      "z": -7,
      "name": "Soil_Clay_Smooth_Yellow"
    },
    {
      "x": -1,
      "y": 0,
      "z": -1,
      "name": "Rock_Gold_Brick_Smooth_Half",
      "rotation": 8
    },
    {
      "x": -1,
      "y": 1,
      "z": -1,
      "name": "Soil_Clay_Smooth_Yellow"
    },
    {
      "x": -1,
      "y": 2,
      "z": -1,
      "name": "Plant_Moss_Short_Green",
      "support": 15
    },
    {
      "x": -1,
      "y": 0,
      "z": 0,
      "name": "Rock_Gold_Brick"
    },
    {
      "x": -1,
      "y": 1,
      "z": 0,
      "name": "Rock_Gold_Brick_Smooth_Half"
    },
    {
      "x": -1,
      "y": -1,
      "z": 1,
      "name": "Rock_Gold_Brick_Smooth_Half",
      "rotation": 8
    },
    {
      "x": -1,
      "y": 0,
      "z": 1,
      "name": "Rock_Gold_Brick"
    },
    {
      "x": -1,
      "y": 1,
      "z": 1,
      "name": "Plant_Moss_Short_Green",
      "support": 15
    },
    {
      "x": -1,
      "y": -3,
      "z": 7,
      "name": "Soil_Clay_Smooth_Yellow"
    },
    {
      "x": -1,
      "y": -3,
      "z": 8,
      "name": "Rock_Gold_Brick_Smooth"
    },
    {
      "x": 0,
      "y": 4,
      "z": -8,
      "name": "Plant_Moss_Wall_Green",
      "support": 15,
      "rotation": 3
    },
    {
      "x": 0,
      "y": 3,
      "z": -7,
      "name": "Rock_Gold_Brick_Smooth_Half",
      "rotation": 8
    },
    {
      "x": 0,
      "y": 4,
      "z": -7,
      "name": "Rock_Gold_Brick_Decorative"
    },
    {
      "x": 0,
      "y": 2,
      "z": -6,
      "name": "Plant_Moss_Cave_Green",
      "support": 15,
      "rotation": 8
    },
    {
      "x": 0,
      "y": 3,
      "z": -6,
      "name": "Rock_Gold_Brick"
    },
    {
      "x": 0,
      "y": 2,
      "z": -5,
      "name": "Rock_Gold_Brick_Smooth_Half",
      "rotation": 8
    },
    {
      "x": 0,
      "y": 3,
      "z": -5,
      "name": "Rock_Gold_Brick_Smooth_Half"
    },
    {
      "x": 0,
      "y": 2,
      "z": -4,
      "name": "Rock_Gold_Brick_Smooth"
    },
    {
      "x": 0,
      "y": 1,
      "z": -3,
      "name": "Rock_Gold_Brick_Smooth_Half",
      "rotation": 8
    },
    {
      "x": 0,
      "y": 2,
      "z": -3,
      "name": "Rock_Gold_Brick_Smooth_Half"
    },
    {
      "x": 0,
      "y": 1,
      "z": -2,
      "name": "Rock_Gold_Brick_Smooth"
    },
    {
      "x": 0,
      "y": 0,
      "z": -1,
      "name": "Rock_Gold_Brick_Smooth_Half",
      "rotation": 8
    },
    {
      "x": 0,
      "y": 1,
      "z": -1,
      "name": "Rock_Gold_Brick_Smooth"
    },
    {
      "x": 0,
      "y": 0,
      "z": 0,
      "name": "Rock_Gold_Brick"
    },
    {
      "x": 0,
      "y": 0,
      "z": 1,
      "name": "Rock_Gold_Brick"
    },
    {
      "x": 0,
      "y": -1,
      "z": 2,
      "name": "Rock_Gold_Brick_Smooth"
    },
    {
      "x": 0,
      "y": -2,
      "z": 3,
      "name": "Rock_Gold_Brick_Smooth_Half",
      "rotation": 8
    },
    {
      "x": 0,
      "y": -1,
      "z": 3,
      "name": "Rock_Gold_Brick_Smooth_Half"
    },
    {
      "x": 0,
      "y": -2,
      "z": 4,
      "name": "Rock_Gold_Brick_Smooth"
    },
    {
      "x": 0,
      "y": -3,
      "z": 5,
      "name": "Rock_Gold_Brick_Smooth_Half",
      "rotation": 8
    },
    {
      "x": 0,
      "y": -2,
      "z": 5,
      "name": "Rock_Gold_Brick_Smooth_Half"
    },
    {
      "x": 0,
      "y": -3,
      "z": 6,
      "name": "Soil_Clay_Smooth_Yellow"
    },
    {
      "x": 0,
      "y": -3,
      "z": 7,
      "name": "Rock_Gold_Brick_Decorative"
    },
    {
      "x": 1,
      "y": 4,
      "z": -9,
      "name": "Plant_Moss_Wall_Green",
      "support": 15,
      "rotation": 2
    },
    {
      "x": 1,
      "y": 4,
      "z": -8,
      "name": "Rock_Gold_Brick_Smooth"
    },
    {
      "x": 1,
      "y": 5,
      "z": -8,
      "name": "Plant_Moss_Rug_Green",
      "support": 15
    },
    {
      "x": 1,
      "y": 4,
      "z": -7,
      "name": "Rock_Gold_Brick"
    },
    {
      "x": 1,
      "y": 0,
      "z": -1,
      "name": "Rock_Gold_Brick_Smooth_Half",
      "rotation": 8
    },
    {
      "x": 1,
      "y": 1,
      "z": -1,
      "name": "Rock_Gold_Brick_Smooth"
    },
    {
      "x": 1,
      "y": 2,
      "z": -1,
      "name": "Plant_Moss_Rug_Green",
      "support": 15
    },
    {
      "x": 1,
      "y": 0,
      "z": 0,
      "name": "Rock_Gold_Brick_Smooth"
    },
    {
      "x": 1,
      "y": 1,
      "z": 0,
      "name": "Rock_Gold_Brick_Smooth_Half"
    },
    {
      "x": 1,
      "y": -1,
      "z": 1,
      "name": "Rock_Gold_Brick_Smooth_Half",
      "rotation": 8
    },
    {
      "x": 1,
      "y": 0,
      "z": 1,
      "name": "Rock_Gold_Brick_Smooth"
    },
    {
      "x": 1,
      "y": -3,
      "z": 7,
      "name": "Rock_Gold_Brick_Smooth"
    },
    {
      "x": 1,
      "y": -3,
      "z": 8,
      "name": "Rock_Gold_Brick_Smooth"
    },
    {
      "x": 1,
      "y": -2,
      "z": 8,
      "name": "Plant_Moss_Rug_Green",
      "support": 15
    },
    {
      "x": 2,
      "y": 4,
      "z": -7,
      "name": "Rock_Gold_Brick"
    },
    {
      "x": 2,
      "y": 5,
      "z": -7,
      "name": "Plant_Moss_Short_Green",
      "support": 15
    },
    {
      "x": 2,
      "y": 1,
      "z": -2,
      "name": "Rock_Gold_Brick_Smooth"
    },
    {
      "x": 2,
      "y": 2,
      "z": -2,
      "name": "Plant_Moss_Rug_Green",
      "support": 15
    },
    {
      "x": 2,
      "y": 0,
      "z": 0,
      "name": "Rock_Gold_Brick_Beam",
      "rotation": 5
    },
    {
      "x": 2,
      "y": -1,
      "z": 2,
      "name": "Rock_Gold_Brick_Smooth"
    },
    {
      "x": 2,
      "y": -3,
      "z": 7,
      "name": "Rock_Gold_Brick_Smooth"
    },
    {
      "x": 3,
      "y": 3,
      "z": -6,
      "name": "Rock_Gold_Brick"
    },
    {
      "x": 3,
      "y": 1,
      "z": -3,
      "name": "Rock_Gold_Brick_Smooth_Half",
      "rotation": 8
    },
    {
      "x": 3,
      "y": 2,
      "z": -3,
      "name": "Rock_Gold_Brick_Smooth_Half"
    },
    {
      "x": 3,
      "y": 0,
      "z": 0,
      "name": "Rock_Gold_Brick_Beam",
      "rotation": 5
    },
    {
      "x": 3,
      "y": -2,
      "z": 3,
      "name": "Rock_Gold_Brick_Smooth_Half",
      "rotation": 8
    },
    {
      "x": 3,
      "y": -1,
      "z": 3,
      "name": "Rock_Gold_Brick_Smooth_Half"
    },
    {
      "x": 3,
      "y": -3,
      "z": 6,
      "name": "Rock_Gold_Brick_Smooth"
    },
    {
      "x": 3,
      "y": -2,
      "z": 6,
      "name": "Plant_Moss_Rug_Green",
      "support": 15
    },
    {
      "x": 4,
      "y": 4,
      "z": -7,
      "name": "Rock_Gold_Brick_Smooth_Half",
      "rotation": 7
    },
    {
      "x": 4,
      "y": 3,
      "z": -6,
      "name": "Rock_Gold_Brick_Smooth"
    },
    {
      "x": 4,
      "y": 2,
      "z": -4,
      "name": "Rock_Gold_Brick_Smooth"
    },
    {
      "x": 4,
      "y": 3,
      "z": -4,
      "name": "Plant_Moss_Short_Green",
      "support": 15
    },
    {
      "x": 4,
      "y": 0,
      "z": 0,
      "name": "Rock_Gold_Brick_Beam",
      "rotation": 5
    },
    {
      "x": 4,
      "y": -2,
      "z": 4,
      "name": "Rock_Gold_Brick"
    },
    {
      "x": 4,
      "y": -1,
      "z": 4,
      "name": "Plant_Moss_Short_Green",
      "support": 15
    },
    {
      "x": 4,
      "y": -3,
      "z": 6,
      "name": "Rock_Gold_Brick_Smooth"
    },
    {
      "x": 4,
      "y": -2,
      "z": 6,
      "name": "Plant_Moss_Rug_Green",
      "support": 15
    },
    {
      "x": 4,
      "y": -3,
      "z": 7,
      "name": "Rock_Gold_Brick_Smooth_Half",
      "rotation": 7
    },
    {
      "x": 5,
      "y": 4,
      "z": -7,
      "name": "Rock_Gold_Brick_Smooth_Half",
      "rotation": 5
    },
    {
      "x": 5,
      "y": 2,
      "z": -5,
      "name": "Rock_Gold_Brick_Smooth_Half",
      "rotation": 8
    },
    {
      "x": 5,
      "y": 3,
      "z": -5,
      "name": "Rock_Gold_Brick_Smooth"
    },
    {
      "x": 5,
      "y": 0,
      "z": 0,
      "name": "Rock_Gold_Brick_Beam",
      "rotation": 5
    },
    {
      "x": 5,
      "y": -3,
      "z": 5,
      "name": "Rock_Gold_Brick_Smooth_Half",
      "rotation": 8
    },
    {
      "x": 5,
      "y": -2,
      "z": 5,
      "name": "Rock_Gold_Brick"
    },
    {
      "x": 5,
      "y": -3,
      "z": 7,
      "name": "Rock_Gold_Brick_Smooth_Half",
      "rotation": 5
    },
    {
      "x": 6,
      "y": 2,
      "z": -4,
      "name": "Rock_Gold_Brick_Smooth"
    },
    {
      "x": 6,
      "y": 3,
      "z": -4,
      "name": "Plant_Moss_Rug_Green",
      "support": 15
    },
    {
      "x": 6,
      "y": 1,
      "z": -3,
      "name": "Rock_Gold_Brick_Smooth_Half",
      "rotation": 8
    },
    {
      "x": 6,
      "y": 2,
      "z": -3,
      "name": "Rock_Gold_Brick_Smooth"
    },
    {
      "x": 6,
      "y": 0,
      "z": 0,
      "name": "Rock_Gold_Brick"
    },
    {
      "x": 6,
      "y": 1,
      "z": 0,
      "name": "Plant_Moss_Rug_Green",
      "support": 15
    },
    {
      "x": 6,
      "y": -2,
      "z": 3,
      "name": "Rock_Gold_Brick_Smooth_Half",
      "rotation": 8
    },
    {
      "x": 6,
      "y": -1,
      "z": 3,
      "name": "Rock_Gold_Brick_Smooth"
    },
    {
      "x": 6,
      "y": -2,
      "z": 4,
      "name": "Rock_Gold_Brick_Smooth"
    },
    {
      "x": 7,
      "y": 2,
      "z": -5,
      "name": "Rock_Gold_Brick_Smooth_Half",
      "rotation": 6
    },
    {
      "x": 7,
      "y": 2,
      "z": -4,
      "name": "Rock_Gold_Brick_Smooth_Half",
      "rotation": 4
    },
    {
      "x": 7,
      "y": 1,
      "z": -2,
      "name": "Rock_Gold_Brick"
    },
    {
      "x": 7,
      "y": 2,
      "z": -2,
      "name": "Plant_Moss_Rug_Green",
      "support": 15
    },
    {
      "x": 7,
      "y": 0,
      "z": -1,
      "name": "Rock_Gold_Brick_Smooth_Half",
      "rotation": 8
    },
    {
      "x": 7,
      "y": 1,
      "z": -1,
      "name": "Soil_Clay_Yellow"
    },
    {
      "x": 7,
      "y": 0,
      "z": 0,
      "name": "Rock_Gold_Brick_Decorative"
    },
    {
      "x": 7,
      "y": 1,
      "z": 0,
      "name": "Plant_Moss_Rug_Green",
      "support": 15
    },
    {
      "x": 7,
      "y": -1,
      "z": 1,
      "name": "Rock_Gold_Brick_Smooth_Half",
      "rotation": 8
    },
    {
      "x": 7,
      "y": 0,
      "z": 1,
      "name": "Rock_Gold_Brick_Smooth"
    },
    {
      "x": 7,
      "y": -1,
      "z": 2,
      "name": "Rock_Gold_Brick_Smooth"
    },
    {
      "x": 7,
      "y": -2,
      "z": 4,
      "name": "Rock_Gold_Brick_Smooth_Half",
      "rotation": 6
    },
    {
      "x": 7,
      "y": -2,
      "z": 5,
      "name": "Rock_Gold_Brick_Smooth_Half",
      "rotation": 4
    },
    {
      "x": 8,
      "y": 1,
      "z": -1,
      "name": "Soil_Clay_Smooth_Yellow"
    },
    {
      "x": 8,
      "y": 0,
      "z": 1,
      "name": "Rock_Gold_Brick_Smooth"
    },
    {
      "x": 8,
      "y": 1,
      "z": 1,
      "name": "Plant_Moss_Rug_Green",
      "support": 15
    }
  ]
}