{
  "version": 8,
  "blockIdVersion": 11,
  "anchorX": 0,
  "anchorY": 0,
  "anchorZ": 0,
  "blocks": [
    {
      "x": -3,
      "y": -1,
      "z": -1,
      "name": "Scrap_Metal_Smooth",
      "rotation": 2
    },
    {
      "x": -3,
      "y": 4,
      "z": -1,
      "name": "Scrap_Metal_Smooth",
      "rotation": 2
    },
    {
      "x": -3,
      "y": 9,
      "z": -1,
      "name": "Scrap_Metal_Smooth",
      "rotation": 2
    },
    {
      "x": -3,
      "y": 14,
      "z": -1,
      "name": "Scrap_Metal_Smooth",
      "rotation": 1
    },
    {
      "x": -3,
      "y": 17,
      "z": -1,
      "name": "Plant_Moss_Cave_Green",
      "support": 15,
      "rotation": 8
    },
    {
      "x": -3,
      "y": 18,
      "z": -1,
      "name": "Scrap_Metal_Smooth",
      "rotation": 2
    },
    {
      "x": -3,
      "y": 19,
      "z": -1,
      "name": "Scrap_Metal_Smooth",
      "rotation": 2
    },
    {
      "x": -3,
      "y": -1,
      "z": 0,
      "name": "Scrap_Metal_Smooth",
      "rotation": 2
    },
    {
      "x": -3,
      "y": 4,
      "z": 0,
      "name": "Scrap_Metal_Smooth",
      "rotation": 2
    },
    {
      "x": -3,
      "y": 9,
      "z": 0,
      "name": "Soil_Clay_Smooth_Orange"
    },
    {
      "x": -3,
      "y": 13,
      "z": 0,
      "name": "Scrap_Metal_Smooth",
      "rotation": 2
    },
    {
      "x": -3,
      "y": 14,
      "z": 0,
      "name": "Scrap_Metal_Smooth",
      "rotation": 2
    },
    {
      "x": -3,
      "y": 18,
      "z": 0,
      "name": "Scrap_Metal_Smooth",
      "rotation": 3
    },
    {
      "x": -3,
      "y": 19,
      "z": 0,
      "name": "Scrap_Metal_Panel"
    },
    {
      "x": -3,
      "y": -1,
      "z": 1,
      "name": "Scrap_Metal_Smooth",
      "rotation": 2
    },
    {
      "x": -3,
      "y": 4,
      "z": 1,
      "name": "Scrap_Metal_Smooth",
      "rotation": 3
    },
    {
      "x": -3,
      "y": 8,
      "z": 1,
      "name": "Soil_Clay_Smooth_Orange"
    },
    {
      "x": -3,
      "y": 9,
      "z": 1,
      "name": "Soil_Clay_Smooth_Red"
    },
    {
      "x": -3,
      "y": 13,
      "z": 1,
      "name": "Scrap_Metal_Smooth",
      "rotation": 2
    },
    {
      "x": -3,
      "y": 18,
      "z": 1,
      "name": "Scrap_Metal_Smooth",
      "rotation": 3
    },
    {
      "x": -3,
      "y": 19,
      "z": 1,
      "name": "Plant_Moss_Rug_Green",
      "support": 15
    },
    {
      "x": -2,
      "y": 0,
      "z": -2,
      "name": "Scrap_Metal_Smooth",
      "rotation": 2
    },
    {
      "x": -2,
      "y": 4,
      "z": -2,
      "name": "Scrap_Metal_Smooth",
      "rotation": 2
    },
    {
      "x": -2,
      "y": 5,
      "z": -2,
      "name": "Scrap_Metal_Smooth",
      "rotation": 2
    },
    {
      "x": -2,
      "y": 6,
      "z": -2,
      "name": "Plant_Moss_Rug_Green",
      "support": 15
    },
    {
      "x": -2,
      "y": 9,
      "z": -2,
      "name": "Scrap_Metal_Smooth",
      "rotation": 1
    },
    {
      "x": -2,
      "y": 14,
      "z": -2,
      "name": "Rock_Sandstone_Red"
    },
    {
      "x": -2,
      "y": 19,
      "z": -2,
      "name": "Scrap_Metal_Smooth",
      "rotation": 2
    },
    {
      "x": -2,
      "y": 0,
      "z": -1,
      "name": "Scrap_Metal_Smooth",
      "rotation": 1
    },
    {
      "x": -2,
      "y": 4,
      "z": -1,
      "name": "Scrap_Metal_Smooth",
      "rotation": 2
    },
    {
      "x": -2,
      "y": 9,
      "z": -1,
      "name": "Scrap_Metal_Smooth",
      "rotation": 1
    },
    {
      "x": -2,
      "y": 14,
      "z": -1,
      "name": "Scrap_Metal_Smooth",
      "rotation": 1
    },
    {
      "x": -2,
      "y": 19,
      "z": -1,
      "name": "Scrap_Metal_Smooth",
      "rotation": 2
    },
    {
      "x": -2,
      "y": -1,
      "z": 1,
      "name": "Scrap_Metal_Smooth",
      "rotation": 1
    },
    {
      "x": -2,
      "y": 3,
      "z": 1,
      "name": "Scrap_Metal_Smooth",
      "rotation": 2
    },
    {
      "x": -2,
      "y": 4,
      "z": 1,
      "name": "Scrap_Metal_Smooth",
      "rotation": 2
    },
    {
      "x": -2,
      "y": 8,
      "z": 1,
      "name": "Rock_Sandstone_Red"
    },
    {
      "x": -2,
      "y": 13,
      "z": 1,
      "name": "Scrap_Metal_Smooth",
      "rotation": 3
    },
    {
      "x": -2,
      "y": 18,
      "z": 1,
      "name": "Soil_Clay"
    },
    {
      "x": -2,
      "y": -1,
      "z": 2,
      "name": "Scrap_Metal_Smooth",
      "rotation": 1
    },
    {
      "x": -2,
      "y": 3,
      "z": 2,
      "name": "Scrap_Metal_Smooth",
      "rotation": 3
    },
    {
      "x": -2,
      "y": 8,
      "z": 2,
      "name": "Soil_Clay"
    },
    {
      "x": -2,
      "y": 13,
      "z": 2,
      "name": "Scrap_Metal_Smooth",
      "rotation": 3
    },
    {
      "x": -2,
      "y": 14,
      "z": 2,
      "name": "Plant_Moss_Rug_Green",
      "support": 15
    },
    {
      "x": -2,
      "y": 18,
      "z": 2,
      "name": "Rock_Sandstone_Red"
    },
    {
      "x": -2,
      "y": 19,
      "z": 2,
      "name": "Plant_Moss_Rug_Green",
      "support": 15
    },
    {
      "x": -1,
      "y": 0,
      "z": -3,
      "name": "Scrap_Metal_Smooth",
      "rotation": 1
    },
    {
      "x": -1,
      "y": 5,
      "z": -3,
      "name": "Scrap_Metal_Smooth",
      "rotation": 1
    },
    {
      "x": -1,
      "y": 6,
      "z": -3,
      "name": "Plant_Moss_Rug_Green",
      "support": 15
    },
    {
      "x": -1,
      "y": 9,
      "z": -3,
      "name": "Plant_Moss_Wall_Green",
      "support": 15,
      "rotation": 2
    },
    {
      "x": -1,
      "y": 10,
      "z": -3,
      "name": "Scrap_Metal_Smooth",
      "rotation": 1
    },
    {
      "x": -1,
      "y": 13,
      "z": -3,
      "name": "Plant_Moss_Cave_Green",
      "support": 15,
      "rotation": 8
    },
    {
      "x": -1,
      "y": 14,
      "z": -3,
      "name": "Scrap_Metal_Smooth",
      "rotation": 2
    },
    {
      "x": -1,
      "y": 15,
      "z": -3,
      "name": "Rock_Sandstone_Red"
    },
    {
      "x": -1,
      "y": 19,
      "z": -3,
      "name": "Scrap_Metal_Smooth",
      "rotation": 2
    },
    {
      "x": -1,
      "y": 0,
      "z": -2,
      "name": "Scrap_Metal_Smooth",
      "rotation": 1
    },
    {
      "x": -1,
      "y": 5,
      "z": -2,
      "name": "Scrap_Metal_Smooth",
      "rotation": 1
    },
    {
      "x": -1,
      "y": 8,
      "z": -2,
      "name": "Plant_Moss_Cave_Green",
      "support": 15,
      "rotation": 8
    },
    {
      "x": -1,
      "y": 9,
      "z": -2,
      "name": "Scrap_Metal_Smooth",
      "rotation": 1
    },
    {
      "x": -1,
      "y": 10,
      "z": -2,
      "name": "Scrap_Metal_Smooth",
      "rotation": 1
    },
    {
      "x": -1,
      "y": 14,
      "z": -2,
      "name": "Scrap_Metal_Smooth",
      "rotation": 1
    },
    {
      "x": -1,
      "y": 19,
      "z": -2,
      "name": "Scrap_Metal_Smooth",
      "rotation": 2
    },
    {
      "x": -1,
      "y": 8,
      "z": 1,
      "name": "Plant_Moss_Wall_Green",
      "support": 15,
      "rotation": 1
    },
    {
      "x": -1,
      "y": -2,
      "z": 2,
      "name": "Scrap_Metal_Smooth",
      "rotation": 3
    },
    {
      "x": -1,
      "y": 3,
      "z": 2,
      "name": "Scrap_Metal_Smooth",
      "rotation": 3
    },
    {
      "x": -1,
      "y": 8,
      "z": 2,
      "name": "Rock_Sandstone_Red"
    },
    {
      "x": -1,
      "y": 13,
      "z": 2,
      "name": "Scrap_Metal_Smooth",
      "rotation": 3
    },
    {
      "x": -1,
      "y": 17,
      "z": 2,
      "name": "Soil_Clay_Smooth_Orange"
    },
    {
      "x": -1,
      "y": 18,
      "z": 2,
      "name": "Soil_Clay"
    },
    {
      "x": -1,
      "y": -2,
      "z": 3,
      "name": "Scrap_Metal_Smooth"
    },
    {
      "x": -1,
      "y": 3,
      "z": 3,
      "name": "Scrap_Metal_Smooth",
      "rotation": 3
    },
    {
      "x": -1,
      "y": 8,
      "z": 3,
      "name": "Soil_Clay"
    },
    {
      "x": -1,
      "y": 12,
      "z": 3,
      "name": "Scrap_Metal_Smooth",
      "rotation": 3
    },
    {
      "x": -1,
      "y": 13,
      "z": 3,
      "name": "Scrap_Metal_Smooth",
      "rotation": 3
    },
    {
      "x": -1,
      "y": 14,
      "z": 3,
      "name": "Plant_Moss_Rug_Green",
      "support": 15
    },
    {
      "x": -1,
      "y": 17,
      "z": 3,
      "name": "Rock_Sandstone_Red"
    },
    {
      "x": -1,
      "y": 3,
      "z": 4,
      "name": "Plant_Moss_Wall_Green",
      "support": 15
    },
    {
      "x": 0,
      "y": 10,
      "z": -4,
      "name": "Plant_Moss_Wall_Green",
      "support": 15,
      "rotation": 2
    },
    {
      "x": 0,
      "y": 0,
      "z": -3,
      "name": "Scrap_Metal_Smooth",
      "rotation": 1
    },
    {
      "x": 0,
      "y": 5,
      "z": -3,
      "name": "Scrap_Metal_Smooth",
      "rotation": 1
    },
    {
      "x": 0,
      "y": 6,
      "z": -3,
      "name": "Plant_Moss_Rug_Green",
      "support": 15
    },
    {
      "x": 0,
      "y": 10,
      "z": -3,
      "name": "Scrap_Metal_Smooth",
      "rotation": 2
    },
    {
      "x": 0,
      "y": 15,
      "z": -3,
      "name": "Scrap_Metal_Smooth",
      "rotation": 1
    },
    {
      "x": 0,
      "y": 16,
      "z": -3,
      "name": "Scrap_Metal_Panel"
    },
    {
      "x": 0,
      "y": 19,
      "z": -3,
      "name": "Scrap_Metal_Smooth",
      "rotation": 1
    },
    {
      "x": 0,
      "y": 20,
      "z": -3,
      "name": "Scrap_Metal_Smooth",
      "rotation": 1
    },
    {
      "x": 0,
      "y": -2,
      "z": 3,
      "name": "Scrap_Metal_Smooth"
    },
    {
      "x": 0,
      "y": 3,
      "z": 3,
      "name": "Scrap_Metal_Smooth",
      "rotation": 3
    },
    {
      "x": 0,
      "y": 7,
      "z": 3,
      "name": "Scrap_Metal_Smooth",
      "rotation": 3
    },
    {
      "x": 0,
      "y": 8,
      "z": 3,
      "name": "Rock_Sandstone_Red"
    },
    {
      "x": 0,
      "y": 12,
      "z": 3,
      "name": "Scrap_Metal_Smooth",
      "rotation": 3
    },
    {
      "x": 0,
      "y": 13,
      "z": 3,
      "name": "Scrap_Metal_Panel"
    },
    {
      "x": 0,
      "y": 17,
      "z": 3,
      "name": "Rock_Sandstone_Red"
    },
    {
      "x": 1,
      "y": 0,
      "z": -3,
      "name": "Scrap_Metal_Smooth",
      "rotation": 1
    },
    {
      "x": 1,
      "y": 1,
      "z": -3,
      "name": "Scrap_Metal_Smooth",
      "rotation": 1
    },
    {
      "x": 1,
      "y": 5,
      "z": -3,
      "name": "Rock_Sandstone_Red"
    },
    {
      "x": 1,
      "y": 10,
      "z": -3,
      "name": "Scrap_Metal_Smooth",
      "rotation": 2
    },
    {
      "x": 1,
      "y": 15,
      "z": -3,
      "name": "Scrap_Metal_Smooth",
      "rotation": 1
    },
    {
      "x": 1,
      "y": 20,
      "z": -3,
      "name": "Scrap_Metal_Smooth",
      "rotation": 1
    },
    {
      "x": 1,
      "y": 1,
      "z": -2,
      "name": "Scrap_Metal_Smooth",
      "rotation": 1
    },
    {
      "x": 1,
      "y": 5,
      "z": -2,
      "name": "Soil_Clay"
    },
    {
      "x": 1,
      "y": 6,
      "z": -2,
      "name": "Soil_Clay"
    },
    {
      "x": 1,
      "y": 10,
      "z": -2,
      "name": "Scrap_Metal_Smooth",
      "rotation": 1
    },
    {
      "x": 1,
      "y": 15,
      "z": -2,
      "name": "Scrap_Metal_Smooth",
      "rotation": 1
    },
    {
      "x": 1,
      "y": 16,
      "z": -2,
      "name": "Scrap_Metal_Panel"
    },
    {
      "x": 1,
      "y": 20,
      "z": -2,
      "name": "Scrap_Metal_Smooth"
    },
    {
      "x": 1,
      "y": -2,
      "z": 2,
      "name": "Scrap_Metal_Smooth",
      "rotation": 3
    },
    {
      "x": 1,
      "y": 2,
      "z": 2,
      "name": "Scrap_Metal_Smooth",
      "rotation": 3
    },
    {
      "x": 1,
      "y": 7,
      "z": 2,
      "name": "Scrap_Metal_Smooth"
    },
    {
      "x": 1,
      "y": 8,
      "z": 2,
      "name": "Scrap_Metal_Panel"
    },
    {
      "x": 1,
      "y": 12,
      "z": 2,
      "name": "Scrap_Metal_Smooth",
      "rotation": 3
    },
    {
      "x": 1,
      "y": 13,
      "z": 2,
      "name": "Scrap_Metal_Panel"
    },
    {
      "x": 1,
      "y": 17,
      "z": 2,
      "name": "Scrap_Metal_Smooth",
      "rotation": 3
    },
    {
      "x": 1,
      "y": 21,
      "z": 2,
      "name": "Scrap_Metal_Smooth",
      "rotation": 3
    },
    {
      "x": 1,
      "y": 22,
      "z": 2,
      "name": "Plant_Moss_Rug_Green",
      "support": 15
    },
    {
      "x": 1,
      "y": -2,
      "z": 3,
      "name": "Scrap_Metal_Smooth",
      "rotation": 3
    },
    {
      "x": 1,
      "y": 2,
      "z": 3,
      "name": "Scrap_Metal_Smooth"
    },
    {
      "x": 1,
      "y": 3,
      "z": 3,
      "name": "Scrap_Metal_Smooth"
    },
    {
      "x": 1,
      "y": 7,
      "z": 3,
      "name": "Rock_Sandstone_Red"
    },
    {
      "x": 1,
      "y": 12,
      "z": 3,
      "name": "Scrap_Metal_Smooth",
      "rotation": 3
    },
    {
      "x": 1,
      "y": 17,
      "z": 3,
      "name": "Scrap_Metal_Smooth",
      "rotation": 3
    },
    {
      "x": 1,
      "y": 21,
      "z": 3,
      "name": "Plant_Moss_Wall_Green",
      "support": 15
    },
    {
      "x": 1,
      "y": 12,
      "z": 4,
      "name": "Plant_Moss_Wall_Green",
      "support": 15
    },
    {
      "x": 2,
      "y": 1,
      "z": -2,
      "name": "Scrap_Metal_Smooth",
      "rotation": 1
    },
    {
      "x": 2,
      "y": 6,
      "z": -2,
      "name": "Rock_Sandstone_Red"
    },
    {
      "x": 2,
      "y": 10,
      "z": -2,
      "name": "Scrap_Metal_Smooth",
      "rotation": 1
    },
    {
      "x": 2,
      "y": 11,
      "z": -2,
      "name": "Scrap_Metal_Smooth",
      "rotation": 3
    },
    {
      "x": 2,
      "y": 15,
      "z": -2,
      "name": "Scrap_Metal_Smooth",
      "rotation": 1
    },
    {
      "x": 2,
      "y": 20,
      "z": -2,
      "name": "Scrap_Metal_Smooth"
    },
    {
      "x": 2,
      "y": 1,
      "z": -1,
      "name": "Scrap_Metal_Smooth",
      "rotation": 1
    },
    {
      "x": 2,
      "y": 6,
      "z": -1,
      "name": "Soil_Clay"
    },
    {
      "x": 2,
      "y": 11,
      "z": -1,
      "name": "Scrap_Metal_Smooth",
      "rotation": 3
    },
    {
      "x": 2,
      "y": 15,
      "z": -1,
      "name": "Scrap_Metal_Smooth"
    },
    {
      "x": 2,
      "y": 16,
      "z": -1,
      "name": "Scrap_Metal_Smooth"
    },
    {
      "x": 2,
      "y": 20,
      "z": -1,
      "name": "Scrap_Metal_Smooth"
    },
    {
      "x": 2,
      "y": 2,
      "z": 1,
      "name": "Scrap_Metal_Smooth",
      "rotation": 3
    },
    {
      "x": 2,
      "y": 3,
      "z": 1,
      "name": "Scrap_Metal_Panel"
    },
    {
      "x": 2,
      "y": 7,
      "z": 1,
      "name": "Scrap_Metal_Smooth"
    },
    {
      "x": 2,
      "y": 11,
      "z": 1,
      "name": "Scrap_Metal_Smooth"
    },
    {
      "x": 2,
      "y": 12,
      "z": 1,
      "name": "Scrap_Metal_Smooth",
      "rotation": 3
    },
    {
      "x": 2,
      "y": 16,
      "z": 1,
      "name": "Scrap_Metal_Smooth"
    },
    {
      "x": 2,
      "y": 17,
      "z": 1,
      "name": "Scrap_Metal_Panel"
    },
    {
      "x": 2,
      "y": 21,
      "z": 1,
      "name": "Scrap_Metal_Smooth",
      "rotation": 3
    },
    {
      "x": 2,
      "y": 2,
      "z": 2,
      "name": "Scrap_Metal_Smooth",
      "rotation": 3
    },
    {
      "x": 2,
      "y": 7,
      "z": 2,
      "name": "Scrap_Metal_Smooth"
    },
    {
      "x": 2,
      "y": 12,
      "z": 2,
      "name": "Scrap_Metal_Smooth"
    },
    {
      "x": 2,
      "y": 13,
      "z": 2,
      "name": "Plant_Moss_Rug_Green",
      "support": 15
    },
    {
      "x": 2,
      "y": 16,
      "z": 2,
      "name": "Scrap_Metal_Smooth"
    },
    {
      "x": 2,
      "y": 17,
      "z": 2,
      "name": "Scrap_Metal_Smooth"
    },
    {
      "x": 2,
      "y": 20,
      "z": 2,
      "name": "Plant_Moss_Cave_Green",
      "support": 15,
      "rotation": 8
    },
    {
      "x": 2,
      "y": 21,
      "z": 2,
      "name": "Scrap_Metal_Smooth",
      "rotation": 3
    },
    {
      "x": 2,
      "y": 22,
      "z": 2,
      "name": "Plant_Moss_Rug_Green",
      "support": 15
    },
    {
      "x": 3,
      "y": 1,
      "z": -1,
      "name": "Scrap_Metal_Smooth"
    },
    {
      "x": 3,
      "y": 6,
      "z": -1,
      "name": "Rock_Sandstone_Red"
    },
    {
      "x": 3,
      "y": 10,
      "z": -1,
      "name": "Plant_Moss_Cave_Green",
      "support": 15,
      "rotation": 8
    },
    {
      "x": 3,
      "y": 11,
      "z": -1,
      "name": "Scrap_Metal_Smooth"
    },
    {
      "x": 3,
      "y": 16,
      "z": -1,
      "name": "Scrap_Metal_Smooth",
      "rotation": 1
    },
    {
      "x": 3,
      "y": 20,
      "z": -1,
      "name": "Scrap_Metal_Smooth"
    },
    {
      "x": 3,
      "y": 21,
      "z": -1,
      "name": "Scrap_Metal_Smooth"
    },
    {
      "x": 3,
      "y": 1,
      "z": 0,
      "name": "Scrap_Metal_Smooth"
    },
    {
      "x": 3,
      "y": 2,
      "z": 0,
      "name": "Scrap_Metal_Smooth"
    },
    {
      "x": 3,
      "y": 3,
      "z": 0,
      "name": "Scrap_Metal_Panel"
    },
    {
      "x": 3,
      "y": 6,
      "z": 0,
      "name": "Scrap_Metal_Smooth",
      "rotation": 1
    },
    {
      "x": 3,
      "y": 10,
      "z": 0,
      "name": "Plant_Moss_Cave_Green",
      "support": 15,
      "rotation": 8
    },
    {
      "x": 3,
      "y": 11,
      "z": 0,
      "name": "Scrap_Metal_Smooth"
    },
    {
      "x": 3,
      "y": 16,
      "z": 0,
      "name": "Scrap_Metal_Smooth"
    },
    {
      "x": 3,
      "y": 17,
      "z": 0,
      "name": "Plant_Moss_Rug_Green",
      "support": 15
    },
    {
      "x": 3,
      "y": 20,
      "z": 0,
      "name": "Plant_Moss_Cave_Green",
      "support": 15,
      "rotation": 8
    },
    {
      "x": 3,
      "y": 21,
      "z": 0,
      "name": "Scrap_Metal_Smooth"
    },
    {
      "x": 3,
      "y": 22,
      "z": 0,
      "name": "Plant_Moss_Rug_Green",
      "support": 15
    },
    {
      "x": 3,
      "y": 2,
      "z": 1,
      "name": "Scrap_Metal_Smooth",
      "rotation": 3
    },
    {
      "x": 3,
      "y": 6,
      "z": 1,
      "name": "Scrap_Metal_Smooth"
    },
    {
      "x": 3,
      "y": 7,
      "z": 1,
      "name": "Scrap_Metal_Smooth"
    },
    {
      "x": 3,
      "y": 11,
      "z": 1,
      "name": "Scrap_Metal_Smooth"
    },
    {
      "x": 3,
      "y": 16,
      "z": 1,
      "name": "Scrap_Metal_Smooth"
    },
    {
      "x": 3,
      "y": 17,
      "z": 1,
      "name": "Plant_Moss_Rug_Green",
      "support": 15
    },
    {
      "x": 3,
      "y": 21,
      "z": 1,
      "name": "Scrap_Metal_Smooth"
    },
    {
      "x": 3,
      "y": 22,
      "z": 1,
      "name": "Plant_Moss_Rug_Green",
      "support": 15
    },
    {
      "x": 4,
      "y": 11,
      "z": 0,
      "name": "Plant_Moss_Wall_Green",
      "support": 15,
      "rotation": 1
    },
    {
      "x": 4,
      "y": 21,
      "z": 0,
      "name": "Plant_Moss_Wall_Green",
      "support": 15,
      "rotation": 1
    },
    {
      "x": 4,
      "y": 11,
      "z": 1,
      "name": "Plant_Moss_Wall_Green",
      "support": 15,
      "rotation": 1
    }
  ]
}