{
  "version": 8,
  "blockIdVersion": 11,
  "anchorX": 0,
  "anchorY": 0,
  "anchorZ": 0,
  "blocks": [
    {
      "x": -11,
      "y": -1,
      "z": 11,
      "name": "Rock_Shale_Brick_Smooth_Half",
      "rotation": 7
    },
    {
      "x": -11,
      "y": 1,
      "z": 11,
      "name": "Rock_Shale_Brick_Smooth_Half",
      "rotation": 7
    },
    {
      "x": -10,
      "y": -4,
      "z": 10,
      "name": "Rock_Shale_Brick_Smooth_Half",
      "rotation": 8
    },
    {
      "x": -10,
      "y": -3,
      "z": 10,
      "name": "Rock_Shale_Brick_Smooth_Half",
      "rotation": 2
    },
    {
      "x": -10,
      "y": -1,
      "z": 10,
      "name": "Rock_Shale_Brick_Smooth",
      "rotation": 4
    },
    {
      "x": -10,
      "y": 1,
      "z": 10,
      "name": "Rock_Shale_Brick_Smooth",
      "rotation": 30
    },
    {
      "x": -10,
      "y": 3,
      "z": 10,
      "name": "Rock_Shale_Brick_Smooth_Half",
      "rotation": 8
    },
    {
      "x": -10,
      "y": 4,
      "z": 10,
      "name": "Rock_Shale_Brick_Smooth_Half",
      "rotation": 2
    },
    {
      "x": -10,
      "y": -1,
      "z": 11,
      "name": "Rock_Shale_Brick_Smooth_Half",
      "rotation": 5
    },
    {
      "x": -10,
      "y": 1,
      "z": 11,
      "name": "Rock_Shale_Brick_Smooth_Half",
      "rotation": 5
    },
    {
      "x": -9,
      "y": -6,
      "z": 9,
      "name": "Rock_Shale_Brick_Smooth_Half",
      "rotation": 8
    },
    {
      "x": -9,
      "y": -5,
      "z": 9,
      "name": "Rock_Shale_Brick_Smooth_Half",
      "rotation": 2
    },
    {
      "x": -9,
      "y": -3,
      "z": 9,
      "name": "Rock_Shale_Brick_Smooth",
      "rotation": 4
    },
    {
      "x": -9,
      "y": -2,
      "z": 9,
      "name": "Rock_Shale",
      "rotation": 4
    },
    {
      "x": -9,
      "y": -1,
      "z": 9,
      "name": "Rock_Shale_Brick_Smooth",
      "rotation": 4
    },
    {
      "x": -9,
      "y": 0,
      "z": 9,
      "name": "Rock_Shale",
      "rotation": 30
    },
    {
      "x": -9,
      "y": 1,
      "z": 9,
      "name": "Rock_Shale_Brick_Smooth",
      "rotation": 30
    },
    {
      "x": -9,
      "y": 2,
      "z": 9,
      "name": "Rock_Shale",
      "rotation": 30
    },
    {
      "x": -9,
      "y": 3,
      "z": 9,
      "name": "Rock_Shale_Brick_Smooth",
      "rotation": 30
    },
    {
      "x": -9,
      "y": 5,
      "z": 9,
      "name": "Rock_Shale_Brick_Smooth_Half",
      "rotation": 8
    },
    {
      "x": -9,
      "y": 6,
      "z": 9,
      "name": "Rock_Shale_Brick_Smooth_Half",
      "rotation": 2
    },
    {
      "x": -8,
      "y": 8,
      "z": 7,
      "name": "Rock_Shale_Brick_Smooth_Half",
      "rotation": 6
    },
    {
      "x": -8,
      "y": -8,
      "z": 8,
      "name": "Rock_Shale_Brick_Smooth",
      "rotation": 4
    },
    {
      "x": -8,
      "y": -5,
      "z": 8,
      "name": "Rock_Shale_Brick_Smooth",
      "rotation": 4
    },
    {
      "x": -8,
      "y": -4,
      "z": 8,
      "name": "Rock_Shale",
      "rotation": 4
    },
    {
      "x": -8,
      "y": -3,
      "z": 8,
      "name": "Rock_Shale",
      "rotation": 4
    },
    {
      "x": -8,
      "y": -2,
      "z": 8,
      "name": "Rock_Shale_Brick",
      "rotation": 4
    },
    {
      "x": -8,
      "y": -1,
      "z": 8,
      "name": "Rock_Shale_Brick",
      "rotation": 4
    },
    {
      "x": -8,
      "y": 0,
      "z": 8,
      "name": "Rock_Shale_Brick_Decorative"
    },
    {
      "x": -8,
      "y": 1,
      "z": 8,
      "name": "Rock_Shale_Brick",
      "rotation": 4
    },
    {
      "x": -8,
      "y": 2,
      "z": 8,
      "name": "Rock_Shale",
      "rotation": 30
    },
    {
      "x": -8,
      "y": 3,
      "z": 8,
      "name": "Rock_Shale",
      "rotation": 30
    },
    {
      "x": -8,
      "y": 4,
      "z": 8,
      "name": "Rock_Shale",
      "rotation": 30
    },
    {
      "x": -8,
      "y": 5,
      "z": 8,
      "name": "Rock_Shale_Brick_Smooth",
      "rotation": 30
    },
    {
      "x": -8,
      "y": 6,
      "z": 8,
      "name": "Plant_Moss_Rug_Green",
      "support": 15
    },
    {
      "x": -8,
      "y": 8,
      "z": 8,
      "name": "Rock_Shale_Brick_Smooth",
      "rotation": 30
    },
    {
      "x": -7,
      "y": -8,
      "z": 7,
      "name": "Rock_Shale_Brick_Smooth_Half",
      "rotation": 8
    },
    {
      "x": -7,
      "y": -7,
      "z": 7,
      "name": "Rock_Shale_Brick_Smooth",
      "rotation": 4
    },
    {
      "x": -7,
      "y": -6,
      "z": 7,
      "name": "Rock_Shale",
      "rotation": 4
    },
    {
      "x": -7,
      "y": -5,
      "z": 7,
      "name": "Rock_Shale_Brick",
      "rotation": 4
    },
    {
      "x": -7,
      "y": -4,
      "z": 7,
      "name": "Rock_Shale_Brick",
      "rotation": 4
    },
    {
      "x": -7,
      "y": -3,
      "z": 7,
      "name": "Rock_Shale",
      "rotation": 4
    },
    {
      "x": -7,
      "y": -2,
      "z": 7,
      "name": "Rock_Shale_Brick",
      "rotation": 4
    },
    {
      "x": -7,
      "y": -1,
      "z": 7,
      "name": "Rock_Shale",
      "rotation": 4
    },
    {
      "x": -7,
      "y": 0,
      "z": 7,
      "name": "Rock_Shale"
    },
    {
      "x": -7,
      "y": 1,
      "z": 7,
      "name": "Rock_Shale_Brick",
      "rotation": 4
    },
    {
      "x": -7,
      "y": 2,
      "z": 7,
      "name": "Rock_Shale_Brick",
      "rotation": 4
    },
    {
      "x": -7,
      "y": 3,
      "z": 7,
      "name": "Rock_Shale_Brick",
      "rotation": 4
    },
    {
      "x": -7,
      "y": 4,
      "z": 7,
      "name": "Rock_Shale",
      "rotation": 30
    },
    {
      "x": -7,
      "y": 5,
      "z": 7,
      "name": "Rock_Shale",
      "rotation": 30
    },
    {
      "x": -7,
      "y": 6,
      "z": 7,
      "name": "Rock_Shale",
      "rotation": 30
    },
    {
      "x": -7,
      "y": 7,
      "z": 7,
      "name": "Rock_Shale_Brick_Smooth",
      "rotation": 30
    },
    {
      "x": -7,
      "y": 8,
      "z": 7,
      "name": "Plant_Moss_Rug_Green",
      "support": 15
    },
    {
      "x": -6,
      "y": -9,
      "z": 6,
      "name": "Rock_Shale_Brick_Smooth_Half",
      "rotation": 7
    },
    {
      "x": -6,
      "y": -7,
      "z": 6,
      "name": "Rock_Shale",
      "rotation": 4
    },
    {
      "x": -6,
      "y": -6,
      "z": 6,
      "name": "Rock_Shale",
      "rotation": 4
    },
    {
      "x": -6,
      "y": -5,
      "z": 6,
      "name": "Rock_Shale_Brick",
      "rotation": 4
    },
    {
      "x": -6,
      "y": -4,
      "z": 6,
      "name": "Rock_Shale_Brick",
      "rotation": 4
    },
    {
      "x": -6,
      "y": -3,
      "z": 6,
      "name": "Rock_Shale_Brick",
      "rotation": 4
    },
    {
      "x": -6,
      "y": -2,
      "z": 6,
      "name": "Rock_Shale_Brick",
      "rotation": 4
    },
    {
      "x": -6,
      "y": -1,
      "z": 6,
      "name": "Rock_Shale_Brick",
      "rotation": 4
    },
    {
      "x": -6,
      "y": 0,
      "z": 6,
      "name": "Rock_Shale",
      "rotation": 30
    },
    {
      "x": -6,
      "y": 1,
      "z": 6,
      "name": "Rock_Shale_Brick",
      "rotation": 4
    },
    {
      "x": -6,
      "y": 2,
      "z": 6,
      "name": "Rock_Shale_Brick",
      "rotation": 4
    },
    {
      "x": -6,
      "y": 3,
      "z": 6,
      "name": "Rock_Shale_Brick",
      "rotation": 4
    },
    {
      "x": -6,
      "y": 4,
      "z": 6,
      "name": "Rock_Shale_Brick",
      "rotation": 4
    },
    {
      "x": -6,
      "y": 5,
      "z": 6,
      "name": "Rock_Shale_Brick",
      "rotation": 4
    },
    {
      "x": -6,
      "y": 6,
      "z": 6,
      "name": "Rock_Shale",
      "rotation": 30
    },
    {
      "x": -6,
      "y": 7,
      "z": 6,
      "name": "Rock_Shale",
      "rotation": 30
    },
    {
      "x": -6,
      "y": 9,
      "z": 6,
      "name": "Rock_Shale_Brick_Smooth_Half",
      "rotation": 7
    },
    {
      "x": -5,
      "y": -9,
      "z": 5,
      "name": "Rock_Shale_Brick_Smooth_Half",
      "rotation": 5
    },
    {
      "x": -5,
      "y": -8,
      "z": 5,
      "name": "Rock_Shale_Brick_Smooth",
      "rotation": 4
    },
    {
      "x": -5,
      "y": -7,
      "z": 5,
      "name": "Rock_Shale",
      "rotation": 4
    },
    {
      "x": -5,
      "y": -6,
      "z": 5,
      "name": "Rock_Shale_Brick",
      "rotation": 4
    },
    {
      "x": -5,
      "y": -5,
      "z": 5,
      "name": "Rock_Shale_Brick",
      "rotation": 4
    },
    {
      "x": -5,
      "y": -4,
      "z": 5,
      "name": "Rock_Shale_Brick_Half",
      "rotation": 5
    },
    {
      "x": -5,
      "y": -2,
      "z": 5,
      "name": "Rock_Shale_Brick_Half",
      "rotation": 5
    },
    {
      "x": -5,
      "y": -1,
      "z": 5,
      "name": "Rock_Shale_Brick",
      "rotation": 4
    },
    {
      "x": -5,
      "y": 0,
      "z": 5,
      "name": "Rock_Shale_Brick",
      "rotation": 4
    },
    {
      "x": -5,
      "y": 1,
      "z": 5,
      "name": "Rock_Shale_Brick",
      "rotation": 4
    },
    {
      "x": -5,
      "y": 2,
      "z": 5,
      "name": "Rock_Shale_Brick_Half",
      "rotation": 5
    },
    {
      "x": -5,
      "y": 4,
      "z": 5,
      "name": "Rock_Shale_Brick_Half",
      "rotation": 5
    },
    {
      "x": -5,
      "y": 5,
      "z": 5,
      "name": "Rock_Shale_Brick",
      "rotation": 4
    },
    {
      "x": -5,
      "y": 6,
      "z": 5,
      "name": "Rock_Shale_Brick",
      "rotation": 4
    },
    {
      "x": -5,
      "y": 7,
      "z": 5,
      "name": "Rock_Shale",
      "rotation": 30
    },
    {
      "x": -5,
      "y": 8,
      "z": 5,
      "name": "Rock_Shale_Brick_Smooth",
      "rotation": 30
    },
    {
      "x": -5,
      "y": 9,
      "z": 5,
      "name": "Rock_Shale_Brick_Smooth_Half",
      "rotation": 5
    },
    {
      "x": -5,
      "y": -3,
      "z": 6,
      "name": "Rock_Shale_Brick_Half",
      "rotation": 5
    },
    {
      "x": -5,
      "y": 3,
      "z": 6,
      "name": "Rock_Shale_Brick_Half",
      "rotation": 5
    },
    {
      "x": -4,
      "y": -10,
      "z": 4,
      "name": "Rock_Shale_Brick_Smooth_Half",
      "rotation": 7
    },
    {
      "x": -4,
      "y": -8,
      "z": 4,
      "name": "Rock_Shale",
      "rotation": 4
    },
    {
      "x": -4,
      "y": -7,
      "z": 4,
      "name": "Rock_Shale",
      "rotation": 4
    },
    {
      "x": -4,
      "y": -6,
      "z": 4,
      "name": "Rock_Shale_Brick",
      "rotation": 4
    },
    {
      "x": -4,
      "y": -5,
      "z": 4,
      "name": "Rock_Shale_Brick_Half",
      "rotation": 2
    },
    {
      "x": -4,
      "y": -1,
      "z": 4,
      "name": "Rock_Shale_Brick_Half",
      "rotation": 8
    },
    {
      "x": -4,
      "y": 0,
      "z": 4,
      "name": "Rock_Shale_Brick",
      "rotation": 4
    },
    {
      "x": -4,
      "y": 1,
      "z": 4,
      "name": "Rock_Shale_Brick_Half",
      "rotation": 2
    },
    {
      "x": -4,
      "y": 5,
      "z": 4,
      "name": "Rock_Shale_Brick_Half",
      "rotation": 8
    },
    {
      "x": -4,
      "y": 6,
      "z": 4,
      "name": "Rock_Shale_Brick",
      "rotation": 4
    },
    {
      "x": -4,
      "y": 7,
      "z": 4,
      "name": "Rock_Shale",
      "rotation": 30
    },
    {
      "x": -4,
      "y": 8,
      "z": 4,
      "name": "Rock_Shale",
      "rotation": 30
    },
    {
      "x": -4,
      "y": 10,
      "z": 4,
      "name": "Rock_Shale_Brick_Smooth_Half",
      "rotation": 7
    },
    {
      "x": -3,
      "y": -10,
      "z": 3,
      "name": "Rock_Shale_Brick_Smooth_Half",
      "rotation": 5
    },
    {
      "x": -3,
      "y": -9,
      "z": 3,
      "name": "Rock_Shale_Brick_Smooth",
      "rotation": 4
    },
    {
      "x": -3,
      "y": -8,
      "z": 3,
      "name": "Rock_Shale_Brick",
      "rotation": 4
    },
    {
      "x": -3,
      "y": -7,
      "z": 3,
      "name": "Rock_Shale_Brick",
      "rotation": 4
    },
    {
      "x": -3,
      "y": -6,
      "z": 3,
      "name": "Rock_Shale_Brick",
      "rotation": 4
    },
    {
      "x": -3,
      "y": 0,
      "z": 3,
      "name": "Rock_Shale_Brick",
      "rotation": 4
    },
    {
      "x": -3,
      "y": 1,
      "z": 3,
      "name": "Plant_Moss_Rug_Green",
      "support": 15
    },
    {
      "x": -3,
      "y": 5,
      "z": 3,
      "name": "Plant_Moss_Cave_Green",
      "support": 15,
      "rotation": 8
    },
    {
      "x": -3,
      "y": 6,
      "z": 3,
      "name": "Rock_Shale_Brick",
      "rotation": 4
    },
    {
      "x": -3,
      "y": 7,
      "z": 3,
      "name": "Rock_Shale",
      "rotation": 30
    },
    {
      "x": -3,
      "y": 8,
      "z": 3,
      "name": "Rock_Shale_Brick",
      "rotation": 4
    },
    {
      "x": -3,
      "y": 9,
      "z": 3,
      "name": "Rock_Shale_Brick_Smooth",
      "rotation": 30
    },
    {
      "x": -3,
      "y": 10,
      "z": 3,
      "name": "Rock_Shale_Brick_Smooth_Half",
      "rotation": 5
    },
    {
      "x": -2,
      "y": -9,
      "z": 2,
      "name": "Rock_Shale",
      "rotation": 4
    },
    {
      "x": -2,
      "y": -8,
      "z": 2,
      "name": "Rock_Shale_Brick",
      "rotation": 4
    },
    {
      "x": -2,
      "y": -7,
      "z": 2,
      "name": "Rock_Shale_Brick",
      "rotation": 4
    },
    {
      "x": -2,
      "y": -6,
      "z": 2,
      "name": "Rock_Shale_Brick",
      "rotation": 4
    },
    {
      "x": -2,
      "y": -5,
      "z": 2,
      "name": "Rock_Shale_Brick_Half",
      "rotation": 2
    },
    {
      "x": -2,
      "y": -1,
      "z": 2,
      "name": "Rock_Shale_Brick_Half",
      "rotation": 8
    },
    {
      "x": -2,
      "y": 0,
      "z": 2,
      "name": "Rock_Shale_Brick_Smooth",
      "rotation": 4
    },
    {
      "x": -2,
      "y": 1,
      "z": 2,
      "name": "Rock_Shale_Brick_Half",
      "rotation": 2
    },
    {
      "x": -2,
      "y": 5,
      "z": 2,
      "name": "Rock_Shale_Brick_Half",
      "rotation": 8
    },
    {
      "x": -2,
      "y": 6,
      "z": 2,
      "name": "Rock_Shale_Brick",
      "rotation": 4
    },
    {
      "x": -2,
      "y": 7,
      "z": 2,
      "name": "Rock_Shale_Brick",
      "rotation": 4
    },
    {
      "x": -2,
      "y": 8,
      "z": 2,
      "name": "Rock_Shale_Brick",
      "rotation": 4
    },
    {
      "x": -2,
      "y": 9,
      "z": 2,
      "name": "Rock_Shale",
      "rotation": 30
    },
    {
      "x": -1,
      "y": 9,
      "z": 0,
      "name": "Plant_Moss_Wall_Green",
      "support": 15,
      "rotation": 2
    },
    {
      "x": -1,
      "y": 10,
      "z": 0,
      "name": "Plant_Moss_Wall_Green",
      "support": 15,
      "rotation": 2
    },
    {
      "x": -1,
      "y": -11,
      "z": 1,
      "name": "Rock_Shale_Brick_Smooth_Half",
      "rotation": 8
    },
    {
      "x": -1,
      "y": -10,
      "z": 1,
      "name": "Rock_Shale_Brick_Smooth",
      "rotation": 4
    },
    {
      "x": -1,
      "y": -9,
      "z": 1,
      "name": "Rock_Shale_Brick_Smooth",
      "rotation": 4
    },
    {
      "x": -1,
      "y": -8,
      "z": 1,
      "name": "Rock_Shale_Brick",
      "rotation": 4
    },
    {
      "x": -1,
      "y": -7,
      "z": 1,
      "name": "Rock_Shale_Brick",
      "rotation": 4
    },
    {
      "x": -1,
      "y": -6,
      "z": 1,
      "name": "Rock_Shale_Brick",
      "rotation": 4
    },
    {
      "x": -1,
      "y": -5,
      "z": 1,
      "name": "Rock_Shale_Brick",
      "rotation": 4
    },
    {
      "x": -1,
      "y": -4,
      "z": 1,
      "name": "Rock_Shale_Brick_Half",
      "rotation": 7
    },
    {
      "x": -1,
      "y": -2,
      "z": 1,
      "name": "Rock_Shale_Brick_Half",
      "rotation": 7
    },
    {
      "x": -1,
      "y": -1,
      "z": 1,
      "name": "Rock_Shale_Brick",
      "rotation": 4
    },
    {
      "x": -1,
      "y": 0,
      "z": 1,
      "name": "Rock_Shale_Brick_Smooth_Half",
      "rotation": 5
    },
    {
      "x": -1,
      "y": 1,
      "z": 1,
      "name": "Rock_Shale_Brick",
      "rotation": 4
    },
    {
      "x": -1,
      "y": 2,
      "z": 1,
      "name": "Rock_Shale_Brick_Half",
      "rotation": 7
    },
    {
      "x": -1,
      "y": 4,
      "z": 1,
      "name": "Rock_Shale_Brick_Half",
      "rotation": 7
    },
    {
      "x": -1,
      "y": 5,
      "z": 1,
      "name": "Rock_Shale_Brick",
      "rotation": 4
    },
    {
      "x": -1,
      "y": 6,
      "z": 1,
      "name": "Rock_Shale_Brick",
      "rotation": 4
    },
    {
      "x": -1,
      "y": 7,
      "z": 1,
      "name": "Rock_Shale_Brick",
      "rotation": 4
    },
    {
      "x": -1,
      "y": 8,
      "z": 1,
      "name": "Rock_Shale",
      "rotation": 30
    },
    {
      "x": -1,
      "y": 9,
      "z": 1,
      "name": "Rock_Shale_Brick_Smooth",
      "rotation": 30
    },
    {
      "x": -1,
      "y": 10,
      "z": 1,
      "name": "Rock_Shale_Brick_Smooth",
      "rotation": 30
    },
    {
      "x": -1,
      "y": 11,
      "z": 1,
      "name": "Rock_Shale_Brick_Smooth_Half",
      "rotation": 2
    },
    {
      "x": 0,
      "y": -9,
      "z": 0,
      "name": "Rock_Shale_Brick",
      "rotation": 4
    },
    {
      "x": 0,
      "y": -8,
      "z": 0,
      "name": "Rock_Shale_Brick_Decorative"
    },
    {
      "x": 0,
      "y": -7,
      "z": 0,
      "name": "Rock_Shale_Brick",
      "rotation": 4
    },
    {
      "x": 0,
      "y": -6,
      "z": 0,
      "name": "Rock_Shale_Brick",
      "rotation": 4
    },
    {
      "x": 0,
      "y": -5,
      "z": 0,
      "name": "Rock_Shale_Brick",
      "rotation": 4
    },
    {
      "x": 0,
      "y": -4,
      "z": 0,
      "name": "Rock_Shale_Brick",
      "rotation": 4
    },
    {
      "x": 0,
      "y": -3,
      "z": 0,
      "name": "Rock_Shale_Brick",
      "rotation": 4
    },
    {
      "x": 0,
      "y": -2,
      "z": 0,
      "name": "Rock_Shale_Brick_Smooth",
      "rotation": 4
    },
    {
      "x": 0,
      "y": -1,
      "z": 0,
      "name": "Rock_Shale_Brick_Smooth_Half",
      "rotation": 2
    },
    {
      "x": 0,
      "y": 0,
      "z": 0,
      "name": "Rock_Shale_Brick_Smooth_Half"
    },
    {
      "x": 0,
      "y": 1,
      "z": 0,
      "name": "Rock_Shale_Brick_Smooth_Half",
      "rotation": 8
    },
    {
      "x": 0,
      "y": 2,
      "z": 0,
      "name": "Rock_Shale_Brick_Smooth",
      "rotation": 4
    },
    {
      "x": 0,
      "y": 3,
      "z": 0,
      "name": "Rock_Shale_Brick",
      "rotation": 4
    },
    {
      "x": 0,
      "y": 4,
      "z": 0,
      "name": "Rock_Shale_Brick",
      "rotation": 4
    },
    {
      "x": 0,
      "y": 5,
      "z": 0,
      "name": "Rock_Shale_Brick",
      "rotation": 4
    },
    {
      "x": 0,
      "y": 6,
      "z": 0,
      "name": "Rock_Shale",
      "rotation": 14
    },
    {
      "x": 0,
      "y": 7,
      "z": 0,
      "name": "Rock_Shale",
      "rotation": 14
    },
    {
      "x": 0,
      "y": 8,
      "z": 0,
      "name": "Rock_Shale_Brick_Decorative"
    },
    {
      "x": 0,
      "y": 9,
      "z": 0,
      "name": "Rock_Shale",
      "rotation": 14
    },
    {
      "x": 0,
      "y": -3,
      "z": 1,
      "name": "Rock_Shale_Brick_Half",
      "rotation": 4
    },
    {
      "x": 0,
      "y": 3,
      "z": 1,
      "name": "Rock_Shale_Brick_Half",
      "rotation": 4
    },
    {
      "x": 0,
      "y": 6,
      "z": 1,
      "name": "Plant_Moss_Wall_Green",
      "support": 15
    },
    {
      "x": 1,
      "y": -11,
      "z": -1,
      "name": "Rock_Shale_Brick_Smooth_Half",
      "rotation": 8
    },
    {
      "x": 1,
      "y": -10,
      "z": -1,
      "name": "Rock_Shale_Brick_Smooth",
      "rotation": 20
    },
    {
      "x": 1,
      "y": -9,
      "z": -1,
      "name": "Rock_Shale_Brick_Smooth",
      "rotation": 20
    },
    {
      "x": 1,
      "y": -8,
      "z": -1,
      "name": "Rock_Shale_Brick",
      "rotation": 4
    },
    {
      "x": 1,
      "y": -7,
      "z": -1,
      "name": "Rock_Shale_Brick",
      "rotation": 4
    },
    {
      "x": 1,
      "y": -6,
      "z": -1,
      "name": "Rock_Shale_Brick",
      "rotation": 4
    },
    {
      "x": 1,
      "y": -5,
      "z": -1,
      "name": "Rock_Shale_Brick",
      "rotation": 4
    },
    {
      "x": 1,
      "y": -4,
      "z": -1,
      "name": "Rock_Shale_Brick_Half",
      "rotation": 5
    },
    {
      "x": 1,
      "y": -2,
      "z": -1,
      "name": "Rock_Shale_Brick_Half",
      "rotation": 5
    },
    {
      "x": 1,
      "y": -1,
      "z": -1,
      "name": "Rock_Shale_Brick",
      "rotation": 4
    },
    {
      "x": 1,
      "y": 0,
      "z": -1,
      "name": "Rock_Shale_Brick_Smooth_Half",
      "rotation": 7
    },
    {
      "x": 1,
      "y": 1,
      "z": -1,
      "name": "Rock_Shale_Brick",
      "rotation": 4
    },
    {
      "x": 1,
      "y": 2,
      "z": -1,
      "name": "Rock_Shale_Brick_Half",
      "rotation": 5
    },
    {
      "x": 1,
      "y": 4,
      "z": -1,
      "name": "Rock_Shale_Brick_Half",
      "rotation": 5
    },
    {
      "x": 1,
      "y": 5,
      "z": -1,
      "name": "Rock_Shale_Brick",
      "rotation": 4
    },
    {
      "x": 1,
      "y": 6,
      "z": -1,
      "name": "Rock_Shale_Brick",
      "rotation": 4
    },
    {
      "x": 1,
      "y": 7,
      "z": -1,
      "name": "Rock_Shale",
      "rotation": 14
    },
    {
      "x": 1,
      "y": 8,
      "z": -1,
      "name": "Rock_Shale",
      "rotation": 14
    },
    {
      "x": 1,
      "y": 9,
      "z": -1,
      "name": "Rock_Shale_Brick_Smooth",
      "rotation": 14
    },
    {
      "x": 1,
      "y": 10,
      "z": -1,
      "name": "Rock_Shale_Brick_Smooth",
      "rotation": 14
    },
    {
      "x": 1,
      "y": 11,
      "z": -1,
      "name": "Rock_Shale_Brick_Smooth_Half",
      "rotation": 2
    },
    {
      "x": 1,
      "y": -3,
      "z": 0,
      "name": "Rock_Shale_Brick_Half",
      "rotation": 5
    },
    {
      "x": 1,
      "y": 3,
      "z": 0,
      "name": "Rock_Shale_Brick_Half",
      "rotation": 5
    },
    {
      "x": 1,
      "y": 7,
      "z": 0,
      "name": "Plant_Moss_Wall_Green",
      "support": 15,
      "rotation": 1
    },
    {
      "x": 2,
      "y": -9,
      "z": -2,
      "name": "Rock_Shale_Brick",
      "rotation": 4
    },
    {
      "x": 2,
      "y": -8,
      "z": -2,
      "name": "Rock_Shale_Brick",
      "rotation": 4
    },
    {
      "x": 2,
      "y": -7,
      "z": -2,
      "name": "Rock_Shale_Brick",
      "rotation": 4
    },
    {
      "x": 2,
      "y": -6,
      "z": -2,
      "name": "Rock_Shale_Brick",
      "rotation": 4
    },
    {
      "x": 2,
      "y": -5,
      "z": -2,
      "name": "Rock_Shale_Brick_Half",
      "rotation": 2
    },
    {
      "x": 2,
      "y": -1,
      "z": -2,
      "name": "Rock_Shale_Brick_Half",
      "rotation": 8
    },
    {
      "x": 2,
      "y": 0,
      "z": -2,
      "name": "Rock_Shale_Brick_Smooth",
      "rotation": 4
    },
    {
      "x": 2,
      "y": 1,
      "z": -2,
      "name": "Rock_Shale_Brick_Half",
      "rotation": 2
    },
    {
      "x": 2,
      "y": 5,
      "z": -2,
      "name": "Rock_Shale_Brick_Half",
      "rotation": 8
    },
    {
      "x": 2,
      "y": 6,
      "z": -2,
      "name": "Rock_Shale_Brick",
      "rotation": 4
    },
    {
      "x": 2,
      "y": 7,
      "z": -2,
      "name": "Rock_Shale_Brick",
      "rotation": 4
    },
    {
      "x": 2,
      "y": 8,
      "z": -2,
      "name": "Rock_Shale",
      "rotation": 14
    },
    {
      "x": 2,
      "y": 9,
      "z": -2,
      "name": "Rock_Shale",
      "rotation": 14
    },
    {
      "x": 2,
      "y": 10,
      "z": -2,
      "name": "Plant_Moss_Rug_Green",
      "support": 15
    },
    {
      "x": 3,
      "y": -10,
      "z": -3,
      "name": "Rock_Shale_Brick_Smooth_Half",
      "rotation": 7
    },
    {
      "x": 3,
      "y": -9,
      "z": -3,
      "name": "Rock_Shale_Brick_Smooth",
      "rotation": 20
    },
    {
      "x": 3,
      "y": -8,
      "z": -3,
      "name": "Rock_Shale_Brick",
      "rotation": 4
    },
    {
      "x": 3,
      "y": -7,
      "z": -3,
      "name": "Rock_Shale",
      "rotation": 20
    },
    {
      "x": 3,
      "y": -6,
      "z": -3,
      "name": "Rock_Shale_Brick",
      "rotation": 4
    },
    {
      "x": 3,
      "y": 0,
      "z": -3,
      "name": "Rock_Shale_Brick",
      "rotation": 4
    },
    {
      "x": 3,
      "y": 6,
      "z": -3,
      "name": "Rock_Shale_Brick",
      "rotation": 4
    },
    {
      "x": 3,
      "y": 7,
      "z": -3,
      "name": "Rock_Shale_Brick",
      "rotation": 4
    },
    {
      "x": 3,
      "y": 8,
      "z": -3,
      "name": "Rock_Shale",
      "rotation": 14
    },
    {
      "x": 3,
      "y": 9,
      "z": -3,
      "name": "Rock_Shale_Brick_Smooth",
      "rotation": 14
    },
    {
      "x": 3,
      "y": 10,
      "z": -3,
      "name": "Rock_Shale_Brick_Smooth_Half",
      "rotation": 7
    },
    {
      "x": 4,
      "y": -10,
      "z": -4,
      "name": "Rock_Shale_Brick_Smooth_Half",
      "rotation": 5
    },
    {
      "x": 4,
      "y": -8,
      "z": -4,
      "name": "Rock_Shale",
      "rotation": 20
    },
    {
      "x": 4,
      "y": -7,
      "z": -4,
      "name": "Rock_Shale",
      "rotation": 20
    },
    {
      "x": 4,
      "y": -6,
      "z": -4,
      "name": "Rock_Shale",
      "rotation": 20
    },
    {
      "x": 4,
      "y": -5,
      "z": -4,
      "name": "Rock_Shale_Brick_Half",
      "rotation": 2
    },
    {
      "x": 4,
      "y": -1,
      "z": -4,
      "name": "Rock_Shale_Brick_Half",
      "rotation": 8
    },
    {
      "x": 4,
      "y": 0,
      "z": -4,
      "name": "Rock_Shale_Brick",
      "rotation": 4
    },
    {
      "x": 4,
      "y": 1,
      "z": -4,
      "name": "Rock_Shale_Brick_Half",
      "rotation": 2
    },
    {
      "x": 4,
      "y": 5,
      "z": -4,
      "name": "Rock_Shale_Brick_Half",
      "rotation": 8
    },
    {
      "x": 4,
      "y": 6,
      "z": -4,
      "name": "Rock_Shale_Brick",
      "rotation": 4
    },
    {
      "x": 4,
      "y": 7,
      "z": -4,
      "name": "Rock_Shale",
      "rotation": 14
    },
    {
      "x": 4,
      "y": 8,
      "z": -4,
      "name": "Rock_Shale",
      "rotation": 14
    },
    {
      "x": 4,
      "y": 9,
      "z": -4,
      "name": "Plant_Moss_Rug_Green",
      "support": 15
    },
    {
      "x": 4,
      "y": 10,
      "z": -4,
      "name": "Rock_Shale_Brick_Smooth_Half",
      "rotation": 5
    },
    {
      "x": 5,
      "y": 7,
      "z": -6,
      "name": "Plant_Moss_Wall_Green",
      "support": 15,
      "rotation": 3
    },
    {
      "x": 5,
      "y": -9,
      "z": -5,
      "name": "Rock_Shale_Brick_Smooth_Half",
      "rotation": 7
    },
    {
      "x": 5,
      "y": -8,
      "z": -5,
      "name": "Rock_Shale_Brick_Smooth",
      "rotation": 20
    },
    {
      "x": 5,
      "y": -7,
      "z": -5,
      "name": "Rock_Shale",
      "rotation": 20
    },
    {
      "x": 5,
      "y": -6,
      "z": -5,
      "name": "Rock_Shale_Brick",
      "rotation": 4
    },
    {
      "x": 5,
      "y": -5,
      "z": -5,
      "name": "Rock_Shale_Brick",
      "rotation": 4
    },
    {
      "x": 5,
      "y": -4,
      "z": -5,
      "name": "Rock_Shale_Brick_Half",
      "rotation": 7
    },
    {
      "x": 5,
      "y": -2,
      "z": -5,
      "name": "Rock_Shale_Brick_Half",
      "rotation": 7
    },
    {
      "x": 5,
      "y": -1,
      "z": -5,
      "name": "Rock_Shale_Brick",
      "rotation": 4
    },
    {
      "x": 5,
      "y": 0,
      "z": -5,
      "name": "Rock_Shale_Brick",
      "rotation": 4
    },
    {
      "x": 5,
      "y": 1,
      "z": -5,
      "name": "Rock_Shale_Brick",
      "rotation": 4
    },
    {
      "x": 5,
      "y": 2,
      "z": -5,
      "name": "Rock_Shale_Brick_Half",
      "rotation": 7
    },
    {
      "x": 5,
      "y": 4,
      "z": -5,
      "name": "Rock_Shale_Brick_Half",
      "rotation": 7
    },
    {
      "x": 5,
      "y": 5,
      "z": -5,
      "name": "Rock_Shale_Brick"
    },
    {
      "x": 5,
      "y": 6,
      "z": -5,
      "name": "Rock_Shale_Brick"
    },
    {
      "x": 5,
      "y": 7,
      "z": -5,
      "name": "Rock_Shale",
      "rotation": 14
    },
    {
      "x": 5,
      "y": 8,
      "z": -5,
      "name": "Plant_Moss_Block_Green",
      "support": 15
    },
    {
      "x": 5,
      "y": 9,
      "z": -5,
      "name": "Rock_Shale_Brick_Smooth_Half",
      "rotation": 7
    },
    {
      "x": 6,
      "y": 5,
      "z": -7,
      "name": "Plant_Moss_Wall_Green",
      "support": 15,
      "rotation": 2
    },
    {
      "x": 6,
      "y": -9,
      "z": -6,
      "name": "Rock_Shale_Brick_Smooth_Half",
      "rotation": 5
    },
    {
      "x": 6,
      "y": -7,
      "z": -6,
      "name": "Rock_Shale",
      "rotation": 20
    },
    {
      "x": 6,
      "y": -6,
      "z": -6,
      "name": "Rock_Shale_Brick",
      "rotation": 4
    },
    {
      "x": 6,
      "y": -5,
      "z": -6,
      "name": "Rock_Shale_Brick",
      "rotation": 4
    },
    {
      "x": 6,
      "y": -4,
      "z": -6,
      "name": "Rock_Shale_Brick",
      "rotation": 4
    },
    {
      "x": 6,
      "y": -3,
      "z": -6,
      "name": "Rock_Shale_Brick",
      "rotation": 4
    },
    {
      "x": 6,
      "y": -2,
      "z": -6,
      "name": "Rock_Shale_Brick",
      "rotation": 4
    },
    {
      "x": 6,
      "y": -1,
      "z": -6,
      "name": "Rock_Shale_Brick",
      "rotation": 4
    },
    {
      "x": 6,
      "y": 0,
      "z": -6,
      "name": "Rock_Shale_Brick",
      "rotation": 4
    },
    {
      "x": 6,
      "y": 1,
      "z": -6,
      "name": "Rock_Shale_Brick",
      "rotation": 4
    },
    {
      "x": 6,
      "y": 2,
      "z": -6,
      "name": "Rock_Shale",
      "rotation": 14
    },
    {
      "x": 6,
      "y": 3,
      "z": -6,
      "name": "Rock_Shale",
      "rotation": 14
    },
    {
      "x": 6,
      "y": 4,
      "z": -6,
      "name": "Rock_Shale_Brick",
      "rotation": 4
    },
    {
      "x": 6,
      "y": 5,
      "z": -6,
      "name": "Rock_Shale_Brick",
      "rotation": 4
    },
    {
      "x": 6,
      "y": 6,
      "z": -6,
      "name": "Rock_Shale_Brick",
      "rotation": 4
    },
    {
      "x": 6,
      "y": 7,
      "z": -6,
      "name": "Plant_Moss_Block_Green",
      "support": 15
    },
    {
      "x": 6,
      "y": 9,
      "z": -6,
      "name": "Rock_Shale_Brick_Smooth_Half",
      "rotation": 5
    },
    {
      "x": 6,
      "y": -3,
      "z": -5,
      "name": "Rock_Shale_Brick_Half",
      "rotation": 4
    },
    {
      "x": 6,
      "y": 3,
      "z": -5,
      "name": "Rock_Shale_Brick_Half",
      "rotation": 4
    },
    {
      "x": 7,
      "y": 8,
      "z": -8,
      "name": "Rock_Shale_Brick_Smooth_Half",
      "rotation": 7
    },
    {
      "x": 7,
      "y": -8,
      "z": -7,
      "name": "Rock_Shale_Brick_Smooth_Half",
      "rotation": 8
    },
    {
      "x": 7,
      "y": -7,
      "z": -7,
      "name": "Rock_Shale_Brick_Smooth",
      "rotation": 20
    },
    {
      "x": 7,
      "y": -6,
      "z": -7,
      "name": "Rock_Shale",
      "rotation": 20
    },
    {
      "x": 7,
      "y": -5,
      "z": -7,
      "name": "Rock_Shale",
      "rotation": 20
    },
    {
      "x": 7,
      "y": -4,
      "z": -7,
      "name": "Rock_Shale",
      "rotation": 20
    },
    {
      "x": 7,
      "y": -3,
      "z": -7,
      "name": "Rock_Shale_Brick",
      "rotation": 4
    },
    {
      "x": 7,
      "y": -2,
      "z": -7,
      "name": "Rock_Shale_Brick",
      "rotation": 4
    },
    {
      "x": 7,
      "y": -1,
      "z": -7,
      "name": "Rock_Shale",
      "rotation": 20
    },
    {
      "x": 7,
      "y": 0,
      "z": -7,
      "name": "Rock_Shale_Brick",
      "rotation": 4
    },
    {
      "x": 7,
      "y": 1,
      "z": -7,
      "name": "Rock_Shale_Brick",
      "rotation": 4
    },
    {
      "x": 7,
      "y": 2,
      "z": -7,
      "name": "Rock_Shale",
      "rotation": 14
    },
    {
      "x": 7,
      "y": 3,
      "z": -7,
      "name": "Rock_Shale",
      "rotation": 14
    },
    {
      "x": 7,
      "y": 4,
      "z": -7,
      "name": "Rock_Shale_Brick",
      "rotation": 4
    },
    {
      "x": 7,
      "y": 5,
      "z": -7,
      "name": "Rock_Shale_Brick",
      "rotation": 4
    },
    {
      "x": 7,
      "y": 6,
      "z": -7,
      "name": "Rock_Shale_Brick",
      "rotation": 4
    },
    {
      "x": 7,
      "y": 7,
      "z": -7,
      "name": "Rock_Shale_Brick_Smooth",
      "rotation": 14
    },
    {
      "x": 7,
      "y": 8,
      "z": -7,
      "name": "Plant_Moss_Rug_Green",
      "support": 15
    },
    {
      "x": 8,
      "y": -8,
      "z": -8,
      "name": "Rock_Shale_Brick_Smooth",
      "rotation": 20
    },
    {
      "x": 8,
      "y": -5,
      "z": -8,
      "name": "Rock_Shale_Brick_Smooth",
      "rotation": 20
    },
    {
      "x": 8,
      "y": -4,
      "z": -8,
      "name": "Rock_Shale_Brick",
      "rotation": 4
    },
    {
      "x": 8,
      "y": -3,
      "z": -8,
      "name": "Rock_Shale_Brick",
      "rotation": 4
    },
    {
      "x": 8,
      "y": -2,
      "z": -8,
      "name": "Rock_Shale",
      "rotation": 20
    },
    {
      "x": 8,
      "y": -1,
      "z": -8,
      "name": "Rock_Shale",
      "rotation": 20
    },
    {
      "x": 8,
      "y": 0,
      "z": -8,
      "name": "Rock_Shale_Brick_Decorative"
    },
    {
      "x": 8,
      "y": 1,
      "z": -8,
      "name": "Rock_Shale",
      "rotation": 14
    },
    {
      "x": 8,
      "y": 2,
      "z": -8,
      "name": "Rock_Shale",
      "rotation": 14
    },
    {
      "x": 8,
      "y": 3,
      "z": -8,
      "name": "Rock_Shale",
      "rotation": 14
    },
    {
      "x": 8,
      "y": 4,
      "z": -8,
      "name": "Rock_Shale",
      "rotation": 14
    },
    {
      "x": 8,
      "y": 5,
      "z": -8,
      "name": "Rock_Shale_Brick_Smooth",
      "rotation": 14
    },
    {
      "x": 8,
      "y": 6,
      "z": -8,
      "name": "Plant_Moss_Short_Green",
      "support": 15
    },
    {
      "x": 8,
      "y": 8,
      "z": -8,
      "name": "Rock_Shale_Brick_Smooth",
      "rotation": 14
    },
    {
      "x": 9,
      "y": -6,
      "z": -9,
      "name": "Rock_Shale_Brick_Smooth_Half",
      "rotation": 8
    },
    {
      "x": 9,
      "y": -5,
      "z": -9,
      "name": "Rock_Shale_Brick_Smooth_Half",
      "rotation": 2
    },
    {
      "x": 9,
      "y": -3,
      "z": -9,
      "name": "Rock_Shale_Brick_Smooth",
      "rotation": 20
    },
    {
      "x": 9,
      "y": -2,
      "z": -9,
      "name": "Rock_Shale",
      "rotation": 20
    },
    {
      "x": 9,
      "y": -1,
      "z": -9,
      "name": "Rock_Shale_Brick_Smooth",
      "rotation": 20
    },
    {
      "x": 9,
      "y": 0,
      "z": -9,
      "name": "Rock_Shale",
      "rotation": 14
    },
    {
      "x": 9,
      "y": 1,
      "z": -9,
      "name": "Rock_Shale_Brick_Smooth",
      "rotation": 14
    },
    {
      "x": 9,
      "y": 2,
      "z": -9,
      "name": "Rock_Shale",
      "rotation": 14
    },
    {
      "x": 9,
      "y": 3,
      "z": -9,
      "name": "Rock_Shale_Brick_Smooth",
      "rotation": 14
    },
    {
      "x": 9,
      "y": 5,
      "z": -9,
      "name": "Rock_Shale_Brick_Smooth_Half",
      "rotation": 8
    },
    {
      "x": 9,
      "y": 6,
      "z": -9,
      "name": "Rock_Shale_Brick_Smooth_Half",
      "rotation": 2
    },
    {
      "x": 10,
      "y": -1,
      "z": -11,
      "name": "Rock_Shale_Brick_Smooth_Half",
      "rotation": 7
    },
    {
      "x": 10,
      "y": 1,
      "z": -11,
      "name": "Rock_Shale_Brick_Smooth_Half",
      "rotation": 7
    },
    {
      "x": 10,
      "y": -4,
      "z": -10,
      "name": "Rock_Shale_Brick_Smooth_Half",
      "rotation": 8
    },
    {
      "x": 10,
      "y": -3,
      "z": -10,
      "name": "Rock_Shale_Brick_Smooth_Half",
      "rotation": 2
    },
    {
      "x": 10,
      "y": -1,
      "z": -10,
      "name": "Rock_Shale_Brick_Smooth",
      "rotation": 20
    },
    {
      "x": 10,
      "y": 1,
      "z": -10,
      "name": "Rock_Shale_Brick_Smooth",
      "rotation": 14
    },
    {
      "x": 10,
      "y": 3,
      "z": -10,
      "name": "Rock_Shale_Brick_Smooth_Half",
      "rotation": 8
    },
    {
      "x": 10,
      "y": 4,
      "z": -10,
      "name": "Rock_Shale_Brick_Smooth_Half",
      "rotation": 2
    },
    {
      "x": 11,
      "y": -1,
      "z": -11,
      "name": "Rock_Shale_Brick_Smooth_Half",
      "rotation": 5
    },
    {
      "x": 11,
      "y": 1,
      "z": -11,
      "name": "Rock_Shale_Brick_Smooth_Half",
      "rotation": 5
    }
  ]
}