{
  "version": 8,
  "blockIdVersion": 11,
  "anchorX": 0,
  "anchorY": 0,
  "anchorZ": 0,
  "blocks": [
    {
      "x": -6,
      "y": -1,
      "z": 1,
      "name": "Scrap_Metal_Grid"
    },
    {
      "x": -6,
      "y": -1,
      "z": 2,
      "name": "Scrap_Metal_Grid"
    },
    {
      "x": -5,
      "y": -1,
      "z": -2,
      "name": "Plant_Moss_Block_Green",
      "support": 15
    },
    {
      "x": -5,
      "y": -1,
      "z": -1,
      "name": "Plant_Moss_Block_Green",
      "support": 15
    },
    {
      "x": -5,
      "y": -1,
      "z": 0,
      "name": "Scrap_Metal_Grid"
    },
    {
      "x": -5,
      "y": -1,
      "z": 1,
      "name": "Scrap_Metal_Grid"
    },
    {
      "x": -5,
      "y": -1,
      "z": 2,
      "name": "Scrap_Metal_Grid"
    },
    {
      "x": -4,
      "y": -1,
      "z": -5,
      "name": "Scrap_Metal_Grid"
    },
    {
      "x": -4,
      "y": -1,
      "z": -4,
      "name": "Scrap_Metal_Grid"
    },
    {
      "x": -4,
      "y": -1,
      "z": -3,
      "name": "Plant_Moss_Block_Green",
      "support": 15
    },
    {
      "x": -4,
      "y": -1,
      "z": -2,
      "name": "Scrap_Metal_Grid"
    },
    {
      "x": -4,
      "y": -1,
      "z": -1,
      "name": "Scrap_Metal_Grid"
    },
    {
      "x": -4,
      "y": -1,
      "z": 0,
      "name": "Scrap_Metal_Grid"
    },
    {
      "x": -4,
      "y": -1,
      "z": 1,
      "name": "Plant_Moss_Wall_Green",
      "support": 15
    },
    {
      "x": -4,
      "y": 0,
      "z": 2,
      "name": "Scrap_Metal_Grid"
    },
    {
      "x": -4,
      "y": 0,
      "z": 3,
      "name": "Scrap_Metal_Grid"
    },
    {
      "x": -3,
      "y": -1,
      "z": -7,
      "name": "Scrap_Metal_Grid"
    },
    {
      "x": -3,
      "y": -1,
      "z": -6,
      "name": "Scrap_Metal_Grid"
    },
    {
      "x": -3,
      "y": -1,
      "z": -5,
      "name": "Scrap_Metal_Grid"
    },
    {
      "x": -3,
      "y": -1,
      "z": -4,
      "name": "Scrap_Metal_Grid"
    },
    {
      "x": -3,
      "y": -1,
      "z": -3,
      "name": "Scrap_Metal_Grid"
    },
    {
      "x": -3,
      "y": -1,
      "z": -2,
      "name": "Scrap_Metal_Grid"
    },
    {
      "x": -3,
      "y": -1,
      "z": -1,
      "name": "Scrap_Metal_Grid"
    },
    {
      "x": -3,
      "y": 0,
      "z": 0,
      "name": "Scrap_Metal_Grid"
    },
    {
      "x": -3,
      "y": 0,
      "z": 1,
      "name": "Scrap_Metal_Grid"
    },
    {
      "x": -3,
      "y": 0,
      "z": 2,
      "name": "Scrap_Metal_Grid"
    },
    {
      "x": -3,
      "y": 0,
      "z": 3,
      "name": "Scrap_Metal_Grid"
    },
    {
      "x": -2,
      "y": -1,
      "z": -7,
      "name": "Scrap_Metal_Grid"
    },
    {
      "x": -2,
      "y": -1,
      "z": -6,
      "name": "Scrap_Metal_Grid"
    },
    {
      "x": -2,
      "y": -1,
      "z": -5,
      "name": "Plant_Moss_Wall_Green",
      "support": 15,
      "rotation": 3
    },
    {
      "x": -2,
      "y": -1,
      "z": -4,
      "name": "Scrap_Metal_Grid"
    },
    {
      "x": -2,
      "y": -1,
      "z": -3,
      "name": "Scrap_Metal_Grid"
    },
    {
      "x": -2,
      "y": 0,
      "z": -2,
      "name": "Scrap_Metal_Grid"
    },
    {
      "x": -2,
      "y": 0,
      "z": -1,
      "name": "Scrap_Metal_Grid"
    },
    {
      "x": -2,
      "y": 0,
      "z": 0,
      "name": "Scrap_Metal_Grid"
    },
    {
      "x": -2,
      "y": 0,
      "z": 1,
      "name": "Scrap_Metal_Grid"
    },
    {
      "x": -2,
      "y": 0,
      "z": 2,
      "name": "Scrap_Metal_Grid"
    },
    {
      "x": -2,
      "y": 0,
      "z": 3,
      "name": "Scrap_Metal_Grid"
    },
    {
      "x": -1,
      "y": -1,
      "z": -6,
      "name": "Scrap_Metal_Grid"
    },
    {
      "x": -1,
      "y": -1,
      "z": -5,
      "name": "Scrap_Metal_Grid"
    },
    {
      "x": -1,
      "y": 0,
      "z": -4,
      "name": "Scrap_Metal_Grid"
    },
    {
      "x": -1,
      "y": 0,
      "z": -3,
      "name": "Scrap_Metal_Grid"
    },
    {
      "x": -1,
      "y": 0,
      "z": -2,
      "name": "Scrap_Metal_Grid"
    },
    {
      "x": -1,
      "y": 0,
      "z": -1,
      "name": "Scrap_Metal_Grid"
    },
    {
      "x": -1,
      "y": 0,
      "z": 0,
      "name": "Scrap_Metal_Grid"
    },
    {
      "x": -1,
      "y": 0,
      "z": 1,
      "name": "Scrap_Metal_Grid"
    },
    {
      "x": -1,
      "y": 1,
      "z": 2,
      "name": "Scrap_Metal_Grid"
    },
    {
      "x": -1,
      "y": 2,
      "z": 2,
      "name": "Plant_Moss_Rug_Green",
      "support": 15
    },
    {
      "x": -1,
      "y": 1,
      "z": 3,
      "name": "Scrap_Metal_Grid"
    },
    {
      "x": -1,
      "y": 1,
      "z": 4,
      "name": "Scrap_Metal_Grid"
    },
    {
      "x": 0,
      "y": 0,
      "z": -6,
      "name": "Scrap_Metal_Grid"
    },
    {
      "x": 0,
      "y": 0,
      "z": -5,
      "name": "Scrap_Metal_Grid"
    },
    {
      "x": 0,
      "y": 0,
      "z": -4,
      "name": "Scrap_Metal_Grid"
    },
    {
      "x": 0,
      "y": 0,
      "z": -3,
      "name": "Scrap_Metal_Grid"
    },
    {
      "x": 0,
      "y": 1,
      "z": -3,
      "name": "Plant_Moss_Rug_Green",
      "support": 15
    },
    {
      "x": 0,
      "y": 0,
      "z": -2,
      "name": "Scrap_Metal_Grid"
    },
    {
      "x": 0,
      "y": 0,
      "z": -1,
      "name": "Scrap_Metal_Grid"
    },
    {
      "x": 0,
      "y": 0,
      "z": 0,
      "name": "Scrap_Metal_Grid"
    },
    {
      "x": 0,
      "y": 1,
      "z": 0,
      "name": "Scrap_Metal_Grid"
    },
    {
      "x": 0,
      "y": 1,
      "z": 1,
      "name": "Scrap_Metal_Grid"
    },
    {
      "x": 0,
      "y": 1,
      "z": 2,
      "name": "Scrap_Metal_Grid"
    },
    {
      "x": 0,
      "y": 1,
      "z": 3,
      "name": "Scrap_Metal_Grid"
    },
    {
      "x": 0,
      "y": 1,
      "z": 4,
      "name": "Scrap_Metal_Grid"
    },
    {
      "x": 1,
      "y": 0,
      "z": -6,
      "name": "Scrap_Metal_Grid"
    },
    {
      "x": 1,
      "y": 0,
      "z": -5,
      "name": "Scrap_Metal_Grid"
    },
    {
      "x": 1,
      "y": 1,
      "z": -5,
      "name": "Plant_Moss_Rug_Green",
      "support": 15
    },
    {
      "x": 1,
      "y": 0,
      "z": -4,
      "name": "Scrap_Metal_Grid"
    },
    {
      "x": 1,
      "y": 1,
      "z": -4,
      "name": "Plant_Moss_Rug_Green",
      "support": 15
    },
    {
      "x": 1,
      "y": 0,
      "z": -3,
      "name": "Scrap_Metal_Grid"
    },
    {
      "x": 1,
      "y": 1,
      "z": -2,
      "name": "Scrap_Metal_Grid"
    },
    {
      "x": 1,
      "y": 1,
      "z": -1,
      "name": "Scrap_Metal_Grid"
    },
    {
      "x": 1,
      "y": 1,
      "z": 0,
      "name": "Scrap_Metal_Grid"
    },
    {
      "x": 1,
      "y": 1,
      "z": 1,
      "name": "Scrap_Metal_Grid"
    },
    {
      "x": 1,
      "y": 1,
      "z": 2,
      "name": "Scrap_Metal_Grid"
    },
    {
      "x": 1,
      "y": 1,
      "z": 3,
      "name": "Scrap_Metal_Grid"
    },
    {
      "x": 1,
      "y": 1,
      "z": 4,
      "name": "Scrap_Metal_Grid"
    },
    {
      "x": 2,
      "y": 0,
      "z": -5,
      "name": "Scrap_Metal_Grid"
    },
    {
      "x": 2,
      "y": 1,
      "z": -4,
      "name": "Scrap_Metal_Grid"
    },
    {
      "x": 2,
      "y": 1,
      "z": -3,
      "name": "Scrap_Metal_Grid"
    },
    {
      "x": 2,
      "y": 1,
      "z": -2,
      "name": "Scrap_Metal_Grid"
    },
    {
      "x": 2,
      "y": 1,
      "z": -1,
      "name": "Scrap_Metal_Grid"
    },
    {
      "x": 2,
      "y": 1,
      "z": 0,
      "name": "Scrap_Metal_Grid"
    },
    {
      "x": 2,
      "y": 1,
      "z": 1,
      "name": "Scrap_Metal_Grid"
    },
    {
      "x": 2,
      "y": 2,
      "z": 2,
      "name": "Scrap_Metal_Grid"
    },
    {
      "x": 2,
      "y": 2,
      "z": 3,
      "name": "Plant_Moss_Wall_Green",
      "support": 15,
      "rotation": 3
    },
    {
      "x": 2,
      "y": 2,
      "z": 4,
      "name": "Scrap_Metal_Grid"
    },
    {
      "x": 2,
      "y": 2,
      "z": 5,
      "name": "Scrap_Metal_Grid"
    },
    {
      "x": 3,
      "y": 1,
      "z": -5,
      "name": "Scrap_Metal_Grid"
    },
    {
      "x": 3,
      "y": 1,
      "z": -4,
      "name": "Scrap_Metal_Grid"
    },
    {
      "x": 3,
      "y": 1,
      "z": -3,
      "name": "Scrap_Metal_Grid"
    },
    {
      "x": 3,
      "y": 1,
      "z": -2,
      "name": "Scrap_Metal_Grid"
    },
    {
      "x": 3,
      "y": 1,
      "z": -1,
      "name": "Scrap_Metal_Grid"
    },
    {
      "x": 3,
      "y": 2,
      "z": 0,
      "name": "Scrap_Metal_Grid"
    },
    {
      "x": 3,
      "y": 2,
      "z": 1,
      "name": "Scrap_Metal_Grid"
    },
    {
      "x": 3,
      "y": 2,
      "z": 2,
      "name": "Scrap_Metal_Grid"
    },
    {
      "x": 3,
      "y": 2,
      "z": 3,
      "name": "Scrap_Metal_Grid"
    },
    {
      "x": 3,
      "y": 3,
      "z": 3,
      "name": "Plant_Moss_Rug_Green",
      "support": 15
    },
    {
      "x": 3,
      "y": 2,
      "z": 4,
      "name": "Scrap_Metal_Grid"
    },
    {
      "x": 3,
      "y": 2,
      "z": 5,
      "name": "Scrap_Metal_Grid"
    },
    {
      "x": 4,
      "y": 1,
      "z": -5,
      "name": "Plant_Moss_Block_Green",
      "support": 15
    },
    {
      "x": 4,
      "y": 1,
      "z": -4,
      "name": "Scrap_Metal_Grid"
    },
    {
      "x": 4,
      "y": 2,
      "z": -3,
      "name": "Plant_Moss_Wall_Green",
      "support": 15,
      "rotation": 3
    },
    {
      "x": 4,
      "y": 2,
      "z": -2,
      "name": "Scrap_Metal_Grid"
    },
    {
      "x": 4,
      "y": 2,
      "z": -1,
      "name": "Scrap_Metal_Grid"
    },
    {
      "x": 4,
      "y": 2,
      "z": 0,
      "name": "Scrap_Metal_Grid"
    },
    {
      "x": 4,
      "y": 2,
      "z": 1,
      "name": "Scrap_Metal_Grid"
    },
    {
      "x": 4,
      "y": 3,
      "z": 1,
      "name": "Plant_Moss_Rug_Green",
      "support": 15
    },
    {
      "x": 4,
      "y": 2,
      "z": 2,
      "name": "Scrap_Metal_Grid"
    },
    {
      "x": 4,
      "y": 3,
      "z": 2,
      "name": "Plant_Moss_Rug_Green",
      "support": 15
    },
    {
      "x": 4,
      "y": 2,
      "z": 3,
      "name": "Scrap_Metal_Grid"
    },
    {
      "x": 5,
      "y": 2,
      "z": -4,
      "name": "Scrap_Metal_Grid"
    },
    {
      "x": 5,
      "y": 2,
      "z": -3,
      "name": "Scrap_Metal_Grid"
    },
    {
      "x": 5,
      "y": 2,
      "z": -2,
      "name": "Scrap_Metal_Grid"
    },
    {
      "x": 5,
      "y": 2,
      "z": -1,
      "name": "Scrap_Metal_Grid"
    },
    {
      "x": 5,
      "y": 2,
      "z": 0,
      "name": "Scrap_Metal_Grid"
    },
    {
      "x": 6,
      "y": 2,
      "z": -4,
      "name": "Plant_Moss_Block_Green",
      "support": 15
    },
    {
      "x": 6,
      "y": 2,
      "z": -3,
      "name": "Scrap_Metal_Grid"
    }
  ]
}