{
  "version": 8,
  "blockIdVersion": 11,
  "anchorX": 0,
  "anchorY": 0,
  "anchorZ": 0,
  "blocks": [
    {
      "x": -24,
      "y": 16,
      "z": -1,
      "name": "Plant_Moss_Wall_Green",
      "support": 15,
      "rotation": 3
    },
    {
      "x": -24,
      "y": 17,
      "z": -1,
      "name": "Plant_Moss_Wall_Green",
      "support": 15,
      "rotation": 3
    },
    {
      "x": -24,
      "y": 19,
      "z": -1,
      "name": "Plant_Moss_Wall_Green",
      "support": 15,
      "rotation": 3
    },
    {
      "x": -23,
      "y": 19,
      "z": -2,
      "name": "Plant_Moss_Wall_Green",
      "support": 15,
      "rotation": 2
    },
    {
      "x": -23,
      "y": 12,
      "z": -1,
      "name": "Plant_Moss_Wall_Green",
      "support": 15,
      "rotation": 3
    },
    {
      "x": -23,
      "y": 16,
      "z": -1,
      "name": "Rock_Sandstone_Red"
    },
    {
      "x": -23,
      "y": 17,
      "z": -1,
      "name": "Rock_Sandstone_Red"
    },
    {
      "x": -23,
      "y": 18,
      "z": -1,
      "name": "Scrap_Metal_Smooth",
      "rotation": 4
    },
    {
      "x": -23,
      "y": 19,
      "z": -1,
      "name": "Scrap_Metal_Smooth",
      "rotation": 4
    },
    {
      "x": -22,
      "y": 11,
      "z": -1,
      "name": "Plant_Moss_Cave_Green",
      "support": 15,
      "rotation": 8
    },
    {
      "x": -22,
      "y": 12,
      "z": -1,
      "name": "Scrap_Metal_Smooth",
      "rotation": 20
    },
    {
      "x": -22,
      "y": 13,
      "z": -1,
      "name": "Scrap_Metal_Smooth",
      "rotation": 20
    },
    {
      "x": -22,
      "y": 14,
      "z": -1,
      "name": "Scrap_Metal_Smooth",
      "rotation": 20
    },
    {
      "x": -22,
      "y": 15,
      "z": -1,
      "name": "Scrap_Metal_Smooth",
      "rotation": 20
    },
    {
      "x": -22,
      "y": 16,
      "z": -1,
      "name": "Scrap_Metal_Smooth",
      "rotation": 4
    },
    {
      "x": -22,
      "y": 17,
      "z": -1,
      "name": "Scrap_Metal_Smooth",
      "rotation": 4
    },
    {
      "x": -22,
      "y": 18,
      "z": -1,
      "name": "Scrap_Metal_Smooth",
      "rotation": 4
    },
    {
      "x": -22,
      "y": 19,
      "z": -1,
      "name": "Scrap_Metal_Smooth",
      "rotation": 4
    },
    {
      "x": -22,
      "y": 20,
      "z": -1,
      "name": "Scrap_Metal_Smooth",
      "rotation": 30
    },
    {
      "x": -22,
      "y": 12,
      "z": 0,
      "name": "Plant_Moss_Wall_Green",
      "support": 15
    },
    {
      "x": -22,
      "y": 13,
      "z": 0,
      "name": "Plant_Moss_Wall_Green",
      "support": 15
    },
    {
      "x": -21,
      "y": 8,
      "z": -1,
      "name": "Scrap_Metal_Smooth",
      "rotation": 20
    },
    {
      "x": -21,
      "y": 9,
      "z": -1,
      "name": "Scrap_Metal_Smooth",
      "rotation": 20
    },
    {
      "x": -21,
      "y": 10,
      "z": -1,
      "name": "Scrap_Metal_Smooth",
      "rotation": 20
    },
    {
      "x": -21,
      "y": 11,
      "z": -1,
      "name": "Scrap_Metal_Smooth",
      "rotation": 20
    },
    {
      "x": -21,
      "y": 12,
      "z": -1,
      "name": "Scrap_Metal_Smooth",
      "rotation": 4
    },
    {
      "x": -21,
      "y": 13,
      "z": -1,
      "name": "Scrap_Metal_Smooth",
      "rotation": 4
    },
    {
      "x": -21,
      "y": 14,
      "z": -1,
      "name": "Scrap_Metal_Smooth",
      "rotation": 4
    },
    {
      "x": -21,
      "y": 15,
      "z": -1,
      "name": "Scrap_Metal_Smooth",
      "rotation": 4
    },
    {
      "x": -21,
      "y": 16,
      "z": -1,
      "name": "Scrap_Metal_Smooth",
      "rotation": 4
    },
    {
      "x": -21,
      "y": 17,
      "z": -1,
      "name": "Plant_Moss_Rug_Green",
      "support": 15
    },
    {
      "x": -21,
      "y": 19,
      "z": -1,
      "name": "Scrap_Metal_Smooth",
      "rotation": 4
    },
    {
      "x": -21,
      "y": 20,
      "z": -1,
      "name": "Scrap_Metal_Smooth",
      "rotation": 30
    },
    {
      "x": -21,
      "y": 21,
      "z": -1,
      "name": "Plant_Moss_Rug_Green",
      "support": 15
    },
    {
      "x": -21,
      "y": 14,
      "z": 0,
      "name": "Plant_Moss_Wall_Green",
      "support": 15
    },
    {
      "x": -20,
      "y": 4,
      "z": -1,
      "name": "Scrap_Metal_Smooth",
      "rotation": 20
    },
    {
      "x": -20,
      "y": 5,
      "z": -1,
      "name": "Soil_Clay_Smooth_Orange"
    },
    {
      "x": -20,
      "y": 6,
      "z": -1,
      "name": "Scrap_Metal_Smooth",
      "rotation": 20
    },
    {
      "x": -20,
      "y": 7,
      "z": -1,
      "name": "Soil_Clay"
    },
    {
      "x": -20,
      "y": 8,
      "z": -1,
      "name": "Scrap_Metal_Smooth",
      "rotation": 14
    },
    {
      "x": -20,
      "y": 9,
      "z": -1,
      "name": "Scrap_Metal_Smooth",
      "rotation": 14
    },
    {
      "x": -20,
      "y": 10,
      "z": -1,
      "name": "Scrap_Metal_Smooth",
      "rotation": 14
    },
    {
      "x": -20,
      "y": 11,
      "z": -1,
      "name": "Scrap_Metal_Smooth",
      "rotation": 14
    },
    {
      "x": -20,
      "y": 12,
      "z": -1,
      "name": "Scrap_Metal_Smooth",
      "rotation": 4
    },
    {
      "x": -20,
      "y": 13,
      "z": -1,
      "name": "Scrap_Metal_Smooth",
      "rotation": 4
    },
    {
      "x": -20,
      "y": 14,
      "z": -1,
      "name": "Scrap_Metal_Smooth",
      "rotation": 4
    },
    {
      "x": -20,
      "y": 15,
      "z": -1,
      "name": "Scrap_Metal_Smooth",
      "rotation": 4
    },
    {
      "x": -20,
      "y": 16,
      "z": -1,
      "name": "Rock_Sandstone_Red"
    },
    {
      "x": -20,
      "y": 19,
      "z": -1,
      "name": "Scrap_Metal_Smooth",
      "rotation": 4
    },
    {
      "x": -20,
      "y": 20,
      "z": -1,
      "name": "Soil_Clay_Smooth_Red"
    },
    {
      "x": -20,
      "y": 21,
      "z": -1,
      "name": "Plant_Moss_Rug_Green",
      "support": 15
    },
    {
      "x": -19,
      "y": 0,
      "z": -1,
      "name": "Scrap_Metal_Smooth",
      "rotation": 20
    },
    {
      "x": -19,
      "y": 1,
      "z": -1,
      "name": "Soil_Clay"
    },
    {
      "x": -19,
      "y": 2,
      "z": -1,
      "name": "Soil_Clay"
    },
    {
      "x": -19,
      "y": 3,
      "z": -1,
      "name": "Soil_Clay"
    },
    {
      "x": -19,
      "y": 4,
      "z": -1,
      "name": "Soil_Clay"
    },
    {
      "x": -19,
      "y": 5,
      "z": -1,
      "name": "Rock_Sandstone_Red"
    },
    {
      "x": -19,
      "y": 6,
      "z": -1,
      "name": "Soil_Clay_Smooth_Orange"
    },
    {
      "x": -19,
      "y": 7,
      "z": -1,
      "name": "Scrap_Metal_Smooth",
      "rotation": 14
    },
    {
      "x": -19,
      "y": 8,
      "z": -1,
      "name": "Scrap_Metal_Smooth",
      "rotation": 14
    },
    {
      "x": -19,
      "y": 9,
      "z": -1,
      "name": "Scrap_Metal_Smooth",
      "rotation": 14
    },
    {
      "x": -19,
      "y": 10,
      "z": -1,
      "name": "Scrap_Metal_Smooth",
      "rotation": 14
    },
    {
      "x": -19,
      "y": 11,
      "z": -1,
      "name": "Scrap_Metal_Smooth",
      "rotation": 14
    },
    {
      "x": -19,
      "y": 12,
      "z": -1,
      "name": "Scrap_Metal_Smooth",
      "rotation": 4
    },
    {
      "x": -19,
      "y": 13,
      "z": -1,
      "name": "Scrap_Metal_Smooth",
      "rotation": 4
    },
    {
      "x": -19,
      "y": 14,
      "z": -1,
      "name": "Scrap_Metal_Smooth",
      "rotation": 4
    },
    {
      "x": -19,
      "y": 15,
      "z": -1,
      "name": "Scrap_Metal_Smooth",
      "rotation": 4
    },
    {
      "x": -19,
      "y": 16,
      "z": -1,
      "name": "Scrap_Metal_Smooth",
      "rotation": 4
    },
    {
      "x": -19,
      "y": 17,
      "z": -1,
      "name": "Soil_Clay_Smooth_Orange"
    },
    {
      "x": -19,
      "y": 18,
      "z": -1,
      "name": "Scrap_Metal_Smooth",
      "rotation": 4
    },
    {
      "x": -19,
      "y": 19,
      "z": -1,
      "name": "Scrap_Metal_Smooth",
      "rotation": 4
    },
    {
      "x": -19,
      "y": 20,
      "z": -1,
      "name": "Soil_Clay_Smooth_Red"
    },
    {
      "x": -18,
      "y": 7,
      "z": -2,
      "name": "Plant_Moss_Wall_Green",
      "support": 15,
      "rotation": 2
    },
    {
      "x": -18,
      "y": -4,
      "z": -1,
      "name": "Scrap_Metal_Smooth",
      "rotation": 20
    },
    {
      "x": -18,
      "y": -3,
      "z": -1,
      "name": "Scrap_Metal_Smooth",
      "rotation": 20
    },
    {
      "x": -18,
      "y": -2,
      "z": -1,
      "name": "Scrap_Metal_Smooth",
      "rotation": 20
    },
    {
      "x": -18,
      "y": -1,
      "z": -1,
      "name": "Scrap_Metal_Smooth",
      "rotation": 20
    },
    {
      "x": -18,
      "y": 0,
      "z": -1,
      "name": "Soil_Clay"
    },
    {
      "x": -18,
      "y": 2,
      "z": -1,
      "name": "Soil_Clay"
    },
    {
      "x": -18,
      "y": 3,
      "z": -1,
      "name": "Rock_Sandstone_Red"
    },
    {
      "x": -18,
      "y": 4,
      "z": -1,
      "name": "Rock_Sandstone_Red"
    },
    {
      "x": -18,
      "y": 5,
      "z": -1,
      "name": "Soil_Clay_Smooth_Red"
    },
    {
      "x": -18,
      "y": 6,
      "z": -1,
      "name": "Soil_Clay"
    },
    {
      "x": -18,
      "y": 7,
      "z": -1,
      "name": "Scrap_Metal_Smooth",
      "rotation": 14
    },
    {
      "x": -18,
      "y": 8,
      "z": -1,
      "name": "Scrap_Metal_Smooth",
      "rotation": 14
    },
    {
      "x": -18,
      "y": 9,
      "z": -1,
      "name": "Scrap_Metal_Smooth",
      "rotation": 14
    },
    {
      "x": -18,
      "y": 10,
      "z": -1,
      "name": "Scrap_Metal_Smooth",
      "rotation": 14
    },
    {
      "x": -18,
      "y": 11,
      "z": -1,
      "name": "Scrap_Metal_Smooth",
      "rotation": 14
    },
    {
      "x": -18,
      "y": 12,
      "z": -1,
      "name": "Scrap_Metal_Smooth",
      "rotation": 4
    },
    {
      "x": -18,
      "y": 13,
      "z": -1,
      "name": "Scrap_Metal_Smooth",
      "rotation": 4
    },
    {
      "x": -18,
      "y": 14,
      "z": -1,
      "name": "Scrap_Metal_Smooth",
      "rotation": 4
    },
    {
      "x": -18,
      "y": 15,
      "z": -1,
      "name": "Scrap_Metal_Smooth",
      "rotation": 4
    },
    {
      "x": -18,
      "y": 16,
      "z": -1,
      "name": "Scrap_Metal_Smooth",
      "rotation": 4
    },
    {
      "x": -18,
      "y": 17,
      "z": -1,
      "name": "Scrap_Metal_Smooth",
      "rotation": 4
    },
    {
      "x": -18,
      "y": 18,
      "z": -1,
      "name": "Scrap_Metal_Smooth",
      "rotation": 4
    },
    {
      "x": -18,
      "y": 19,
      "z": -1,
      "name": "Scrap_Metal_Smooth",
      "rotation": 4
    },
    {
      "x": -18,
      "y": 20,
      "z": -1,
      "name": "Scrap_Metal_Smooth",
      "rotation": 4
    },
    {
      "x": -18,
      "y": 21,
      "z": -1,
      "name": "Soil_Clay_Smooth_Red"
    },
    {
      "x": -17,
      "y": 7,
      "z": -2,
      "name": "Plant_Moss_Wall_Green",
      "support": 15,
      "rotation": 2
    },
    {
      "x": -17,
      "y": 8,
      "z": -2,
      "name": "Plant_Moss_Wall_Green",
      "support": 15,
      "rotation": 2
    },
    {
      "x": -17,
      "y": -8,
      "z": -1,
      "name": "Plant_Moss_Block_Green",
      "support": 15
    },
    {
      "x": -17,
      "y": -7,
      "z": -1,
      "name": "Plant_Moss_Block_Green",
      "support": 15
    },
    {
      "x": -17,
      "y": -6,
      "z": -1,
      "name": "Scrap_Metal_Smooth",
      "rotation": 20
    },
    {
      "x": -17,
      "y": -5,
      "z": -1,
      "name": "Scrap_Metal_Smooth",
      "rotation": 20
    },
    {
      "x": -17,
      "y": -4,
      "z": -1,
      "name": "Scrap_Metal_Smooth",
      "rotation": 4
    },
    {
      "x": -17,
      "y": -3,
      "z": -1,
      "name": "Scrap_Metal_Smooth",
      "rotation": 4
    },
    {
      "x": -17,
      "y": -2,
      "z": -1,
      "name": "Scrap_Metal_Smooth",
      "rotation": 4
    },
    {
      "x": -17,
      "y": -1,
      "z": -1,
      "name": "Scrap_Metal_Smooth",
      "rotation": 4
    },
    {
      "x": -17,
      "y": 0,
      "z": -1,
      "name": "Soil_Clay"
    },
    {
      "x": -17,
      "y": 1,
      "z": -1,
      "name": "Soil_Clay_Smooth_Red"
    },
    {
      "x": -17,
      "y": 2,
      "z": -1,
      "name": "Rock_Sandstone_Red"
    },
    {
      "x": -17,
      "y": 3,
      "z": -1,
      "name": "Soil_Clay"
    },
    {
      "x": -17,
      "y": 4,
      "z": -1,
      "name": "Rock_Sandstone_Red"
    },
    {
      "x": -17,
      "y": 5,
      "z": -1,
      "name": "Soil_Clay"
    },
    {
      "x": -17,
      "y": 6,
      "z": -1,
      "name": "Scrap_Metal_Smooth",
      "rotation": 4
    },
    {
      "x": -17,
      "y": 7,
      "z": -1,
      "name": "Scrap_Metal_Smooth",
      "rotation": 4
    },
    {
      "x": -17,
      "y": 8,
      "z": -1,
      "name": "Scrap_Metal_Smooth",
      "rotation": 4
    },
    {
      "x": -17,
      "y": 9,
      "z": -1,
      "name": "Scrap_Metal_Smooth",
      "rotation": 4
    },
    {
      "x": -17,
      "y": 10,
      "z": -1,
      "name": "Scrap_Metal_Smooth",
      "rotation": 4
    },
    {
      "x": -17,
      "y": 11,
      "z": -1,
      "name": "Scrap_Metal_Smooth",
      "rotation": 4
    },
    {
      "x": -17,
      "y": 12,
      "z": -1,
      "name": "Scrap_Metal_Smooth",
      "rotation": 4
    },
    {
      "x": -17,
      "y": 13,
      "z": -1,
      "name": "Scrap_Metal_Smooth",
      "rotation": 4
    },
    {
      "x": -17,
      "y": 14,
      "z": -1,
      "name": "Scrap_Metal_Smooth",
      "rotation": 4
    },
    {
      "x": -17,
      "y": 15,
      "z": -1,
      "name": "Scrap_Metal_Smooth",
      "rotation": 4
    },
    {
      "x": -17,
      "y": 16,
      "z": -1,
      "name": "Scrap_Metal_Smooth",
      "rotation": 4
    },
    {
      "x": -17,
      "y": 17,
      "z": -1,
      "name": "Scrap_Metal_Smooth",
      "rotation": 4
    },
    {
      "x": -17,
      "y": 18,
      "z": -1,
      "name": "Scrap_Metal_Smooth",
      "rotation": 4
    },
    {
      "x": -17,
      "y": 19,
      "z": -1,
      "name": "Scrap_Metal_Smooth",
      "rotation": 4
    },
    {
      "x": -17,
      "y": 20,
      "z": -1,
      "name": "Scrap_Metal_Smooth",
      "rotation": 4
    },
    {
      "x": -17,
      "y": 21,
      "z": -1,
      "name": "Scrap_Metal_Smooth",
      "rotation": 30
    },
    {
      "x": -17,
      "y": 22,
      "z": -1,
      "name": "Plant_Moss_Rug_Green",
      "support": 15
    },
    {
      "x": -16,
      "y": 8,
      "z": -2,
      "name": "Plant_Moss_Wall_Green",
      "support": 15,
      "rotation": 2
    },
    {
      "x": -16,
      "y": -12,
      "z": -1,
      "name": "Scrap_Metal_Smooth",
      "rotation": 30
    },
    {
      "x": -16,
      "y": -11,
      "z": -1,
      "name": "Scrap_Metal_Smooth",
      "rotation": 30
    },
    {
      "x": -16,
      "y": -10,
      "z": -1,
      "name": "Plant_Moss_Block_Green",
      "support": 15
    },
    {
      "x": -16,
      "y": -9,
      "z": -1,
      "name": "Plant_Moss_Block_Green",
      "support": 15
    },
    {
      "x": -16,
      "y": -8,
      "z": -1,
      "name": "Scrap_Metal_Smooth",
      "rotation": 20
    },
    {
      "x": -16,
      "y": -7,
      "z": -1,
      "name": "Scrap_Metal_Smooth",
      "rotation": 20
    },
    {
      "x": -16,
      "y": -6,
      "z": -1,
      "name": "Scrap_Metal_Smooth",
      "rotation": 4
    },
    {
      "x": -16,
      "y": -5,
      "z": -1,
      "name": "Scrap_Metal_Smooth",
      "rotation": 4
    },
    {
      "x": -16,
      "y": -4,
      "z": -1,
      "name": "Scrap_Metal_Smooth",
      "rotation": 4
    },
    {
      "x": -16,
      "y": -3,
      "z": -1,
      "name": "Scrap_Metal_Smooth",
      "rotation": 4
    },
    {
      "x": -16,
      "y": -2,
      "z": -1,
      "name": "Scrap_Metal_Smooth",
      "rotation": 4
    },
    {
      "x": -16,
      "y": -1,
      "z": -1,
      "name": "Scrap_Metal_Smooth",
      "rotation": 4
    },
    {
      "x": -16,
      "y": 0,
      "z": -1,
      "name": "Scrap_Metal_Smooth",
      "rotation": 4
    },
    {
      "x": -16,
      "y": 1,
      "z": -1,
      "name": "Soil_Clay"
    },
    {
      "x": -16,
      "y": 2,
      "z": -1,
      "name": "Scrap_Metal_Smooth",
      "rotation": 4
    },
    {
      "x": -16,
      "y": 3,
      "z": -1,
      "name": "Scrap_Metal_Smooth",
      "rotation": 4
    },
    {
      "x": -16,
      "y": 4,
      "z": -1,
      "name": "Soil_Clay"
    },
    {
      "x": -16,
      "y": 5,
      "z": -1,
      "name": "Scrap_Metal_Smooth",
      "rotation": 4
    },
    {
      "x": -16,
      "y": 6,
      "z": -1,
      "name": "Scrap_Metal_Smooth",
      "rotation": 4
    },
    {
      "x": -16,
      "y": 7,
      "z": -1,
      "name": "Scrap_Metal_Smooth",
      "rotation": 4
    },
    {
      "x": -16,
      "y": 8,
      "z": -1,
      "name": "Scrap_Metal_Smooth",
      "rotation": 4
    },
    {
      "x": -16,
      "y": 9,
      "z": -1,
      "name": "Scrap_Metal_Smooth",
      "rotation": 4
    },
    {
      "x": -16,
      "y": 10,
      "z": -1,
      "name": "Scrap_Metal_Smooth",
      "rotation": 4
    },
    {
      "x": -16,
      "y": 11,
      "z": -1,
      "name": "Scrap_Metal_Smooth",
      "rotation": 4
    },
    {
      "x": -16,
      "y": 12,
      "z": -1,
      "name": "Scrap_Metal_Smooth",
      "rotation": 4
    },
    {
      "x": -16,
      "y": 13,
      "z": -1,
      "name": "Scrap_Metal_Smooth",
      "rotation": 4
    },
    {
      "x": -16,
      "y": 14,
      "z": -1,
      "name": "Scrap_Metal_Smooth",
      "rotation": 4
    },
    {
      "x": -16,
      "y": 15,
      "z": -1,
      "name": "Scrap_Metal_Smooth",
      "rotation": 4
    },
    {
      "x": -16,
      "y": 16,
      "z": -1,
      "name": "Scrap_Metal_Smooth",
      "rotation": 4
    },
    {
      "x": -16,
      "y": 17,
      "z": -1,
      "name": "Scrap_Metal_Smooth",
      "rotation": 4
    },
    {
      "x": -16,
      "y": 18,
      "z": -1,
      "name": "Scrap_Metal_Smooth",
      "rotation": 4
    },
    {
      "x": -16,
      "y": 19,
      "z": -1,
      "name": "Scrap_Metal_Smooth",
      "rotation": 4
    },
    {
      "x": -16,
      "y": 20,
      "z": -1,
      "name": "Scrap_Metal_Smooth",
      "rotation": 4
    },
    {
      "x": -16,
      "y": 21,
      "z": -1,
      "name": "Plant_Moss_Block_Green",
      "support": 15
    },
    {
      "x": -16,
      "y": 22,
      "z": -1,
      "name": "Plant_Moss_Rug_Green",
      "support": 15
    },
    {
      "x": -15,
      "y": 9,
      "z": -2,
      "name": "Plant_Moss_Wall_Green",
      "support": 15,
      "rotation": 2
    },
    {
      "x": -15,
      "y": 21,
      "z": -2,
      "name": "Plant_Moss_Wall_Green",
      "support": 15,
      "rotation": 2
    },
    {
      "x": -15,
      "y": -13,
      "z": -1,
      "name": "Scrap_Metal_Smooth",
      "rotation": 30
    },
    {
      "x": -15,
      "y": -12,
      "z": -1,
      "name": "Scrap_Metal_Smooth",
      "rotation": 20
    },
    {
      "x": -15,
      "y": -11,
      "z": -1,
      "name": "Scrap_Metal_Smooth",
      "rotation": 20
    },
    {
      "x": -15,
      "y": -10,
      "z": -1,
      "name": "Soil_Clay"
    },
    {
      "x": -15,
      "y": -9,
      "z": -1,
      "name": "Scrap_Metal_Smooth",
      "rotation": 20
    },
    {
      "x": -15,
      "y": -8,
      "z": -1,
      "name": "Scrap_Metal_Smooth",
      "rotation": 20
    },
    {
      "x": -15,
      "y": -7,
      "z": -1,
      "name": "Scrap_Metal_Smooth",
      "rotation": 20
    },
    {
      "x": -15,
      "y": -6,
      "z": -1,
      "name": "Scrap_Metal_Smooth",
      "rotation": 4
    },
    {
      "x": -15,
      "y": -5,
      "z": -1,
      "name": "Scrap_Metal_Smooth",
      "rotation": 4
    },
    {
      "x": -15,
      "y": -4,
      "z": -1,
      "name": "Scrap_Metal_Smooth",
      "rotation": 4
    },
    {
      "x": -15,
      "y": -3,
      "z": -1,
      "name": "Scrap_Metal_Smooth",
      "rotation": 4
    },
    {
      "x": -15,
      "y": -2,
      "z": -1,
      "name": "Scrap_Metal_Smooth",
      "rotation": 4
    },
    {
      "x": -15,
      "y": -1,
      "z": -1,
      "name": "Scrap_Metal_Smooth",
      "rotation": 4
    },
    {
      "x": -15,
      "y": 0,
      "z": -1,
      "name": "Scrap_Metal_Smooth",
      "rotation": 4
    },
    {
      "x": -15,
      "y": 1,
      "z": -1,
      "name": "Scrap_Metal_Smooth",
      "rotation": 4
    },
    {
      "x": -15,
      "y": 2,
      "z": -1,
      "name": "Scrap_Metal_Smooth",
      "rotation": 4
    },
    {
      "x": -15,
      "y": 3,
      "z": -1,
      "name": "Scrap_Metal_Smooth",
      "rotation": 4
    },
    {
      "x": -15,
      "y": 4,
      "z": -1,
      "name": "Scrap_Metal_Smooth",
      "rotation": 4
    },
    {
      "x": -15,
      "y": 5,
      "z": -1,
      "name": "Scrap_Metal_Smooth",
      "rotation": 4
    },
    {
      "x": -15,
      "y": 6,
      "z": -1,
      "name": "Scrap_Metal_Smooth",
      "rotation": 4
    },
    {
      "x": -15,
      "y": 7,
      "z": -1,
      "name": "Scrap_Metal_Smooth",
      "rotation": 4
    },
    {
      "x": -15,
      "y": 8,
      "z": -1,
      "name": "Scrap_Metal_Smooth",
      "rotation": 4
    },
    {
      "x": -15,
      "y": 9,
      "z": -1,
      "name": "Scrap_Metal_Smooth",
      "rotation": 4
    },
    {
      "x": -15,
      "y": 10,
      "z": -1,
      "name": "Scrap_Metal_Smooth",
      "rotation": 4
    },
    {
      "x": -15,
      "y": 11,
      "z": -1,
      "name": "Scrap_Metal_Smooth",
      "rotation": 4
    },
    {
      "x": -15,
      "y": 12,
      "z": -1,
      "name": "Scrap_Metal_Smooth",
      "rotation": 4
    },
    {
      "x": -15,
      "y": 13,
      "z": -1,
      "name": "Scrap_Metal_Smooth",
      "rotation": 4
    },
    {
      "x": -15,
      "y": 14,
      "z": -1,
      "name": "Scrap_Metal_Smooth",
      "rotation": 4
    },
    {
      "x": -15,
      "y": 15,
      "z": -1,
      "name": "Scrap_Metal_Smooth",
      "rotation": 4
    },
    {
      "x": -15,
      "y": 16,
      "z": -1,
      "name": "Scrap_Metal_Smooth",
      "rotation": 4
    },
    {
      "x": -15,
      "y": 17,
      "z": -1,
      "name": "Scrap_Metal_Smooth",
      "rotation": 4
    },
    {
      "x": -15,
      "y": 18,
      "z": -1,
      "name": "Scrap_Metal_Smooth",
      "rotation": 4
    },
    {
      "x": -15,
      "y": 19,
      "z": -1,
      "name": "Scrap_Metal_Smooth",
      "rotation": 4
    },
    {
      "x": -15,
      "y": 20,
      "z": -1,
      "name": "Scrap_Metal_Smooth",
      "rotation": 4
    },
    {
      "x": -15,
      "y": 21,
      "z": -1,
      "name": "Plant_Moss_Block_Green",
      "support": 15
    },
    {
      "x": -15,
      "y": 21,
      "z": 0,
      "name": "Plant_Moss_Wall_Green",
      "support": 15
    },
    {
      "x": -14,
      "y": -13,
      "z": -1,
      "name": "Scrap_Metal_Smooth",
      "rotation": 30
    },
    {
      "x": -14,
      "y": -12,
      "z": -1,
      "name": "Scrap_Metal_Smooth",
      "rotation": 20
    },
    {
      "x": -14,
      "y": -9,
      "z": -1,
      "name": "Soil_Clay"
    },
    {
      "x": -14,
      "y": -8,
      "z": -1,
      "name": "Scrap_Metal_Smooth",
      "rotation": 20
    },
    {
      "x": -14,
      "y": -7,
      "z": -1,
      "name": "Scrap_Metal_Smooth",
      "rotation": 20
    },
    {
      "x": -14,
      "y": -6,
      "z": -1,
      "name": "Scrap_Metal_Smooth",
      "rotation": 4
    },
    {
      "x": -14,
      "y": -5,
      "z": -1,
      "name": "Scrap_Metal_Smooth",
      "rotation": 4
    },
    {
      "x": -14,
      "y": -4,
      "z": -1,
      "name": "Scrap_Metal_Smooth",
      "rotation": 4
    },
    {
      "x": -14,
      "y": -3,
      "z": -1,
      "name": "Scrap_Metal_Smooth",
      "rotation": 4
    },
    {
      "x": -14,
      "y": -2,
      "z": -1,
      "name": "Scrap_Metal_Smooth",
      "rotation": 4
    },
    {
      "x": -14,
      "y": -1,
      "z": -1,
      "name": "Scrap_Metal_Smooth",
      "rotation": 4
    },
    {
      "x": -14,
      "y": 0,
      "z": -1,
      "name": "Scrap_Metal_Smooth",
      "rotation": 4
    },
    {
      "x": -14,
      "y": 1,
      "z": -1,
      "name": "Scrap_Metal_Smooth",
      "rotation": 4
    },
    {
      "x": -14,
      "y": 2,
      "z": -1,
      "name": "Scrap_Metal_Smooth",
      "rotation": 4
    },
    {
      "x": -14,
      "y": 3,
      "z": -1,
      "name": "Scrap_Metal_Smooth",
      "rotation": 4
    },
    {
      "x": -14,
      "y": 4,
      "z": -1,
      "name": "Scrap_Metal_Smooth",
      "rotation": 4
    },
    {
      "x": -14,
      "y": 5,
      "z": -1,
      "name": "Scrap_Metal_Smooth",
      "rotation": 4
    },
    {
      "x": -14,
      "y": 6,
      "z": -1,
      "name": "Scrap_Metal_Smooth",
      "rotation": 4
    },
    {
      "x": -14,
      "y": 7,
      "z": -1,
      "name": "Scrap_Metal_Smooth",
      "rotation": 4
    },
    {
      "x": -14,
      "y": 8,
      "z": -1,
      "name": "Scrap_Metal_Smooth",
      "rotation": 4
    },
    {
      "x": -14,
      "y": 9,
      "z": -1,
      "name": "Scrap_Metal_Smooth",
      "rotation": 4
    },
    {
      "x": -14,
      "y": 10,
      "z": -1,
      "name": "Scrap_Metal_Smooth",
      "rotation": 4
    },
    {
      "x": -14,
      "y": 11,
      "z": -1,
      "name": "Scrap_Metal_Smooth",
      "rotation": 4
    },
    {
      "x": -14,
      "y": 12,
      "z": -1,
      "name": "Scrap_Metal_Smooth",
      "rotation": 4
    },
    {
      "x": -14,
      "y": 13,
      "z": -1,
      "name": "Scrap_Metal_Smooth",
      "rotation": 4
    },
    {
      "x": -14,
      "y": 14,
      "z": -1,
      "name": "Scrap_Metal_Smooth",
      "rotation": 4
    },
    {
      "x": -14,
      "y": 15,
      "z": -1,
      "name": "Scrap_Metal_Smooth",
      "rotation": 4
    },
    {
      "x": -14,
      "y": 16,
      "z": -1,
      "name": "Rock_Sandstone_Red"
    },
    {
      "x": -14,
      "y": 17,
      "z": -1,
      "name": "Scrap_Metal_Smooth",
      "rotation": 4
    },
    {
      "x": -14,
      "y": 18,
      "z": -1,
      "name": "Scrap_Metal_Smooth",
      "rotation": 4
    },
    {
      "x": -14,
      "y": 19,
      "z": -1,
      "name": "Scrap_Metal_Smooth",
      "rotation": 4
    },
    {
      "x": -14,
      "y": 20,
      "z": -1,
      "name": "Scrap_Metal_Smooth",
      "rotation": 4
    },
    {
      "x": -14,
      "y": 21,
      "z": -1,
      "name": "Scrap_Metal_Smooth",
      "rotation": 4
    },
    {
      "x": -14,
      "y": 22,
      "z": -1,
      "name": "Plant_Moss_Block_Green",
      "support": 15
    },
    {
      "x": -14,
      "y": 22,
      "z": 0,
      "name": "Plant_Moss_Wall_Green",
      "support": 15
    },
    {
      "x": -13,
      "y": -13,
      "z": -1,
      "name": "Scrap_Metal_Smooth",
      "rotation": 30
    },
    {
      "x": -13,
      "y": -12,
      "z": -1,
      "name": "Plant_Moss_Block_Green",
      "support": 15
    },
    {
      "x": -13,
      "y": -9,
      "z": -1,
      "name": "Scrap_Metal_Smooth",
      "rotation": 20
    },
    {
      "x": -13,
      "y": -8,
      "z": -1,
      "name": "Scrap_Metal_Smooth",
      "rotation": 20
    },
    {
      "x": -13,
      "y": -7,
      "z": -1,
      "name": "Scrap_Metal_Smooth",
      "rotation": 20
    },
    {
      "x": -13,
      "y": -6,
      "z": -1,
      "name": "Scrap_Metal_Smooth",
      "rotation": 4
    },
    {
      "x": -13,
      "y": -5,
      "z": -1,
      "name": "Scrap_Metal_Smooth",
      "rotation": 4
    },
    {
      "x": -13,
      "y": -4,
      "z": -1,
      "name": "Scrap_Metal_Smooth",
      "rotation": 4
    },
    {
      "x": -13,
      "y": -3,
      "z": -1,
      "name": "Scrap_Metal_Smooth",
      "rotation": 4
    },
    {
      "x": -13,
      "y": -2,
      "z": -1,
      "name": "Scrap_Metal_Smooth",
      "rotation": 4
    },
    {
      "x": -13,
      "y": -1,
      "z": -1,
      "name": "Scrap_Metal_Smooth",
      "rotation": 4
    },
    {
      "x": -13,
      "y": 0,
      "z": -1,
      "name": "Scrap_Metal_Smooth",
      "rotation": 4
    },
    {
      "x": -13,
      "y": 1,
      "z": -1,
      "name": "Scrap_Metal_Smooth",
      "rotation": 4
    },
    {
      "x": -13,
      "y": 2,
      "z": -1,
      "name": "Scrap_Metal_Smooth",
      "rotation": 4
    },
    {
      "x": -13,
      "y": 3,
      "z": -1,
      "name": "Scrap_Metal_Smooth",
      "rotation": 4
    },
    {
      "x": -13,
      "y": 4,
      "z": -1,
      "name": "Scrap_Metal_Smooth",
      "rotation": 4
    },
    {
      "x": -13,
      "y": 5,
      "z": -1,
      "name": "Scrap_Metal_Smooth",
      "rotation": 4
    },
    {
      "x": -13,
      "y": 6,
      "z": -1,
      "name": "Scrap_Metal_Smooth",
      "rotation": 4
    },
    {
      "x": -13,
      "y": 7,
      "z": -1,
      "name": "Scrap_Metal_Smooth",
      "rotation": 4
    },
    {
      "x": -13,
      "y": 8,
      "z": -1,
      "name": "Scrap_Metal_Smooth",
      "rotation": 4
    },
    {
      "x": -13,
      "y": 9,
      "z": -1,
      "name": "Scrap_Metal_Smooth",
      "rotation": 4
    },
    {
      "x": -13,
      "y": 10,
      "z": -1,
      "name": "Scrap_Metal_Smooth",
      "rotation": 4
    },
    {
      "x": -13,
      "y": 11,
      "z": -1,
      "name": "Scrap_Metal_Smooth",
      "rotation": 4
    },
    {
      "x": -13,
      "y": 12,
      "z": -1,
      "name": "Scrap_Metal_Smooth",
      "rotation": 4
    },
    {
      "x": -13,
      "y": 13,
      "z": -1,
      "name": "Scrap_Metal_Smooth",
      "rotation": 4
    },
    {
      "x": -13,
      "y": 14,
      "z": -1,
      "name": "Scrap_Metal_Smooth",
      "rotation": 4
    },
    {
      "x": -13,
      "y": 15,
      "z": -1,
      "name": "Scrap_Metal_Smooth",
      "rotation": 4
    },
    {
      "x": -13,
      "y": 16,
      "z": -1,
      "name": "Scrap_Metal_Smooth",
      "rotation": 4
    },
    {
      "x": -13,
      "y": 17,
      "z": -1,
      "name": "Soil_Clay"
    },
    {
      "x": -13,
      "y": 18,
      "z": -1,
      "name": "Scrap_Metal_Smooth",
      "rotation": 4
    },
    {
      "x": -13,
      "y": 19,
      "z": -1,
      "name": "Scrap_Metal_Smooth",
      "rotation": 4
    },
    {
      "x": -13,
      "y": 20,
      "z": -1,
      "name": "Scrap_Metal_Smooth",
      "rotation": 4
    },
    {
      "x": -13,
      "y": 21,
      "z": -1,
      "name": "Scrap_Metal_Smooth",
      "rotation": 4
    },
    {
      "x": -13,
      "y": 22,
      "z": -1,
      "name": "Scrap_Metal_Smooth",
      "rotation": 30
    },
    {
      "x": -12,
      "y": -13,
      "z": 0,
      "name": "Scrap_Metal_Smooth",
      "rotation": 30
    },
    {
      "x": -12,
      "y": -12,
      "z": 0,
      "name": "Soil_Clay"
    },
    {
      "x": -12,
      "y": -11,
      "z": 0,
      "name": "Soil_Clay"
    },
    {
      "x": -12,
      "y": -10,
      "z": 0,
      "name": "Scrap_Metal_Smooth",
      "rotation": 20
    },
    {
      "x": -12,
      "y": -9,
      "z": 0,
      "name": "Scrap_Metal_Smooth",
      "rotation": 20
    },
    {
      "x": -12,
      "y": -8,
      "z": 0,
      "name": "Scrap_Metal_Smooth",
      "rotation": 20
    },
    {
      "x": -12,
      "y": -7,
      "z": 0,
      "name": "Scrap_Metal_Smooth",
      "rotation": 20
    },
    {
      "x": -12,
      "y": -6,
      "z": 0,
      "name": "Scrap_Metal_Smooth",
      "rotation": 4
    },
    {
      "x": -12,
      "y": -5,
      "z": 0,
      "name": "Scrap_Metal_Smooth",
      "rotation": 4
    },
    {
      "x": -12,
      "y": -4,
      "z": 0,
      "name": "Scrap_Metal_Smooth",
      "rotation": 4
    },
    {
      "x": -12,
      "y": -3,
      "z": 0,
      "name": "Scrap_Metal_Smooth",
      "rotation": 4
    },
    {
      "x": -12,
      "y": -2,
      "z": 0,
      "name": "Scrap_Metal_Smooth",
      "rotation": 4
    },
    {
      "x": -12,
      "y": -1,
      "z": 0,
      "name": "Scrap_Metal_Smooth",
      "rotation": 4
    },
    {
      "x": -12,
      "y": 0,
      "z": 0,
      "name": "Scrap_Metal_Smooth",
      "rotation": 4
    },
    {
      "x": -12,
      "y": 1,
      "z": 0,
      "name": "Scrap_Metal_Smooth",
      "rotation": 4
    },
    {
      "x": -12,
      "y": 2,
      "z": 0,
      "name": "Scrap_Metal_Smooth",
      "rotation": 4
    },
    {
      "x": -12,
      "y": 3,
      "z": 0,
      "name": "Scrap_Metal_Smooth",
      "rotation": 4
    },
    {
      "x": -12,
      "y": 4,
      "z": 0,
      "name": "Scrap_Metal_Smooth",
      "rotation": 4
    },
    {
      "x": -12,
      "y": 5,
      "z": 0,
      "name": "Scrap_Metal_Smooth",
      "rotation": 4
    },
    {
      "x": -12,
      "y": 6,
      "z": 0,
      "name": "Scrap_Metal_Smooth",
      "rotation": 4
    },
    {
      "x": -12,
      "y": 7,
      "z": 0,
      "name": "Scrap_Metal_Smooth",
      "rotation": 4
    },
    {
      "x": -12,
      "y": 8,
      "z": 0,
      "name": "Scrap_Metal_Smooth",
      "rotation": 4
    },
    {
      "x": -12,
      "y": 9,
      "z": 0,
      "name": "Scrap_Metal_Smooth",
      "rotation": 4
    },
    {
      "x": -12,
      "y": 10,
      "z": 0,
      "name": "Scrap_Metal_Smooth",
      "rotation": 4
    },
    {
      "x": -12,
      "y": 11,
      "z": 0,
      "name": "Scrap_Metal_Smooth",
      "rotation": 4
    },
    {
      "x": -12,
      "y": 12,
      "z": 0,
      "name": "Scrap_Metal_Smooth",
      "rotation": 4
    },
    {
      "x": -12,
      "y": 13,
      "z": 0,
      "name": "Scrap_Metal_Smooth",
      "rotation": 4
    },
    {
      "x": -12,
      "y": 14,
      "z": 0,
      "name": "Scrap_Metal_Smooth",
      "rotation": 4
    },
    {
      "x": -12,
      "y": 15,
      "z": 0,
      "name": "Scrap_Metal_Smooth",
      "rotation": 4
    },
    {
      "x": -12,
      "y": 16,
      "z": 0,
      "name": "Scrap_Metal_Smooth",
      "rotation": 4
    },
    {
      "x": -12,
      "y": 17,
      "z": 0,
      "name": "Scrap_Metal_Smooth",
      "rotation": 4
    },
    {
      "x": -12,
      "y": 18,
      "z": 0,
      "name": "Scrap_Metal_Smooth",
      "rotation": 4
    },
    {
      "x": -12,
      "y": 19,
      "z": 0,
      "name": "Scrap_Metal_Smooth",
      "rotation": 4
    },
    {
      "x": -12,
      "y": 20,
      "z": 0,
      "name": "Scrap_Metal_Smooth",
      "rotation": 4
    },
    {
      "x": -12,
      "y": 21,
      "z": 0,
      "name": "Scrap_Metal_Smooth",
      "rotation": 4
    },
    {
      "x": -12,
      "y": 22,
      "z": 0,
      "name": "Scrap_Metal_Smooth",
      "rotation": 30
    },
    {
      "x": -11,
      "y": -12,
      "z": 0,
      "name": "Scrap_Metal_Smooth",
      "rotation": 30
    },
    {
      "x": -11,
      "y": -11,
      "z": 0,
      "name": "Scrap_Metal_Smooth",
      "rotation": 20
    },
    {
      "x": -11,
      "y": -10,
      "z": 0,
      "name": "Scrap_Metal_Smooth",
      "rotation": 20
    },
    {
      "x": -11,
      "y": -9,
      "z": 0,
      "name": "Scrap_Metal_Smooth",
      "rotation": 20
    },
    {
      "x": -11,
      "y": -8,
      "z": 0,
      "name": "Scrap_Metal_Smooth",
      "rotation": 20
    },
    {
      "x": -11,
      "y": -7,
      "z": 0,
      "name": "Scrap_Metal_Smooth",
      "rotation": 20
    },
    {
      "x": -11,
      "y": -6,
      "z": 0,
      "name": "Scrap_Metal_Smooth",
      "rotation": 4
    },
    {
      "x": -11,
      "y": -5,
      "z": 0,
      "name": "Scrap_Metal_Smooth",
      "rotation": 4
    },
    {
      "x": -11,
      "y": -4,
      "z": 0,
      "name": "Scrap_Metal_Smooth",
      "rotation": 4
    },
    {
      "x": -11,
      "y": -3,
      "z": 0,
      "name": "Scrap_Metal_Smooth",
      "rotation": 4
    },
    {
      "x": -11,
      "y": -2,
      "z": 0,
      "name": "Scrap_Metal_Smooth",
      "rotation": 4
    },
    {
      "x": -11,
      "y": -1,
      "z": 0,
      "name": "Scrap_Metal_Smooth",
      "rotation": 4
    },
    {
      "x": -11,
      "y": 0,
      "z": 0,
      "name": "Scrap_Metal_Smooth",
      "rotation": 4
    },
    {
      "x": -11,
      "y": 1,
      "z": 0,
      "name": "Scrap_Metal_Smooth",
      "rotation": 4
    },
    {
      "x": -11,
      "y": 2,
      "z": 0,
      "name": "Scrap_Metal_Smooth",
      "rotation": 4
    },
    {
      "x": -11,
      "y": 3,
      "z": 0,
      "name": "Scrap_Metal_Smooth",
      "rotation": 4
    },
    {
      "x": -11,
      "y": 4,
      "z": 0,
      "name": "Scrap_Metal_Smooth",
      "rotation": 4
    },
    {
      "x": -11,
      "y": 5,
      "z": 0,
      "name": "Scrap_Metal_Smooth",
      "rotation": 4
    },
    {
      "x": -11,
      "y": 6,
      "z": 0,
      "name": "Scrap_Metal_Smooth",
      "rotation": 4
    },
    {
      "x": -11,
      "y": 7,
      "z": 0,
      "name": "Scrap_Metal_Smooth",
      "rotation": 4
    },
    {
      "x": -11,
      "y": 8,
      "z": 0,
      "name": "Scrap_Metal_Smooth",
      "rotation": 4
    },
    {
      "x": -11,
      "y": 9,
      "z": 0,
      "name": "Scrap_Metal_Smooth",
      "rotation": 4
    },
    {
      "x": -11,
      "y": 10,
      "z": 0,
      "name": "Scrap_Metal_Smooth",
      "rotation": 4
    },
    {
      "x": -11,
      "y": 11,
      "z": 0,
      "name": "Scrap_Metal_Smooth",
      "rotation": 4
    },
    {
      "x": -11,
      "y": 12,
      "z": 0,
      "name": "Scrap_Metal_Smooth",
      "rotation": 4
    },
    {
      "x": -11,
      "y": 13,
      "z": 0,
      "name": "Scrap_Metal_Smooth",
      "rotation": 4
    },
    {
      "x": -11,
      "y": 14,
      "z": 0,
      "name": "Scrap_Metal_Smooth",
      "rotation": 4
    },
    {
      "x": -11,
      "y": 15,
      "z": 0,
      "name": "Scrap_Metal_Smooth",
      "rotation": 4
    },
    {
      "x": -11,
      "y": 16,
      "z": 0,
      "name": "Scrap_Metal_Smooth",
      "rotation": 4
    },
    {
      "x": -11,
      "y": 17,
      "z": 0,
      "name": "Scrap_Metal_Smooth",
      "rotation": 4
    },
    {
      "x": -11,
      "y": 18,
      "z": 0,
      "name": "Scrap_Metal_Smooth",
      "rotation": 4
    },
    {
      "x": -11,
      "y": 19,
      "z": 0,
      "name": "Scrap_Metal_Smooth",
      "rotation": 4
    },
    {
      "x": -11,
      "y": 20,
      "z": 0,
      "name": "Scrap_Metal_Smooth",
      "rotation": 4
    },
    {
      "x": -11,
      "y": 21,
      "z": 0,
      "name": "Scrap_Metal_Smooth",
      "rotation": 4
    },
    {
      "x": -11,
      "y": 22,
      "z": 0,
      "name": "Scrap_Metal_Smooth",
      "rotation": 30
    },
    {
      "x": -11,
      "y": 12,
      "z": 1,
      "name": "Plant_Moss_Wall_Green",
      "support": 15
    },
    {
      "x": -11,
      "y": 13,
      "z": 1,
      "name": "Plant_Moss_Wall_Green",
      "support": 15
    },
    {
      "x": -10,
      "y": -12,
      "z": 0,
      "name": "Scrap_Metal_Smooth",
      "rotation": 30
    },
    {
      "x": -10,
      "y": -11,
      "z": 0,
      "name": "Scrap_Metal_Smooth",
      "rotation": 20
    },
    {
      "x": -10,
      "y": -10,
      "z": 0,
      "name": "Scrap_Metal_Smooth",
      "rotation": 20
    },
    {
      "x": -10,
      "y": -9,
      "z": 0,
      "name": "Scrap_Metal_Smooth",
      "rotation": 20
    },
    {
      "x": -10,
      "y": -8,
      "z": 0,
      "name": "Scrap_Metal_Smooth",
      "rotation": 20
    },
    {
      "x": -10,
      "y": -7,
      "z": 0,
      "name": "Scrap_Metal_Smooth",
      "rotation": 20
    },
    {
      "x": -10,
      "y": -6,
      "z": 0,
      "name": "Scrap_Metal_Smooth",
      "rotation": 4
    },
    {
      "x": -10,
      "y": -5,
      "z": 0,
      "name": "Scrap_Metal_Smooth",
      "rotation": 4
    },
    {
      "x": -10,
      "y": -4,
      "z": 0,
      "name": "Scrap_Metal_Smooth",
      "rotation": 4
    },
    {
      "x": -10,
      "y": -3,
      "z": 0,
      "name": "Scrap_Metal_Smooth",
      "rotation": 4
    },
    {
      "x": -10,
      "y": -2,
      "z": 0,
      "name": "Scrap_Metal_Smooth",
      "rotation": 4
    },
    {
      "x": -10,
      "y": -1,
      "z": 0,
      "name": "Scrap_Metal_Smooth",
      "rotation": 4
    },
    {
      "x": -10,
      "y": 0,
      "z": 0,
      "name": "Scrap_Metal_Smooth",
      "rotation": 4
    },
    {
      "x": -10,
      "y": 1,
      "z": 0,
      "name": "Scrap_Metal_Smooth",
      "rotation": 4
    },
    {
      "x": -10,
      "y": 2,
      "z": 0,
      "name": "Scrap_Metal_Smooth",
      "rotation": 4
    },
    {
      "x": -10,
      "y": 3,
      "z": 0,
      "name": "Scrap_Metal_Smooth",
      "rotation": 4
    },
    {
      "x": -10,
      "y": 4,
      "z": 0,
      "name": "Scrap_Metal_Smooth",
      "rotation": 4
    },
    {
      "x": -10,
      "y": 5,
      "z": 0,
      "name": "Scrap_Metal_Smooth",
      "rotation": 4
    },
    {
      "x": -10,
      "y": 6,
      "z": 0,
      "name": "Scrap_Metal_Smooth",
      "rotation": 4
    },
    {
      "x": -10,
      "y": 7,
      "z": 0,
      "name": "Scrap_Metal_Smooth",
      "rotation": 4
    },
    {
      "x": -10,
      "y": 8,
      "z": 0,
      "name": "Scrap_Metal_Smooth",
      "rotation": 4
    },
    {
      "x": -10,
      "y": 9,
      "z": 0,
      "name": "Scrap_Metal_Smooth",
      "rotation": 4
    },
    {
      "x": -10,
      "y": 10,
      "z": 0,
      "name": "Scrap_Metal_Smooth",
      "rotation": 4
    },
    {
      "x": -10,
      "y": 11,
      "z": 0,
      "name": "Scrap_Metal_Smooth",
      "rotation": 4
    },
    {
      "x": -10,
      "y": 12,
      "z": 0,
      "name": "Scrap_Metal_Smooth",
      "rotation": 4
    },
    {
      "x": -10,
      "y": 13,
      "z": 0,
      "name": "Scrap_Metal_Smooth",
      "rotation": 4
    },
    {
      "x": -10,
      "y": 14,
      "z": 0,
      "name": "Scrap_Metal_Smooth",
      "rotation": 4
    },
    {
      "x": -10,
      "y": 15,
      "z": 0,
      "name": "Scrap_Metal_Smooth",
      "rotation": 4
    },
    {
      "x": -10,
      "y": 16,
      "z": 0,
      "name": "Scrap_Metal_Smooth",
      "rotation": 4
    },
    {
      "x": -10,
      "y": 17,
      "z": 0,
      "name": "Scrap_Metal_Smooth",
      "rotation": 4
    },
    {
      "x": -10,
      "y": 18,
      "z": 0,
      "name": "Scrap_Metal_Smooth",
      "rotation": 4
    },
    {
      "x": -10,
      "y": 19,
      "z": 0,
      "name": "Scrap_Metal_Smooth",
      "rotation": 4
    },
    {
      "x": -10,
      "y": 20,
      "z": 0,
      "name": "Scrap_Metal_Smooth",
      "rotation": 4
    },
    {
      "x": -10,
      "y": 21,
      "z": 0,
      "name": "Scrap_Metal_Smooth",
      "rotation": 4
    },
    {
      "x": -10,
      "y": 22,
      "z": 0,
      "name": "Scrap_Metal_Smooth",
      "rotation": 4
    },
    {
      "x": -10,
      "y": 23,
      "z": 0,
      "name": "Soil_Clay"
    },
    {
      "x": -10,
      "y": 11,
      "z": 1,
      "name": "Plant_Moss_Wall_Green",
      "support": 15
    },
    {
      "x": -10,
      "y": 12,
      "z": 1,
      "name": "Plant_Moss_Wall_Green",
      "support": 15
    },
    {
      "x": -10,
      "y": 13,
      "z": 1,
      "name": "Plant_Moss_Wall_Green",
      "support": 15
    },
    {
      "x": -10,
      "y": 14,
      "z": 1,
      "name": "Plant_Moss_Wall_Green",
      "support": 15
    },
    {
      "x": -9,
      "y": -12,
      "z": 0,
      "name": "Plant_Moss_Block_Green",
      "support": 15
    },
    {
      "x": -9,
      "y": -11,
      "z": 0,
      "name": "Scrap_Metal_Smooth",
      "rotation": 20
    },
    {
      "x": -9,
      "y": -10,
      "z": 0,
      "name": "Scrap_Metal_Smooth",
      "rotation": 20
    },
    {
      "x": -9,
      "y": -9,
      "z": 0,
      "name": "Scrap_Metal_Smooth",
      "rotation": 20
    },
    {
      "x": -9,
      "y": -8,
      "z": 0,
      "name": "Scrap_Metal_Smooth",
      "rotation": 20
    },
    {
      "x": -9,
      "y": -7,
      "z": 0,
      "name": "Scrap_Metal_Smooth",
      "rotation": 20
    },
    {
      "x": -9,
      "y": -6,
      "z": 0,
      "name": "Scrap_Metal_Smooth",
      "rotation": 4
    },
    {
      "x": -9,
      "y": -5,
      "z": 0,
      "name": "Scrap_Metal_Smooth",
      "rotation": 4
    },
    {
      "x": -9,
      "y": -4,
      "z": 0,
      "name": "Scrap_Metal_Smooth",
      "rotation": 4
    },
    {
      "x": -9,
      "y": -3,
      "z": 0,
      "name": "Scrap_Metal_Smooth",
      "rotation": 4
    },
    {
      "x": -9,
      "y": -2,
      "z": 0,
      "name": "Scrap_Metal_Smooth",
      "rotation": 4
    },
    {
      "x": -9,
      "y": -1,
      "z": 0,
      "name": "Scrap_Metal_Smooth",
      "rotation": 4
    },
    {
      "x": -9,
      "y": 0,
      "z": 0,
      "name": "Scrap_Metal_Smooth",
      "rotation": 4
    },
    {
      "x": -9,
      "y": 1,
      "z": 0,
      "name": "Scrap_Metal_Smooth",
      "rotation": 4
    },
    {
      "x": -9,
      "y": 2,
      "z": 0,
      "name": "Scrap_Metal_Smooth",
      "rotation": 4
    },
    {
      "x": -9,
      "y": 3,
      "z": 0,
      "name": "Scrap_Metal_Smooth",
      "rotation": 4
    },
    {
      "x": -9,
      "y": 4,
      "z": 0,
      "name": "Scrap_Metal_Smooth",
      "rotation": 4
    },
    {
      "x": -9,
      "y": 5,
      "z": 0,
      "name": "Scrap_Metal_Smooth",
      "rotation": 4
    },
    {
      "x": -9,
      "y": 6,
      "z": 0,
      "name": "Scrap_Metal_Smooth",
      "rotation": 4
    },
    {
      "x": -9,
      "y": 7,
      "z": 0,
      "name": "Scrap_Metal_Smooth",
      "rotation": 4
    },
    {
      "x": -9,
      "y": 8,
      "z": 0,
      "name": "Scrap_Metal_Smooth",
      "rotation": 4
    },
    {
      "x": -9,
      "y": 9,
      "z": 0,
      "name": "Scrap_Metal_Smooth",
      "rotation": 4
    },
    {
      "x": -9,
      "y": 10,
      "z": 0,
      "name": "Scrap_Metal_Smooth",
      "rotation": 4
    },
    {
      "x": -9,
      "y": 11,
      "z": 0,
      "name": "Scrap_Metal_Smooth",
      "rotation": 4
    },
    {
      "x": -9,
      "y": 12,
      "z": 0,
      "name": "Scrap_Metal_Smooth",
      "rotation": 4
    },
    {
      "x": -9,
      "y": 13,
      "z": 0,
      "name": "Scrap_Metal_Smooth",
      "rotation": 4
    },
    {
      "x": -9,
      "y": 14,
      "z": 0,
      "name": "Scrap_Metal_Smooth",
      "rotation": 4
    },
    {
      "x": -9,
      "y": 15,
      "z": 0,
      "name": "Scrap_Metal_Smooth",
      "rotation": 4
    },
    {
      "x": -9,
      "y": 16,
      "z": 0,
      "name": "Scrap_Metal_Smooth",
      "rotation": 4
    },
    {
      "x": -9,
      "y": 17,
      "z": 0,
      "name": "Scrap_Metal_Smooth",
      "rotation": 4
    },
    {
      "x": -9,
      "y": 18,
      "z": 0,
      "name": "Scrap_Metal_Smooth",
      "rotation": 4
    },
    {
      "x": -9,
      "y": 19,
      "z": 0,
      "name": "Scrap_Metal_Smooth",
      "rotation": 4
    },
    {
      "x": -9,
      "y": 20,
      "z": 0,
      "name": "Scrap_Metal_Smooth",
      "rotation": 4
    },
    {
      "x": -9,
      "y": 21,
      "z": 0,
      "name": "Scrap_Metal_Smooth",
      "rotation": 4
    },
    {
      "x": -9,
      "y": 22,
      "z": 0,
      "name": "Rock_Sandstone_Red"
    },
    {
      "x": -9,
      "y": 23,
      "z": 0,
      "name": "Soil_Clay"
    },
    {
      "x": -9,
      "y": 9,
      "z": 1,
      "name": "Plant_Moss_Wall_Green",
      "support": 15
    },
    {
      "x": -9,
      "y": 11,
      "z": 1,
      "name": "Plant_Moss_Wall_Green",
      "support": 15
    },
    {
      "x": -8,
      "y": -12,
      "z": 0,
      "name": "Plant_Moss_Block_Green",
      "support": 15
    },
    {
      "x": -8,
      "y": -11,
      "z": 0,
      "name": "Scrap_Metal_Smooth",
      "rotation": 20
    },
    {
      "x": -8,
      "y": -10,
      "z": 0,
      "name": "Scrap_Metal_Smooth",
      "rotation": 20
    },
    {
      "x": -8,
      "y": -9,
      "z": 0,
      "name": "Scrap_Metal_Smooth",
      "rotation": 20
    },
    {
      "x": -8,
      "y": -8,
      "z": 0,
      "name": "Scrap_Metal_Smooth",
      "rotation": 20
    },
    {
      "x": -8,
      "y": -7,
      "z": 0,
      "name": "Scrap_Metal_Smooth",
      "rotation": 20
    },
    {
      "x": -8,
      "y": -6,
      "z": 0,
      "name": "Scrap_Metal_Smooth",
      "rotation": 4
    },
    {
      "x": -8,
      "y": -5,
      "z": 0,
      "name": "Scrap_Metal_Smooth",
      "rotation": 4
    },
    {
      "x": -8,
      "y": -4,
      "z": 0,
      "name": "Scrap_Metal_Smooth",
      "rotation": 4
    },
    {
      "x": -8,
      "y": -3,
      "z": 0,
      "name": "Scrap_Metal_Smooth",
      "rotation": 4
    },
    {
      "x": -8,
      "y": -2,
      "z": 0,
      "name": "Scrap_Metal_Smooth",
      "rotation": 4
    },
    {
      "x": -8,
      "y": -1,
      "z": 0,
      "name": "Scrap_Metal_Smooth",
      "rotation": 4
    },
    {
      "x": -8,
      "y": 0,
      "z": 0,
      "name": "Scrap_Metal_Smooth",
      "rotation": 4
    },
    {
      "x": -8,
      "y": 1,
      "z": 0,
      "name": "Scrap_Metal_Smooth",
      "rotation": 4
    },
    {
      "x": -8,
      "y": 2,
      "z": 0,
      "name": "Scrap_Metal_Smooth",
      "rotation": 4
    },
    {
      "x": -8,
      "y": 3,
      "z": 0,
      "name": "Scrap_Metal_Smooth",
      "rotation": 4
    },
    {
      "x": -8,
      "y": 4,
      "z": 0,
      "name": "Scrap_Metal_Smooth",
      "rotation": 4
    },
    {
      "x": -8,
      "y": 5,
      "z": 0,
      "name": "Scrap_Metal_Smooth",
      "rotation": 4
    },
    {
      "x": -8,
      "y": 6,
      "z": 0,
      "name": "Scrap_Metal_Smooth",
      "rotation": 4
    },
    {
      "x": -8,
      "y": 7,
      "z": 0,
      "name": "Scrap_Metal_Smooth",
      "rotation": 4
    },
    {
      "x": -8,
      "y": 8,
      "z": 0,
      "name": "Scrap_Metal_Smooth",
      "rotation": 4
    },
    {
      "x": -8,
      "y": 9,
      "z": 0,
      "name": "Scrap_Metal_Smooth",
      "rotation": 4
    },
    {
      "x": -8,
      "y": 10,
      "z": 0,
      "name": "Scrap_Metal_Smooth",
      "rotation": 4
    },
    {
      "x": -8,
      "y": 11,
      "z": 0,
      "name": "Scrap_Metal_Smooth",
      "rotation": 4
    },
    {
      "x": -8,
      "y": 12,
      "z": 0,
      "name": "Scrap_Metal_Smooth",
      "rotation": 4
    },
    {
      "x": -8,
      "y": 13,
      "z": 0,
      "name": "Scrap_Metal_Smooth",
      "rotation": 4
    },
    {
      "x": -8,
      "y": 14,
      "z": 0,
      "name": "Scrap_Metal_Smooth",
      "rotation": 4
    },
    {
      "x": -8,
      "y": 15,
      "z": 0,
      "name": "Scrap_Metal_Smooth",
      "rotation": 4
    },
    {
      "x": -8,
      "y": 16,
      "z": 0,
      "name": "Scrap_Metal_Smooth",
      "rotation": 4
    },
    {
      "x": -8,
      "y": 17,
      "z": 0,
      "name": "Scrap_Metal_Smooth",
      "rotation": 4
    },
    {
      "x": -8,
      "y": 18,
      "z": 0,
      "name": "Scrap_Metal_Smooth",
      "rotation": 4
    },
    {
      "x": -8,
      "y": 19,
      "z": 0,
      "name": "Scrap_Metal_Smooth",
      "rotation": 4
    },
    {
      "x": -8,
      "y": 20,
      "z": 0,
      "name": "Scrap_Metal_Smooth",
      "rotation": 4
    },
    {
      "x": -8,
      "y": 21,
      "z": 0,
      "name": "Scrap_Metal_Smooth",
      "rotation": 4
    },
    {
      "x": -8,
      "y": 22,
      "z": 0,
      "name": "Soil_Clay"
    },
    {
      "x": -8,
      "y": 23,
      "z": 0,
      "name": "Scrap_Metal_Smooth",
      "rotation": 30
    },
    {
      "x": -8,
      "y": 10,
      "z": 1,
      "name": "Plant_Moss_Wall_Green",
      "support": 15
    },
    {
      "x": -7,
      "y": -11,
      "z": 0,
      "name": "Scrap_Metal_Smooth",
      "rotation": 30
    },
    {
      "x": -7,
      "y": -10,
      "z": 0,
      "name": "Scrap_Metal_Smooth",
      "rotation": 20
    },
    {
      "x": -7,
      "y": -9,
      "z": 0,
      "name": "Scrap_Metal_Smooth",
      "rotation": 20
    },
    {
      "x": -7,
      "y": -8,
      "z": 0,
      "name": "Scrap_Metal_Smooth",
      "rotation": 20
    },
    {
      "x": -7,
      "y": -7,
      "z": 0,
      "name": "Scrap_Metal_Smooth",
      "rotation": 20
    },
    {
      "x": -7,
      "y": -6,
      "z": 0,
      "name": "Scrap_Metal_Smooth",
      "rotation": 4
    },
    {
      "x": -7,
      "y": -5,
      "z": 0,
      "name": "Scrap_Metal_Smooth",
      "rotation": 4
    },
    {
      "x": -7,
      "y": -4,
      "z": 0,
      "name": "Scrap_Metal_Smooth",
      "rotation": 4
    },
    {
      "x": -7,
      "y": -3,
      "z": 0,
      "name": "Scrap_Metal_Smooth",
      "rotation": 4
    },
    {
      "x": -7,
      "y": -2,
      "z": 0,
      "name": "Scrap_Metal_Smooth",
      "rotation": 4
    },
    {
      "x": -7,
      "y": -1,
      "z": 0,
      "name": "Scrap_Metal_Smooth",
      "rotation": 4
    },
    {
      "x": -7,
      "y": 0,
      "z": 0,
      "name": "Scrap_Metal_Smooth",
      "rotation": 4
    },
    {
      "x": -7,
      "y": 1,
      "z": 0,
      "name": "Scrap_Metal_Smooth",
      "rotation": 4
    },
    {
      "x": -7,
      "y": 2,
      "z": 0,
      "name": "Scrap_Metal_Smooth",
      "rotation": 4
    },
    {
      "x": -7,
      "y": 3,
      "z": 0,
      "name": "Scrap_Metal_Smooth",
      "rotation": 4
    },
    {
      "x": -7,
      "y": 4,
      "z": 0,
      "name": "Scrap_Metal_Smooth",
      "rotation": 4
    },
    {
      "x": -7,
      "y": 5,
      "z": 0,
      "name": "Scrap_Metal_Smooth",
      "rotation": 4
    },
    {
      "x": -7,
      "y": 6,
      "z": 0,
      "name": "Scrap_Metal_Smooth",
      "rotation": 4
    },
    {
      "x": -7,
      "y": 7,
      "z": 0,
      "name": "Scrap_Metal_Smooth",
      "rotation": 4
    },
    {
      "x": -7,
      "y": 8,
      "z": 0,
      "name": "Scrap_Metal_Smooth",
      "rotation": 4
    },
    {
      "x": -7,
      "y": 9,
      "z": 0,
      "name": "Scrap_Metal_Smooth",
      "rotation": 4
    },
    {
      "x": -7,
      "y": 10,
      "z": 0,
      "name": "Scrap_Metal_Smooth",
      "rotation": 4
    },
    {
      "x": -7,
      "y": 11,
      "z": 0,
      "name": "Scrap_Metal_Smooth",
      "rotation": 4
    },
    {
      "x": -7,
      "y": 12,
      "z": 0,
      "name": "Scrap_Metal_Smooth",
      "rotation": 4
    },
    {
      "x": -7,
      "y": 13,
      "z": 0,
      "name": "Scrap_Metal_Smooth",
      "rotation": 4
    },
    {
      "x": -7,
      "y": 14,
      "z": 0,
      "name": "Scrap_Metal_Smooth",
      "rotation": 4
    },
    {
      "x": -7,
      "y": 15,
      "z": 0,
      "name": "Scrap_Metal_Smooth",
      "rotation": 4
    },
    {
      "x": -7,
      "y": 16,
      "z": 0,
      "name": "Scrap_Metal_Smooth",
      "rotation": 4
    },
    {
      "x": -7,
      "y": 17,
      "z": 0,
      "name": "Scrap_Metal_Smooth",
      "rotation": 4
    },
    {
      "x": -7,
      "y": 18,
      "z": 0,
      "name": "Scrap_Metal_Smooth",
      "rotation": 4
    },
    {
      "x": -7,
      "y": 19,
      "z": 0,
      "name": "Scrap_Metal_Smooth",
      "rotation": 4
    },
    {
      "x": -7,
      "y": 20,
      "z": 0,
      "name": "Scrap_Metal_Smooth",
      "rotation": 4
    },
    {
      "x": -7,
      "y": 21,
      "z": 0,
      "name": "Scrap_Metal_Smooth",
      "rotation": 4
    },
    {
      "x": -7,
      "y": 22,
      "z": 0,
      "name": "Scrap_Metal_Smooth",
      "rotation": 4
    },
    {
      "x": -7,
      "y": 23,
      "z": 0,
      "name": "Soil_Clay"
    },
    {
      "x": -6,
      "y": -11,
      "z": 0,
      "name": "Scrap_Metal_Smooth",
      "rotation": 30
    },
    {
      "x": -6,
      "y": -10,
      "z": 0,
      "name": "Scrap_Metal_Smooth",
      "rotation": 20
    },
    {
      "x": -6,
      "y": -9,
      "z": 0,
      "name": "Scrap_Metal_Smooth",
      "rotation": 20
    },
    {
      "x": -6,
      "y": -8,
      "z": 0,
      "name": "Scrap_Metal_Smooth",
      "rotation": 20
    },
    {
      "x": -6,
      "y": -7,
      "z": 0,
      "name": "Scrap_Metal_Smooth",
      "rotation": 20
    },
    {
      "x": -6,
      "y": -6,
      "z": 0,
      "name": "Scrap_Metal_Smooth",
      "rotation": 4
    },
    {
      "x": -6,
      "y": -5,
      "z": 0,
      "name": "Scrap_Metal_Smooth",
      "rotation": 4
    },
    {
      "x": -6,
      "y": -4,
      "z": 0,
      "name": "Scrap_Metal_Smooth",
      "rotation": 4
    },
    {
      "x": -6,
      "y": -3,
      "z": 0,
      "name": "Scrap_Metal_Smooth",
      "rotation": 4
    },
    {
      "x": -6,
      "y": -2,
      "z": 0,
      "name": "Scrap_Metal_Smooth",
      "rotation": 4
    },
    {
      "x": -6,
      "y": -1,
      "z": 0,
      "name": "Scrap_Metal_Smooth",
      "rotation": 4
    },
    {
      "x": -6,
      "y": 0,
      "z": 0,
      "name": "Scrap_Metal_Smooth",
      "rotation": 4
    },
    {
      "x": -6,
      "y": 1,
      "z": 0,
      "name": "Scrap_Metal_Smooth",
      "rotation": 4
    },
    {
      "x": -6,
      "y": 2,
      "z": 0,
      "name": "Scrap_Metal_Smooth",
      "rotation": 4
    },
    {
      "x": -6,
      "y": 3,
      "z": 0,
      "name": "Scrap_Metal_Smooth",
      "rotation": 4
    },
    {
      "x": -6,
      "y": 4,
      "z": 0,
      "name": "Scrap_Metal_Smooth",
      "rotation": 4
    },
    {
      "x": -6,
      "y": 5,
      "z": 0,
      "name": "Scrap_Metal_Smooth",
      "rotation": 4
    },
    {
      "x": -6,
      "y": 6,
      "z": 0,
      "name": "Scrap_Metal_Smooth",
      "rotation": 4
    },
    {
      "x": -6,
      "y": 7,
      "z": 0,
      "name": "Scrap_Metal_Smooth",
      "rotation": 4
    },
    {
      "x": -6,
      "y": 8,
      "z": 0,
      "name": "Scrap_Metal_Smooth",
      "rotation": 4
    },
    {
      "x": -6,
      "y": 9,
      "z": 0,
      "name": "Scrap_Metal_Smooth",
      "rotation": 4
    },
    {
      "x": -6,
      "y": 10,
      "z": 0,
      "name": "Scrap_Metal_Smooth",
      "rotation": 4
    },
    {
      "x": -6,
      "y": 11,
      "z": 0,
      "name": "Scrap_Metal_Smooth",
      "rotation": 4
    },
    {
      "x": -6,
      "y": 12,
      "z": 0,
      "name": "Scrap_Metal_Smooth",
      "rotation": 4
    },
    {
      "x": -6,
      "y": 13,
      "z": 0,
      "name": "Scrap_Metal_Smooth",
      "rotation": 4
    },
    {
      "x": -6,
      "y": 14,
      "z": 0,
      "name": "Scrap_Metal_Smooth",
      "rotation": 4
    },
    {
      "x": -6,
      "y": 15,
      "z": 0,
      "name": "Scrap_Metal_Smooth",
      "rotation": 4
    },
    {
      "x": -6,
      "y": 16,
      "z": 0,
      "name": "Scrap_Metal_Smooth",
      "rotation": 4
    },
    {
      "x": -6,
      "y": 17,
      "z": 0,
      "name": "Scrap_Metal_Smooth",
      "rotation": 4
    },
    {
      "x": -6,
      "y": 18,
      "z": 0,
      "name": "Scrap_Metal_Smooth",
      "rotation": 4
    },
    {
      "x": -6,
      "y": 19,
      "z": 0,
      "name": "Scrap_Metal_Smooth",
      "rotation": 4
    },
    {
      "x": -6,
      "y": 20,
      "z": 0,
      "name": "Scrap_Metal_Smooth",
      "rotation": 4
    },
    {
      "x": -6,
      "y": 21,
      "z": 0,
      "name": "Scrap_Metal_Smooth",
      "rotation": 4
    },
    {
      "x": -6,
      "y": 22,
      "z": 0,
      "name": "Scrap_Metal_Smooth",
      "rotation": 4
    },
    {
      "x": -6,
      "y": 23,
      "z": 0,
      "name": "Scrap_Metal_Smooth",
      "rotation": 4
    },
    {
      "x": -6,
      "y": 24,
      "z": 0,
      "name": "Scrap_Metal_Smooth",
      "rotation": 30
    },
    {
      "x": -6,
      "y": 25,
      "z": 0,
      "name": "Plant_Moss_Rug_Green",
      "support": 15
    },
    {
      "x": -6,
      "y": 22,
      "z": 1,
      "name": "Plant_Moss_Wall_Green",
      "support": 15
    },
    {
      "x": -6,
      "y": 23,
      "z": 1,
      "name": "Plant_Moss_Wall_Green",
      "support": 15
    },
    {
      "x": -6,
      "y": 24,
      "z": 1,
      "name": "Plant_Moss_Wall_Green",
      "support": 15
    },
    {
      "x": -5,
      "y": -11,
      "z": 0,
      "name": "Scrap_Metal_Smooth",
      "rotation": 30
    },
    {
      "x": -5,
      "y": -10,
      "z": 0,
      "name": "Scrap_Metal_Smooth",
      "rotation": 20
    },
    {
      "x": -5,
      "y": -9,
      "z": 0,
      "name": "Scrap_Metal_Smooth",
      "rotation": 20
    },
    {
      "x": -5,
      "y": -8,
      "z": 0,
      "name": "Scrap_Metal_Smooth",
      "rotation": 20
    },
    {
      "x": -5,
      "y": -7,
      "z": 0,
      "name": "Scrap_Metal_Smooth",
      "rotation": 20
    },
    {
      "x": -5,
      "y": -6,
      "z": 0,
      "name": "Scrap_Metal_Smooth",
      "rotation": 4
    },
    {
      "x": -5,
      "y": -5,
      "z": 0,
      "name": "Scrap_Metal_Smooth",
      "rotation": 4
    },
    {
      "x": -5,
      "y": -4,
      "z": 0,
      "name": "Scrap_Metal_Smooth",
      "rotation": 4
    },
    {
      "x": -5,
      "y": -3,
      "z": 0,
      "name": "Scrap_Metal_Smooth",
      "rotation": 4
    },
    {
      "x": -5,
      "y": -2,
      "z": 0,
      "name": "Scrap_Metal_Smooth",
      "rotation": 4
    },
    {
      "x": -5,
      "y": -1,
      "z": 0,
      "name": "Scrap_Metal_Smooth",
      "rotation": 4
    },
    {
      "x": -5,
      "y": 0,
      "z": 0,
      "name": "Scrap_Metal_Smooth",
      "rotation": 4
    },
    {
      "x": -5,
      "y": 1,
      "z": 0,
      "name": "Scrap_Metal_Smooth",
      "rotation": 4
    },
    {
      "x": -5,
      "y": 2,
      "z": 0,
      "name": "Scrap_Metal_Smooth",
      "rotation": 4
    },
    {
      "x": -5,
      "y": 3,
      "z": 0,
      "name": "Scrap_Metal_Smooth",
      "rotation": 4
    },
    {
      "x": -5,
      "y": 4,
      "z": 0,
      "name": "Scrap_Metal_Smooth",
      "rotation": 4
    },
    {
      "x": -5,
      "y": 5,
      "z": 0,
      "name": "Scrap_Metal_Smooth",
      "rotation": 4
    },
    {
      "x": -5,
      "y": 6,
      "z": 0,
      "name": "Scrap_Metal_Smooth",
      "rotation": 4
    },
    {
      "x": -5,
      "y": 7,
      "z": 0,
      "name": "Scrap_Metal_Smooth",
      "rotation": 4
    },
    {
      "x": -5,
      "y": 8,
      "z": 0,
      "name": "Scrap_Metal_Smooth",
      "rotation": 4
    },
    {
      "x": -5,
      "y": 9,
      "z": 0,
      "name": "Scrap_Metal_Smooth",
      "rotation": 4
    },
    {
      "x": -5,
      "y": 10,
      "z": 0,
      "name": "Scrap_Metal_Smooth",
      "rotation": 4
    },
    {
      "x": -5,
      "y": 11,
      "z": 0,
      "name": "Scrap_Metal_Smooth",
      "rotation": 4
    },
    {
      "x": -5,
      "y": 12,
      "z": 0,
      "name": "Scrap_Metal_Smooth",
      "rotation": 4
    },
    {
      "x": -5,
      "y": 13,
      "z": 0,
      "name": "Scrap_Metal_Smooth",
      "rotation": 4
    },
    {
      "x": -5,
      "y": 14,
      "z": 0,
      "name": "Scrap_Metal_Smooth",
      "rotation": 4
    },
    {
      "x": -5,
      "y": 15,
      "z": 0,
      "name": "Scrap_Metal_Smooth",
      "rotation": 4
    },
    {
      "x": -5,
      "y": 16,
      "z": 0,
      "name": "Scrap_Metal_Smooth",
      "rotation": 4
    },
    {
      "x": -5,
      "y": 17,
      "z": 0,
      "name": "Scrap_Metal_Smooth",
      "rotation": 4
    },
    {
      "x": -5,
      "y": 18,
      "z": 0,
      "name": "Scrap_Metal_Smooth",
      "rotation": 4
    },
    {
      "x": -5,
      "y": 19,
      "z": 0,
      "name": "Scrap_Metal_Smooth",
      "rotation": 4
    },
    {
      "x": -5,
      "y": 20,
      "z": 0,
      "name": "Scrap_Metal_Smooth",
      "rotation": 4
    },
    {
      "x": -5,
      "y": 21,
      "z": 0,
      "name": "Scrap_Metal_Smooth",
      "rotation": 4
    },
    {
      "x": -5,
      "y": 22,
      "z": 0,
      "name": "Scrap_Metal_Smooth",
      "rotation": 4
    },
    {
      "x": -5,
      "y": 23,
      "z": 0,
      "name": "Scrap_Metal_Smooth",
      "rotation": 4
    },
    {
      "x": -5,
      "y": 24,
      "z": 0,
      "name": "Scrap_Metal_Smooth",
      "rotation": 30
    },
    {
      "x": -5,
      "y": 25,
      "z": 0,
      "name": "Plant_Moss_Rug_Green",
      "support": 15
    },
    {
      "x": -5,
      "y": 24,
      "z": 1,
      "name": "Plant_Moss_Wall_Green",
      "support": 15
    },
    {
      "x": -4,
      "y": -11,
      "z": 0,
      "name": "Scrap_Metal_Smooth",
      "rotation": 30
    },
    {
      "x": -4,
      "y": -10,
      "z": 0,
      "name": "Scrap_Metal_Smooth",
      "rotation": 20
    },
    {
      "x": -4,
      "y": -9,
      "z": 0,
      "name": "Scrap_Metal_Smooth",
      "rotation": 20
    },
    {
      "x": -4,
      "y": -8,
      "z": 0,
      "name": "Scrap_Metal_Smooth",
      "rotation": 20
    },
    {
      "x": -4,
      "y": -7,
      "z": 0,
      "name": "Scrap_Metal_Smooth",
      "rotation": 20
    },
    {
      "x": -4,
      "y": -6,
      "z": 0,
      "name": "Scrap_Metal_Smooth",
      "rotation": 4
    },
    {
      "x": -4,
      "y": -5,
      "z": 0,
      "name": "Scrap_Metal_Smooth",
      "rotation": 4
    },
    {
      "x": -4,
      "y": -4,
      "z": 0,
      "name": "Scrap_Metal_Smooth",
      "rotation": 4
    },
    {
      "x": -4,
      "y": -3,
      "z": 0,
      "name": "Scrap_Metal_Smooth",
      "rotation": 4
    },
    {
      "x": -4,
      "y": -2,
      "z": 0,
      "name": "Scrap_Metal_Smooth",
      "rotation": 4
    },
    {
      "x": -4,
      "y": -1,
      "z": 0,
      "name": "Scrap_Metal_Smooth",
      "rotation": 4
    },
    {
      "x": -4,
      "y": 0,
      "z": 0,
      "name": "Scrap_Metal_Smooth",
      "rotation": 4
    },
    {
      "x": -4,
      "y": 1,
      "z": 0,
      "name": "Scrap_Metal_Smooth",
      "rotation": 4
    },
    {
      "x": -4,
      "y": 2,
      "z": 0,
      "name": "Scrap_Metal_Smooth",
      "rotation": 4
    },
    {
      "x": -4,
      "y": 3,
      "z": 0,
      "name": "Scrap_Metal_Smooth",
      "rotation": 4
    },
    {
      "x": -4,
      "y": 4,
      "z": 0,
      "name": "Scrap_Metal_Smooth",
      "rotation": 4
    },
    {
      "x": -4,
      "y": 5,
      "z": 0,
      "name": "Scrap_Metal_Smooth",
      "rotation": 4
    },
    {
      "x": -4,
      "y": 6,
      "z": 0,
      "name": "Scrap_Metal_Smooth",
      "rotation": 4
    },
    {
      "x": -4,
      "y": 7,
      "z": 0,
      "name": "Scrap_Metal_Smooth",
      "rotation": 4
    },
    {
      "x": -4,
      "y": 8,
      "z": 0,
      "name": "Scrap_Metal_Smooth",
      "rotation": 4
    },
    {
      "x": -4,
      "y": 9,
      "z": 0,
      "name": "Scrap_Metal_Smooth",
      "rotation": 4
    },
    {
      "x": -4,
      "y": 10,
      "z": 0,
      "name": "Scrap_Metal_Smooth",
      "rotation": 4
    },
    {
      "x": -4,
      "y": 11,
      "z": 0,
      "name": "Scrap_Metal_Smooth",
      "rotation": 4
    },
    {
      "x": -4,
      "y": 12,
      "z": 0,
      "name": "Scrap_Metal_Smooth",
      "rotation": 4
    },
    {
      "x": -4,
      "y": 13,
      "z": 0,
      "name": "Scrap_Metal_Smooth",
      "rotation": 4
    },
    {
      "x": -4,
      "y": 14,
      "z": 0,
      "name": "Scrap_Metal_Smooth",
      "rotation": 4
    },
    {
      "x": -4,
      "y": 15,
      "z": 0,
      "name": "Scrap_Metal_Smooth",
      "rotation": 4
    },
    {
      "x": -4,
      "y": 16,
      "z": 0,
      "name": "Scrap_Metal_Smooth",
      "rotation": 4
    },
    {
      "x": -4,
      "y": 17,
      "z": 0,
      "name": "Scrap_Metal_Smooth",
      "rotation": 4
    },
    {
      "x": -4,
      "y": 18,
      "z": 0,
      "name": "Scrap_Metal_Smooth",
      "rotation": 4
    },
    {
      "x": -4,
      "y": 19,
      "z": 0,
      "name": "Scrap_Metal_Smooth",
      "rotation": 4
    },
    {
      "x": -4,
      "y": 20,
      "z": 0,
      "name": "Scrap_Metal_Smooth",
      "rotation": 4
    },
    {
      "x": -4,
      "y": 21,
      "z": 0,
      "name": "Scrap_Metal_Smooth",
      "rotation": 4
    },
    {
      "x": -4,
      "y": 22,
      "z": 0,
      "name": "Scrap_Metal_Smooth",
      "rotation": 4
    },
    {
      "x": -4,
      "y": 23,
      "z": 0,
      "name": "Scrap_Metal_Smooth",
      "rotation": 4
    },
    {
      "x": -4,
      "y": 24,
      "z": 0,
      "name": "Scrap_Metal_Smooth",
      "rotation": 30
    },
    {
      "x": -4,
      "y": 24,
      "z": 1,
      "name": "Plant_Moss_Wall_Green",
      "support": 15
    },
    {
      "x": -3,
      "y": -10,
      "z": 0,
      "name": "Scrap_Metal_Smooth",
      "rotation": 30
    },
    {
      "x": -3,
      "y": -9,
      "z": 0,
      "name": "Scrap_Metal_Smooth",
      "rotation": 20
    },
    {
      "x": -3,
      "y": -8,
      "z": 0,
      "name": "Scrap_Metal_Smooth",
      "rotation": 20
    },
    {
      "x": -3,
      "y": -7,
      "z": 0,
      "name": "Scrap_Metal_Smooth",
      "rotation": 20
    },
    {
      "x": -3,
      "y": -6,
      "z": 0,
      "name": "Scrap_Metal_Smooth",
      "rotation": 4
    },
    {
      "x": -3,
      "y": -5,
      "z": 0,
      "name": "Scrap_Metal_Smooth",
      "rotation": 4
    },
    {
      "x": -3,
      "y": -4,
      "z": 0,
      "name": "Scrap_Metal_Smooth",
      "rotation": 4
    },
    {
      "x": -3,
      "y": -3,
      "z": 0,
      "name": "Scrap_Metal_Smooth",
      "rotation": 4
    },
    {
      "x": -3,
      "y": -2,
      "z": 0,
      "name": "Scrap_Metal_Smooth",
      "rotation": 4
    },
    {
      "x": -3,
      "y": -1,
      "z": 0,
      "name": "Scrap_Metal_Smooth",
      "rotation": 4
    },
    {
      "x": -3,
      "y": 0,
      "z": 0,
      "name": "Scrap_Metal_Smooth",
      "rotation": 4
    },
    {
      "x": -3,
      "y": 1,
      "z": 0,
      "name": "Scrap_Metal_Smooth",
      "rotation": 4
    },
    {
      "x": -3,
      "y": 2,
      "z": 0,
      "name": "Scrap_Metal_Smooth",
      "rotation": 4
    },
    {
      "x": -3,
      "y": 3,
      "z": 0,
      "name": "Scrap_Metal_Smooth",
      "rotation": 4
    },
    {
      "x": -3,
      "y": 4,
      "z": 0,
      "name": "Scrap_Metal_Smooth",
      "rotation": 4
    },
    {
      "x": -3,
      "y": 5,
      "z": 0,
      "name": "Scrap_Metal_Smooth",
      "rotation": 4
    },
    {
      "x": -3,
      "y": 6,
      "z": 0,
      "name": "Scrap_Metal_Smooth",
      "rotation": 4
    },
    {
      "x": -3,
      "y": 7,
      "z": 0,
      "name": "Scrap_Metal_Smooth",
      "rotation": 4
    },
    {
      "x": -3,
      "y": 8,
      "z": 0,
      "name": "Scrap_Metal_Smooth",
      "rotation": 4
    },
    {
      "x": -3,
      "y": 9,
      "z": 0,
      "name": "Scrap_Metal_Smooth",
      "rotation": 4
    },
    {
      "x": -3,
      "y": 10,
      "z": 0,
      "name": "Scrap_Metal_Smooth",
      "rotation": 4
    },
    {
      "x": -3,
      "y": 11,
      "z": 0,
      "name": "Scrap_Metal_Smooth",
      "rotation": 4
    },
    {
      "x": -3,
      "y": 12,
      "z": 0,
      "name": "Scrap_Metal_Smooth",
      "rotation": 4
    },
    {
      "x": -3,
      "y": 13,
      "z": 0,
      "name": "Scrap_Metal_Smooth",
      "rotation": 4
    },
    {
      "x": -3,
      "y": 14,
      "z": 0,
      "name": "Scrap_Metal_Smooth",
      "rotation": 4
    },
    {
      "x": -3,
      "y": 15,
      "z": 0,
      "name": "Scrap_Metal_Smooth",
      "rotation": 4
    },
    {
      "x": -3,
      "y": 16,
      "z": 0,
      "name": "Scrap_Metal_Smooth",
      "rotation": 4
    },
    {
      "x": -3,
      "y": 17,
      "z": 0,
      "name": "Scrap_Metal_Smooth",
      "rotation": 4
    },
    {
      "x": -3,
      "y": 18,
      "z": 0,
      "name": "Scrap_Metal_Smooth",
      "rotation": 4
    },
    {
      "x": -3,
      "y": 19,
      "z": 0,
      "name": "Scrap_Metal_Smooth",
      "rotation": 4
    },
    {
      "x": -3,
      "y": 20,
      "z": 0,
      "name": "Scrap_Metal_Smooth",
      "rotation": 4
    },
    {
      "x": -3,
      "y": 21,
      "z": 0,
      "name": "Scrap_Metal_Smooth",
      "rotation": 4
    },
    {
      "x": -3,
      "y": 22,
      "z": 0,
      "name": "Scrap_Metal_Smooth",
      "rotation": 4
    },
    {
      "x": -3,
      "y": 23,
      "z": 0,
      "name": "Scrap_Metal_Smooth",
      "rotation": 4
    },
    {
      "x": -3,
      "y": 24,
      "z": 0,
      "name": "Scrap_Metal_Smooth",
      "rotation": 30
    },
    {
      "x": -2,
      "y": 12,
      "z": 0,
      "name": "Plant_Moss_Wall_Green",
      "support": 15,
      "rotation": 2
    },
    {
      "x": -2,
      "y": -10,
      "z": 1,
      "name": "Scrap_Metal_Smooth",
      "rotation": 30
    },
    {
      "x": -2,
      "y": -9,
      "z": 1,
      "name": "Scrap_Metal_Smooth",
      "rotation": 20
    },
    {
      "x": -2,
      "y": -8,
      "z": 1,
      "name": "Scrap_Metal_Smooth",
      "rotation": 20
    },
    {
      "x": -2,
      "y": -7,
      "z": 1,
      "name": "Scrap_Metal_Smooth",
      "rotation": 20
    },
    {
      "x": -2,
      "y": -6,
      "z": 1,
      "name": "Scrap_Metal_Smooth",
      "rotation": 4
    },
    {
      "x": -2,
      "y": -5,
      "z": 1,
      "name": "Scrap_Metal_Smooth",
      "rotation": 4
    },
    {
      "x": -2,
      "y": -4,
      "z": 1,
      "name": "Scrap_Metal_Smooth",
      "rotation": 4
    },
    {
      "x": -2,
      "y": -3,
      "z": 1,
      "name": "Scrap_Metal_Smooth",
      "rotation": 4
    },
    {
      "x": -2,
      "y": -2,
      "z": 1,
      "name": "Scrap_Metal_Smooth",
      "rotation": 4
    },
    {
      "x": -2,
      "y": -1,
      "z": 1,
      "name": "Scrap_Metal_Smooth",
      "rotation": 4
    },
    {
      "x": -2,
      "y": 0,
      "z": 1,
      "name": "Scrap_Metal_Smooth",
      "rotation": 4
    },
    {
      "x": -2,
      "y": 1,
      "z": 1,
      "name": "Scrap_Metal_Smooth",
      "rotation": 4
    },
    {
      "x": -2,
      "y": 2,
      "z": 1,
      "name": "Scrap_Metal_Smooth",
      "rotation": 4
    },
    {
      "x": -2,
      "y": 3,
      "z": 1,
      "name": "Scrap_Metal_Smooth",
      "rotation": 4
    },
    {
      "x": -2,
      "y": 4,
      "z": 1,
      "name": "Scrap_Metal_Smooth",
      "rotation": 4
    },
    {
      "x": -2,
      "y": 5,
      "z": 1,
      "name": "Scrap_Metal_Smooth",
      "rotation": 4
    },
    {
      "x": -2,
      "y": 6,
      "z": 1,
      "name": "Scrap_Metal_Smooth",
      "rotation": 4
    },
    {
      "x": -2,
      "y": 7,
      "z": 1,
      "name": "Scrap_Metal_Smooth",
      "rotation": 4
    },
    {
      "x": -2,
      "y": 8,
      "z": 1,
      "name": "Scrap_Metal_Smooth",
      "rotation": 4
    },
    {
      "x": -2,
      "y": 9,
      "z": 1,
      "name": "Scrap_Metal_Smooth",
      "rotation": 4
    },
    {
      "x": -2,
      "y": 10,
      "z": 1,
      "name": "Scrap_Metal_Smooth",
      "rotation": 4
    },
    {
      "x": -2,
      "y": 11,
      "z": 1,
      "name": "Scrap_Metal_Smooth",
      "rotation": 4
    },
    {
      "x": -2,
      "y": 12,
      "z": 1,
      "name": "Scrap_Metal_Smooth",
      "rotation": 4
    },
    {
      "x": -2,
      "y": 13,
      "z": 1,
      "name": "Scrap_Metal_Smooth",
      "rotation": 4
    },
    {
      "x": -2,
      "y": 14,
      "z": 1,
      "name": "Scrap_Metal_Smooth",
      "rotation": 4
    },
    {
      "x": -2,
      "y": 15,
      "z": 1,
      "name": "Scrap_Metal_Smooth",
      "rotation": 4
    },
    {
      "x": -2,
      "y": 16,
      "z": 1,
      "name": "Scrap_Metal_Smooth",
      "rotation": 4
    },
    {
      "x": -2,
      "y": 17,
      "z": 1,
      "name": "Scrap_Metal_Smooth",
      "rotation": 4
    },
    {
      "x": -2,
      "y": 18,
      "z": 1,
      "name": "Scrap_Metal_Smooth",
      "rotation": 4
    },
    {
      "x": -2,
      "y": 19,
      "z": 1,
      "name": "Scrap_Metal_Smooth",
      "rotation": 4
    },
    {
      "x": -2,
      "y": 20,
      "z": 1,
      "name": "Scrap_Metal_Smooth",
      "rotation": 4
    },
    {
      "x": -2,
      "y": 21,
      "z": 1,
      "name": "Scrap_Metal_Smooth",
      "rotation": 4
    },
    {
      "x": -2,
      "y": 22,
      "z": 1,
      "name": "Scrap_Metal_Smooth",
      "rotation": 4
    },
    {
      "x": -2,
      "y": 23,
      "z": 1,
      "name": "Scrap_Metal_Smooth",
      "rotation": 4
    },
    {
      "x": -2,
      "y": 24,
      "z": 1,
      "name": "Scrap_Metal_Smooth",
      "rotation": 4
    },
    {
      "x": -2,
      "y": 25,
      "z": 1,
      "name": "Scrap_Metal_Smooth",
      "rotation": 30
    },
    {
      "x": -1,
      "y": 11,
      "z": 0,
      "name": "Plant_Moss_Wall_Green",
      "support": 15,
      "rotation": 2
    },
    {
      "x": -1,
      "y": -10,
      "z": 1,
      "name": "Scrap_Metal_Smooth",
      "rotation": 30
    },
    {
      "x": -1,
      "y": -9,
      "z": 1,
      "name": "Scrap_Metal_Smooth",
      "rotation": 20
    },
    {
      "x": -1,
      "y": -8,
      "z": 1,
      "name": "Scrap_Metal_Smooth",
      "rotation": 20
    },
    {
      "x": -1,
      "y": -7,
      "z": 1,
      "name": "Scrap_Metal_Smooth",
      "rotation": 20
    },
    {
      "x": -1,
      "y": -6,
      "z": 1,
      "name": "Scrap_Metal_Smooth",
      "rotation": 4
    },
    {
      "x": -1,
      "y": -5,
      "z": 1,
      "name": "Scrap_Metal_Smooth",
      "rotation": 4
    },
    {
      "x": -1,
      "y": -4,
      "z": 1,
      "name": "Scrap_Metal_Smooth",
      "rotation": 4
    },
    {
      "x": -1,
      "y": -3,
      "z": 1,
      "name": "Scrap_Metal_Smooth",
      "rotation": 4
    },
    {
      "x": -1,
      "y": -2,
      "z": 1,
      "name": "Scrap_Metal_Smooth",
      "rotation": 4
    },
    {
      "x": -1,
      "y": -1,
      "z": 1,
      "name": "Scrap_Metal_Smooth",
      "rotation": 4
    },
    {
      "x": -1,
      "y": 0,
      "z": 1,
      "name": "Scrap_Metal_Smooth",
      "rotation": 4
    },
    {
      "x": -1,
      "y": 1,
      "z": 1,
      "name": "Scrap_Metal_Smooth",
      "rotation": 4
    },
    {
      "x": -1,
      "y": 2,
      "z": 1,
      "name": "Scrap_Metal_Smooth",
      "rotation": 4
    },
    {
      "x": -1,
      "y": 3,
      "z": 1,
      "name": "Scrap_Metal_Smooth",
      "rotation": 4
    },
    {
      "x": -1,
      "y": 4,
      "z": 1,
      "name": "Scrap_Metal_Smooth",
      "rotation": 4
    },
    {
      "x": -1,
      "y": 5,
      "z": 1,
      "name": "Scrap_Metal_Smooth",
      "rotation": 4
    },
    {
      "x": -1,
      "y": 6,
      "z": 1,
      "name": "Scrap_Metal_Smooth",
      "rotation": 4
    },
    {
      "x": -1,
      "y": 7,
      "z": 1,
      "name": "Scrap_Metal_Smooth",
      "rotation": 4
    },
    {
      "x": -1,
      "y": 8,
      "z": 1,
      "name": "Scrap_Metal_Smooth",
      "rotation": 4
    },
    {
      "x": -1,
      "y": 9,
      "z": 1,
      "name": "Scrap_Metal_Smooth",
      "rotation": 4
    },
    {
      "x": -1,
      "y": 10,
      "z": 1,
      "name": "Scrap_Metal_Smooth",
      "rotation": 4
    },
    {
      "x": -1,
      "y": 11,
      "z": 1,
      "name": "Scrap_Metal_Smooth",
      "rotation": 4
    },
    {
      "x": -1,
      "y": 12,
      "z": 1,
      "name": "Scrap_Metal_Smooth",
      "rotation": 4
    },
    {
      "x": -1,
      "y": 13,
      "z": 1,
      "name": "Scrap_Metal_Smooth",
      "rotation": 4
    },
    {
      "x": -1,
      "y": 14,
      "z": 1,
      "name": "Scrap_Metal_Smooth",
      "rotation": 4
    },
    {
      "x": -1,
      "y": 15,
      "z": 1,
      "name": "Scrap_Metal_Smooth",
      "rotation": 4
    },
    {
      "x": -1,
      "y": 16,
      "z": 1,
      "name": "Scrap_Metal_Smooth",
      "rotation": 4
    },
    {
      "x": -1,
      "y": 17,
      "z": 1,
      "name": "Scrap_Metal_Smooth",
      "rotation": 4
    },
    {
      "x": -1,
      "y": 18,
      "z": 1,
      "name": "Scrap_Metal_Smooth",
      "rotation": 4
    },
    {
      "x": -1,
      "y": 19,
      "z": 1,
      "name": "Scrap_Metal_Smooth",
      "rotation": 4
    },
    {
      "x": -1,
      "y": 20,
      "z": 1,
      "name": "Scrap_Metal_Smooth",
      "rotation": 4
    },
    {
      "x": -1,
      "y": 21,
      "z": 1,
      "name": "Scrap_Metal_Smooth",
      "rotation": 4
    },
    {
      "x": -1,
      "y": 22,
      "z": 1,
      "name": "Scrap_Metal_Smooth",
      "rotation": 4
    },
    {
      "x": -1,
      "y": 23,
      "z": 1,
      "name": "Scrap_Metal_Smooth",
      "rotation": 4
    },
    {
      "x": -1,
      "y": 24,
      "z": 1,
      "name": "Scrap_Metal_Smooth",
      "rotation": 4
    },
    {
      "x": -1,
      "y": 25,
      "z": 1,
      "name": "Scrap_Metal_Smooth",
      "rotation": 30
    },
    {
      "x": 0,
      "y": 0,
      "z": 0,
      "name": "Scrap_Metal_Smooth"
    },
    {
      "x": 0,
      "y": 10,
      "z": 0,
      "name": "Plant_Moss_Wall_Green",
      "support": 15,
      "rotation": 2
    },
    {
      "x": 0,
      "y": 11,
      "z": 0,
      "name": "Plant_Moss_Wall_Green",
      "support": 15,
      "rotation": 2
    },
    {
      "x": 0,
      "y": -10,
      "z": 1,
      "name": "Scrap_Metal_Smooth",
      "rotation": 30
    },
    {
      "x": 0,
      "y": -9,
      "z": 1,
      "name": "Scrap_Metal_Smooth",
      "rotation": 20
    },
    {
      "x": 0,
      "y": -8,
      "z": 1,
      "name": "Scrap_Metal_Smooth",
      "rotation": 20
    },
    {
      "x": 0,
      "y": -7,
      "z": 1,
      "name": "Scrap_Metal_Smooth",
      "rotation": 20
    },
    {
      "x": 0,
      "y": -6,
      "z": 1,
      "name": "Scrap_Metal_Smooth",
      "rotation": 4
    },
    {
      "x": 0,
      "y": -5,
      "z": 1,
      "name": "Scrap_Metal_Smooth",
      "rotation": 4
    },
    {
      "x": 0,
      "y": -4,
      "z": 1,
      "name": "Scrap_Metal_Smooth",
      "rotation": 4
    },
    {
      "x": 0,
      "y": -3,
      "z": 1,
      "name": "Scrap_Metal_Smooth",
      "rotation": 4
    },
    {
      "x": 0,
      "y": -2,
      "z": 1,
      "name": "Scrap_Metal_Smooth",
      "rotation": 4
    },
    {
      "x": 0,
      "y": -1,
      "z": 1,
      "name": "Scrap_Metal_Smooth",
      "rotation": 4
    },
    {
      "x": 0,
      "y": 0,
      "z": 1,
      "name": "Scrap_Metal_Smooth",
      "rotation": 4
    },
    {
      "x": 0,
      "y": 1,
      "z": 1,
      "name": "Scrap_Metal_Smooth",
      "rotation": 4
    },
    {
      "x": 0,
      "y": 2,
      "z": 1,
      "name": "Scrap_Metal_Smooth",
      "rotation": 4
    },
    {
      "x": 0,
      "y": 3,
      "z": 1,
      "name": "Scrap_Metal_Smooth",
      "rotation": 4
    },
    {
      "x": 0,
      "y": 4,
      "z": 1,
      "name": "Scrap_Metal_Smooth",
      "rotation": 4
    },
    {
      "x": 0,
      "y": 5,
      "z": 1,
      "name": "Scrap_Metal_Smooth",
      "rotation": 4
    },
    {
      "x": 0,
      "y": 6,
      "z": 1,
      "name": "Scrap_Metal_Smooth",
      "rotation": 4
    },
    {
      "x": 0,
      "y": 7,
      "z": 1,
      "name": "Scrap_Metal_Smooth",
      "rotation": 4
    },
    {
      "x": 0,
      "y": 8,
      "z": 1,
      "name": "Scrap_Metal_Smooth",
      "rotation": 4
    },
    {
      "x": 0,
      "y": 9,
      "z": 1,
      "name": "Scrap_Metal_Smooth",
      "rotation": 4
    },
    {
      "x": 0,
      "y": 10,
      "z": 1,
      "name": "Scrap_Metal_Smooth",
      "rotation": 4
    },
    {
      "x": 0,
      "y": 11,
      "z": 1,
      "name": "Scrap_Metal_Smooth",
      "rotation": 4
    },
    {
      "x": 0,
      "y": 12,
      "z": 1,
      "name": "Scrap_Metal_Smooth",
      "rotation": 4
    },
    {
      "x": 0,
      "y": 13,
      "z": 1,
      "name": "Scrap_Metal_Smooth",
      "rotation": 4
    },
    {
      "x": 0,
      "y": 14,
      "z": 1,
      "name": "Scrap_Metal_Smooth",
      "rotation": 4
    },
    {
      "x": 0,
      "y": 15,
      "z": 1,
      "name": "Scrap_Metal_Smooth",
      "rotation": 4
    },
    {
      "x": 0,
      "y": 16,
      "z": 1,
      "name": "Scrap_Metal_Smooth",
      "rotation": 4
    },
    {
      "x": 0,
      "y": 17,
      "z": 1,
      "name": "Scrap_Metal_Smooth",
      "rotation": 4
    },
    {
      "x": 0,
      "y": 18,
      "z": 1,
      "name": "Scrap_Metal_Smooth",
      "rotation": 4
    },
    {
      "x": 0,
      "y": 19,
      "z": 1,
      "name": "Scrap_Metal_Smooth",
      "rotation": 4
    },
    {
      "x": 0,
      "y": 20,
      "z": 1,
      "name": "Scrap_Metal_Smooth",
      "rotation": 4
    },
    {
      "x": 0,
      "y": 21,
      "z": 1,
      "name": "Scrap_Metal_Smooth",
      "rotation": 4
    },
    {
      "x": 0,
      "y": 22,
      "z": 1,
      "name": "Scrap_Metal_Smooth",
      "rotation": 4
    },
    {
      "x": 0,
      "y": 23,
      "z": 1,
      "name": "Scrap_Metal_Smooth",
      "rotation": 4
    },
    {
      "x": 0,
      "y": 24,
      "z": 1,
      "name": "Scrap_Metal_Smooth",
      "rotation": 4
    },
    {
      "x": 0,
      "y": 25,
      "z": 1,
      "name": "Scrap_Metal_Smooth",
      "rotation": 30
    },
    {
      "x": 1,
      "y": -9,
      "z": 1,
      "name": "Soil_Clay_Smooth_Orange"
    },
    {
      "x": 1,
      "y": -8,
      "z": 1,
      "name": "Scrap_Metal_Smooth",
      "rotation": 20
    },
    {
      "x": 1,
      "y": -7,
      "z": 1,
      "name": "Scrap_Metal_Smooth",
      "rotation": 20
    },
    {
      "x": 1,
      "y": -6,
      "z": 1,
      "name": "Scrap_Metal_Smooth",
      "rotation": 4
    },
    {
      "x": 1,
      "y": -5,
      "z": 1,
      "name": "Scrap_Metal_Smooth",
      "rotation": 4
    },
    {
      "x": 1,
      "y": -4,
      "z": 1,
      "name": "Scrap_Metal_Smooth",
      "rotation": 4
    },
    {
      "x": 1,
      "y": -3,
      "z": 1,
      "name": "Scrap_Metal_Smooth",
      "rotation": 4
    },
    {
      "x": 1,
      "y": -2,
      "z": 1,
      "name": "Scrap_Metal_Smooth",
      "rotation": 4
    },
    {
      "x": 1,
      "y": -1,
      "z": 1,
      "name": "Scrap_Metal_Smooth",
      "rotation": 4
    },
    {
      "x": 1,
      "y": 0,
      "z": 1,
      "name": "Scrap_Metal_Smooth",
      "rotation": 4
    },
    {
      "x": 1,
      "y": 1,
      "z": 1,
      "name": "Scrap_Metal_Smooth",
      "rotation": 4
    },
    {
      "x": 1,
      "y": 2,
      "z": 1,
      "name": "Scrap_Metal_Smooth",
      "rotation": 4
    },
    {
      "x": 1,
      "y": 3,
      "z": 1,
      "name": "Scrap_Metal_Smooth",
      "rotation": 4
    },
    {
      "x": 1,
      "y": 4,
      "z": 1,
      "name": "Scrap_Metal_Smooth",
      "rotation": 4
    },
    {
      "x": 1,
      "y": 5,
      "z": 1,
      "name": "Scrap_Metal_Smooth",
      "rotation": 4
    },
    {
      "x": 1,
      "y": 6,
      "z": 1,
      "name": "Scrap_Metal_Smooth",
      "rotation": 4
    },
    {
      "x": 1,
      "y": 7,
      "z": 1,
      "name": "Scrap_Metal_Smooth",
      "rotation": 4
    },
    {
      "x": 1,
      "y": 8,
      "z": 1,
      "name": "Scrap_Metal_Smooth",
      "rotation": 4
    },
    {
      "x": 1,
      "y": 9,
      "z": 1,
      "name": "Scrap_Metal_Smooth",
      "rotation": 4
    },
    {
      "x": 1,
      "y": 10,
      "z": 1,
      "name": "Scrap_Metal_Smooth",
      "rotation": 4
    },
    {
      "x": 1,
      "y": 11,
      "z": 1,
      "name": "Scrap_Metal_Smooth",
      "rotation": 4
    },
    {
      "x": 1,
      "y": 12,
      "z": 1,
      "name": "Scrap_Metal_Smooth",
      "rotation": 4
    },
    {
      "x": 1,
      "y": 13,
      "z": 1,
      "name": "Scrap_Metal_Smooth",
      "rotation": 4
    },
    {
      "x": 1,
      "y": 14,
      "z": 1,
      "name": "Scrap_Metal_Smooth",
      "rotation": 4
    },
    {
      "x": 1,
      "y": 15,
      "z": 1,
      "name": "Scrap_Metal_Smooth",
      "rotation": 4
    },
    {
      "x": 1,
      "y": 16,
      "z": 1,
      "name": "Scrap_Metal_Smooth",
      "rotation": 4
    },
    {
      "x": 1,
      "y": 17,
      "z": 1,
      "name": "Scrap_Metal_Smooth",
      "rotation": 4
    },
    {
      "x": 1,
      "y": 18,
      "z": 1,
      "name": "Scrap_Metal_Smooth",
      "rotation": 4
    },
    {
      "x": 1,
      "y": 19,
      "z": 1,
      "name": "Scrap_Metal_Smooth",
      "rotation": 4
    },
    {
      "x": 1,
      "y": 20,
      "z": 1,
      "name": "Scrap_Metal_Smooth",
      "rotation": 4
    },
    {
      "x": 1,
      "y": 21,
      "z": 1,
      "name": "Scrap_Metal_Smooth",
      "rotation": 4
    },
    {
      "x": 1,
      "y": 22,
      "z": 1,
      "name": "Scrap_Metal_Smooth",
      "rotation": 4
    },
    {
      "x": 1,
      "y": 23,
      "z": 1,
      "name": "Scrap_Metal_Smooth",
      "rotation": 4
    },
    {
      "x": 1,
      "y": 24,
      "z": 1,
      "name": "Scrap_Metal_Smooth",
      "rotation": 4
    },
    {
      "x": 1,
      "y": 25,
      "z": 1,
      "name": "Scrap_Metal_Smooth",
      "rotation": 30
    },
    {
      "x": 2,
      "y": 8,
      "z": 0,
      "name": "Plant_Moss_Wall_Green",
      "support": 15,
      "rotation": 2
    },
    {
      "x": 2,
      "y": -9,
      "z": 1,
      "name": "Soil_Clay_Smooth_Orange"
    },
    {
      "x": 2,
      "y": -8,
      "z": 1,
      "name": "Scrap_Metal_Smooth",
      "rotation": 20
    },
    {
      "x": 2,
      "y": -7,
      "z": 1,
      "name": "Scrap_Metal_Smooth",
      "rotation": 20
    },
    {
      "x": 2,
      "y": -6,
      "z": 1,
      "name": "Scrap_Metal_Smooth",
      "rotation": 4
    },
    {
      "x": 2,
      "y": -5,
      "z": 1,
      "name": "Scrap_Metal_Smooth",
      "rotation": 4
    },
    {
      "x": 2,
      "y": -4,
      "z": 1,
      "name": "Scrap_Metal_Smooth",
      "rotation": 4
    },
    {
      "x": 2,
      "y": -3,
      "z": 1,
      "name": "Scrap_Metal_Smooth",
      "rotation": 4
    },
    {
      "x": 2,
      "y": -2,
      "z": 1,
      "name": "Scrap_Metal_Smooth",
      "rotation": 4
    },
    {
      "x": 2,
      "y": -1,
      "z": 1,
      "name": "Scrap_Metal_Smooth",
      "rotation": 4
    },
    {
      "x": 2,
      "y": 0,
      "z": 1,
      "name": "Scrap_Metal_Smooth",
      "rotation": 4
    },
    {
      "x": 2,
      "y": 1,
      "z": 1,
      "name": "Scrap_Metal_Smooth",
      "rotation": 4
    },
    {
      "x": 2,
      "y": 2,
      "z": 1,
      "name": "Scrap_Metal_Smooth",
      "rotation": 4
    },
    {
      "x": 2,
      "y": 3,
      "z": 1,
      "name": "Scrap_Metal_Smooth",
      "rotation": 4
    },
    {
      "x": 2,
      "y": 4,
      "z": 1,
      "name": "Scrap_Metal_Smooth",
      "rotation": 4
    },
    {
      "x": 2,
      "y": 5,
      "z": 1,
      "name": "Scrap_Metal_Smooth",
      "rotation": 4
    },
    {
      "x": 2,
      "y": 6,
      "z": 1,
      "name": "Scrap_Metal_Smooth",
      "rotation": 4
    },
    {
      "x": 2,
      "y": 7,
      "z": 1,
      "name": "Scrap_Metal_Smooth",
      "rotation": 4
    },
    {
      "x": 2,
      "y": 8,
      "z": 1,
      "name": "Scrap_Metal_Smooth",
      "rotation": 4
    },
    {
      "x": 2,
      "y": 9,
      "z": 1,
      "name": "Scrap_Metal_Smooth",
      "rotation": 4
    },
    {
      "x": 2,
      "y": 10,
      "z": 1,
      "name": "Scrap_Metal_Smooth",
      "rotation": 4
    },
    {
      "x": 2,
      "y": 11,
      "z": 1,
      "name": "Scrap_Metal_Smooth",
      "rotation": 4
    },
    {
      "x": 2,
      "y": 12,
      "z": 1,
      "name": "Scrap_Metal_Smooth",
      "rotation": 4
    },
    {
      "x": 2,
      "y": 13,
      "z": 1,
      "name": "Scrap_Metal_Smooth",
      "rotation": 4
    },
    {
      "x": 2,
      "y": 14,
      "z": 1,
      "name": "Scrap_Metal_Smooth",
      "rotation": 4
    },
    {
      "x": 2,
      "y": 15,
      "z": 1,
      "name": "Scrap_Metal_Smooth",
      "rotation": 4
    },
    {
      "x": 2,
      "y": 16,
      "z": 1,
      "name": "Scrap_Metal_Smooth",
      "rotation": 4
    },
    {
      "x": 2,
      "y": 17,
      "z": 1,
      "name": "Scrap_Metal_Smooth",
      "rotation": 4
    },
    {
      "x": 2,
      "y": 18,
      "z": 1,
      "name": "Scrap_Metal_Smooth",
      "rotation": 4
    },
    {
      "x": 2,
      "y": 19,
      "z": 1,
      "name": "Scrap_Metal_Smooth",
      "rotation": 4
    },
    {
      "x": 2,
      "y": 20,
      "z": 1,
      "name": "Scrap_Metal_Smooth",
      "rotation": 4
    },
    {
      "x": 2,
      "y": 21,
      "z": 1,
      "name": "Scrap_Metal_Smooth",
      "rotation": 4
    },
    {
      "x": 2,
      "y": 22,
      "z": 1,
      "name": "Scrap_Metal_Smooth",
      "rotation": 4
    },
    {
      "x": 2,
      "y": 23,
      "z": 1,
      "name": "Scrap_Metal_Smooth",
      "rotation": 4
    },
    {
      "x": 2,
      "y": 24,
      "z": 1,
      "name": "Scrap_Metal_Smooth",
      "rotation": 4
    },
    {
      "x": 2,
      "y": 25,
      "z": 1,
      "name": "Scrap_Metal_Smooth",
      "rotation": 4
    },
    {
      "x": 2,
      "y": 26,
      "z": 1,
      "name": "Scrap_Metal_Smooth",
      "rotation": 30
    },
    {
      "x": 3,
      "y": 8,
      "z": 0,
      "name": "Plant_Moss_Wall_Green",
      "support": 15,
      "rotation": 2
    },
    {
      "x": 3,
      "y": -9,
      "z": 1,
      "name": "Scrap_Metal_Smooth",
      "rotation": 30
    },
    {
      "x": 3,
      "y": -8,
      "z": 1,
      "name": "Soil_Clay"
    },
    {
      "x": 3,
      "y": -7,
      "z": 1,
      "name": "Soil_Clay"
    },
    {
      "x": 3,
      "y": -6,
      "z": 1,
      "name": "Scrap_Metal_Smooth",
      "rotation": 4
    },
    {
      "x": 3,
      "y": -5,
      "z": 1,
      "name": "Scrap_Metal_Smooth",
      "rotation": 14
    },
    {
      "x": 3,
      "y": -4,
      "z": 1,
      "name": "Scrap_Metal_Smooth",
      "rotation": 14
    },
    {
      "x": 3,
      "y": -3,
      "z": 1,
      "name": "Scrap_Metal_Smooth",
      "rotation": 14
    },
    {
      "x": 3,
      "y": -2,
      "z": 1,
      "name": "Scrap_Metal_Smooth",
      "rotation": 14
    },
    {
      "x": 3,
      "y": -1,
      "z": 1,
      "name": "Scrap_Metal_Smooth",
      "rotation": 4
    },
    {
      "x": 3,
      "y": 0,
      "z": 1,
      "name": "Scrap_Metal_Smooth",
      "rotation": 4
    },
    {
      "x": 3,
      "y": 1,
      "z": 1,
      "name": "Scrap_Metal_Smooth",
      "rotation": 4
    },
    {
      "x": 3,
      "y": 2,
      "z": 1,
      "name": "Scrap_Metal_Smooth",
      "rotation": 4
    },
    {
      "x": 3,
      "y": 3,
      "z": 1,
      "name": "Scrap_Metal_Smooth",
      "rotation": 4
    },
    {
      "x": 3,
      "y": 4,
      "z": 1,
      "name": "Scrap_Metal_Smooth",
      "rotation": 4
    },
    {
      "x": 3,
      "y": 5,
      "z": 1,
      "name": "Scrap_Metal_Smooth",
      "rotation": 4
    },
    {
      "x": 3,
      "y": 6,
      "z": 1,
      "name": "Scrap_Metal_Smooth",
      "rotation": 4
    },
    {
      "x": 3,
      "y": 7,
      "z": 1,
      "name": "Scrap_Metal_Smooth",
      "rotation": 4
    },
    {
      "x": 3,
      "y": 8,
      "z": 1,
      "name": "Scrap_Metal_Smooth",
      "rotation": 4
    },
    {
      "x": 3,
      "y": 9,
      "z": 1,
      "name": "Scrap_Metal_Smooth",
      "rotation": 4
    },
    {
      "x": 3,
      "y": 10,
      "z": 1,
      "name": "Scrap_Metal_Smooth",
      "rotation": 4
    },
    {
      "x": 3,
      "y": 11,
      "z": 1,
      "name": "Scrap_Metal_Smooth",
      "rotation": 4
    },
    {
      "x": 3,
      "y": 12,
      "z": 1,
      "name": "Scrap_Metal_Smooth",
      "rotation": 4
    },
    {
      "x": 3,
      "y": 13,
      "z": 1,
      "name": "Scrap_Metal_Smooth",
      "rotation": 4
    },
    {
      "x": 3,
      "y": 14,
      "z": 1,
      "name": "Scrap_Metal_Smooth",
      "rotation": 4
    },
    {
      "x": 3,
      "y": 15,
      "z": 1,
      "name": "Scrap_Metal_Smooth",
      "rotation": 4
    },
    {
      "x": 3,
      "y": 16,
      "z": 1,
      "name": "Scrap_Metal_Smooth",
      "rotation": 4
    },
    {
      "x": 3,
      "y": 17,
      "z": 1,
      "name": "Scrap_Metal_Smooth",
      "rotation": 4
    },
    {
      "x": 3,
      "y": 18,
      "z": 1,
      "name": "Scrap_Metal_Smooth",
      "rotation": 4
    },
    {
      "x": 3,
      "y": 19,
      "z": 1,
      "name": "Scrap_Metal_Smooth",
      "rotation": 4
    },
    {
      "x": 3,
      "y": 20,
      "z": 1,
      "name": "Scrap_Metal_Smooth",
      "rotation": 4
    },
    {
      "x": 3,
      "y": 21,
      "z": 1,
      "name": "Scrap_Metal_Smooth",
      "rotation": 4
    },
    {
      "x": 3,
      "y": 22,
      "z": 1,
      "name": "Scrap_Metal_Smooth",
      "rotation": 4
    },
    {
      "x": 3,
      "y": 23,
      "z": 1,
      "name": "Scrap_Metal_Smooth",
      "rotation": 4
    },
    {
      "x": 3,
      "y": 24,
      "z": 1,
      "name": "Scrap_Metal_Smooth",
      "rotation": 4
    },
    {
      "x": 3,
      "y": 25,
      "z": 1,
      "name": "Soil_Clay"
    },
    {
      "x": 4,
      "y": -9,
      "z": 1,
      "name": "Soil_Clay"
    },
    {
      "x": 4,
      "y": -8,
      "z": 1,
      "name": "Soil_Clay_Smooth_Orange"
    },
    {
      "x": 4,
      "y": -6,
      "z": 1,
      "name": "Soil_Clay_Smooth_Orange"
    },
    {
      "x": 4,
      "y": -5,
      "z": 1,
      "name": "Scrap_Metal_Smooth",
      "rotation": 4
    },
    {
      "x": 4,
      "y": -4,
      "z": 1,
      "name": "Scrap_Metal_Smooth",
      "rotation": 4
    },
    {
      "x": 4,
      "y": -3,
      "z": 1,
      "name": "Scrap_Metal_Smooth",
      "rotation": 4
    },
    {
      "x": 4,
      "y": -2,
      "z": 1,
      "name": "Scrap_Metal_Smooth",
      "rotation": 4
    },
    {
      "x": 4,
      "y": -1,
      "z": 1,
      "name": "Scrap_Metal_Smooth",
      "rotation": 14
    },
    {
      "x": 4,
      "y": 0,
      "z": 1,
      "name": "Scrap_Metal_Smooth",
      "rotation": 14
    },
    {
      "x": 4,
      "y": 1,
      "z": 1,
      "name": "Scrap_Metal_Smooth",
      "rotation": 14
    },
    {
      "x": 4,
      "y": 2,
      "z": 1,
      "name": "Scrap_Metal_Smooth",
      "rotation": 14
    },
    {
      "x": 4,
      "y": 3,
      "z": 1,
      "name": "Scrap_Metal_Smooth",
      "rotation": 4
    },
    {
      "x": 4,
      "y": 4,
      "z": 1,
      "name": "Scrap_Metal_Smooth",
      "rotation": 4
    },
    {
      "x": 4,
      "y": 5,
      "z": 1,
      "name": "Scrap_Metal_Smooth",
      "rotation": 4
    },
    {
      "x": 4,
      "y": 6,
      "z": 1,
      "name": "Scrap_Metal_Smooth",
      "rotation": 4
    },
    {
      "x": 4,
      "y": 7,
      "z": 1,
      "name": "Scrap_Metal_Smooth",
      "rotation": 4
    },
    {
      "x": 4,
      "y": 8,
      "z": 1,
      "name": "Scrap_Metal_Smooth",
      "rotation": 4
    },
    {
      "x": 4,
      "y": 9,
      "z": 1,
      "name": "Scrap_Metal_Smooth",
      "rotation": 4
    },
    {
      "x": 4,
      "y": 10,
